Workbook

Sheet tom_demand_setup
B1: order | C1: EXPORT CSV | D1: WEIGHTS_RA | J1: Peso BG por RS | S1: EXPORT CSV | T1: WEIGHTS_RS | AD1: REF DATA | AG1: REF DATA
B2: # | C2: RequestingArea | D2: RevenueStream | E2: BudgetGroup | F2: Weight | G2: Weight-RS+BG | H2: Weight-Base | J2: RevenueStream | K2: BudgetGroup | L2: Target | M2: Check | N2: Count | O2: Check | P2: Weight | Q2: Check | S2: RevenueStream | T2: Weight | U2: Check | W2: {=_xlfn.UNIQUE(E2:E1000)} -> BudgetGroup | X2: Check | Z2: {=_xlfn.UNIQUE(C2:C1000)} -> RequestingArea | AA2: Check | AB2: hasBG? | AD2: RequestingArea | AE2: BudgetGroup | AG2: MicroPhase bmap | AH2: MicroPhase Macro | AI2: MicroPhase Demand
B3: 1 | C3: GP B2B | D3: Business Solutions | E3: =VLOOKUP($C3,$AD:$AE,2,FALSE) -> Commercial | F3: =H3*SUMIFS($H:$H,$J:$J,D3,$K:$K,E3)/G3 -> 0.1 | G3: =SUMIFS($H$2:$H$1000,$E$2:$E$1000,E3,$D$2:$D$1000,D3) -> 10 | H3: 1 | J3: eCommerce | K3: Operations | L3: =N3/O3*100 -> 9.5238095 | M3: =SUMIF($J:$J,J3,$L:$L) -> 100 | N3: =COUNTIFS(E:E,K3,D:D,J3) -> 4 | O3: =SUMIF($J:$J,J3,$N:$N) -> 42 | P3: =SUMIFS(F:F,E:E,K3,D:D,J3) -> 1 | Q3: =SUMIF($J:$J,N3,$N:$N) -> 0 | S3: eCommerce | T3: 40 | U3: =SUM(T3:T18) -> 100 | W3: Commercial | X3: =SUMIF($E:$E,W3,$F:$F) -> 6 | Z3: GP B2B | AA3: =SUMIF($C:$C,Z3,$F:$F) -> 0.64166667 | AB3: =VLOOKUP(Z3,$AD:$AE,2,FALSE) -> Commercial | AD3: CISO | AE3: CISO | AG3: IDEA > Backlog | AH3: {=_xlfn.TEXTSPLIT(AG3,">",)} -> IDEA | AI3: Backlog
B4: 2 | C4: SEO | D4: Business Solutions | E4: =VLOOKUP($C4,$AD:$AE,2,FALSE) -> Operations | F4: =H4*SUMIFS($H:$H,$J:$J,D4,$K:$K,E4)/G4 -> 0.33333333 | G4: =SUMIFS($H$2:$H$1000,$E$2:$E$1000,E4,$D$2:$D$1000,D4) -> 3 | H4: 1 | J4: eCommerce | K4: Commercial | L4: =N4/O4*100 -> 28.571429 | M4: =SUMIF($J:$J,J4,$L:$L) -> 100 | N4: =COUNTIFS(E:E,K4,D:D,J4) -> 12 | O4: =SUMIF($J:$J,J4,$N:$N) -> 42 | P4: =SUMIFS(F:F,E:E,K4,D:D,J4) -> 1 | Q4: =SUMIF($J:$J,N4,$N:$N) -> 0 | S4: Mail | T4: 22 | W4: Operations | X4: =SUMIF($E:$E,W4,$F:$F) -> 6 | Z4: SEO | AA4: =SUMIF($C:$C,Z4,$F:$F) -> 1.9166667 | AB4: =VLOOKUP(Z4,$AD:$AE,2,FALSE) -> Operations | AD4: CCO | AE4: Commercial | AG4: IDEA > Pitch | AH4: {=_xlfn.TEXTSPLIT(AG4,">",)} -> IDEA | AI4: Pitch
B5: 3 | C5: CF | D5: Business Solutions | E5: =VLOOKUP($C5,$AD:$AE,2,FALSE) -> Corporate | F5: =H5*SUMIFS($H:$H,$J:$J,D5,$K:$K,E5)/G5 -> 0.076923077 | G5: =SUMIFS($H$2:$H$1000,$E$2:$E$1000,E5,$D$2:$D$1000,D5) -> 13 | H5: 1 | J5: eCommerce | K5: Corporate | L5: =N5/O5*100 -> 42.857143 | M5: =SUMIF($J:$J,J5,$L:$L) -> 100 | N5: =COUNTIFS(E:E,K5,D:D,J5) -> 18 | O5: =SUMIF($J:$J,J5,$N:$N) -> 42 | P5: =SUMIFS(F:F,E:E,K5,D:D,J5) -> 1 | Q5: =SUMIF($J:$J,N5,$N:$N) -> 0 | S5: Business Solutions | T5: 16 | W5: Corporate | X5: =SUMIF($E:$E,W5,$F:$F) -> 6 | Z5: CF | AA5: =SUMIF($C:$C,Z5,$F:$F) -> 0.48824786 | AB5: =VLOOKUP(Z5,$AD:$AE,2,FALSE) -> Corporate | AD5: CMO | AE5: Commercial | AG5: IDEA > In Definition | AH5: {=_xlfn.TEXTSPLIT(AG5,">",)} -> IDEA | AI5: In Definition
B6: 4 | C6: SI | D6: Business Solutions | E6: =VLOOKUP($C6,$AD:$AE,2,FALSE) -> Technology | F6: =H6*SUMIFS($H:$H,$J:$J,D6,$K:$K,E6)/G6 -> 0.2 | G6: =SUMIFS($H$2:$H$1000,$E$2:$E$1000,E6,$D$2:$D$1000,D6) -> 5 | H6: 1 | J6: eCommerce | K6: Technology | L6: =N6/O6*100 -> 14.285714 | M6: =SUMIF($J:$J,J6,$L:$L) -> 100 | N6: =COUNTIFS(E:E,K6,D:D,J6) -> 6 | O6: =SUMIF($J:$J,J6,$N:$N) -> 42 | P6: =SUMIFS(F:F,E:E,K6,D:D,J6) -> 1 | Q6: =SUMIF($J:$J,N6,$N:$N) -> 0 | S6: Retail & Financial Services | T6: 10 | W6: Technology | X6: =SUMIF($E:$E,W6,$F:$F) -> 6 | Z6: SI | AA6: =SUMIF($C:$C,Z6,$F:$F) -> 1.1666667 | AB6: =VLOOKUP(Z6,$AD:$AE,2,FALSE) -> Technology | AD6: CSI | AE6: Commercial | AG6: SOLUTION > In Approval | AH6: {=_xlfn.TEXTSPLIT(AG6,">",)} -> SOLUTION | AI6: In Approval
B7: 5 | C7: CISO | D7: Business Solutions | E7: =VLOOKUP($C7,$AD:$AE,2,FALSE) -> CISO | F7: =H7*SUMIFS($H:$H,$J:$J,D7,$K:$K,E7)/G7 -> 1 | G7: =SUMIFS($H$2:$H$1000,$E$2:$E$1000,E7,$D$2:$D$1000,D7) -> 1 | H7: 1 | J7: eCommerce | K7: Data & AI | L7: =N7/O7*100 -> 2.3809524 | M7: =SUMIF($J:$J,J7,$L:$L) -> 100 | N7: =COUNTIFS(E:E,K7,D:D,J7) -> 1 | O7: =SUMIF($J:$J,J7,$N:$N) -> 42 | P7: =SUMIFS(F:F,E:E,K7,D:D,J7) -> 1 | Q7: =SUMIF($J:$J,N7,$N:$N) -> 0 | S7: Payments | T7: 8 | W7: CISO | X7: =SUMIF($E:$E,W7,$F:$F) -> 6 | Z7: CISO | AA7: =SUMIF($C:$C,Z7,$F:$F) -> 6 | AB7: =VLOOKUP(Z7,$AD:$AE,2,FALSE) -> CISO | AD7: CTTE | AE7: Commercial | AG7: SOLUTION > Ready for Approval | AH7: {=_xlfn.TEXTSPLIT(AG7,">",)} -> SOLUTION | AI7: Ready for Approval
B8: 6 | C8: IAD | D8: Business Solutions | E8: =VLOOKUP($C8,$AD:$AE,2,FALSE) -> Data & AI | F8: =H8*SUMIFS($H:$H,$J:$J,D8,$K:$K,E8)/G8 -> 1 | G8: =SUMIFS($H$2:$H$1000,$E$2:$E$1000,E8,$D$2:$D$1000,D8) -> 1 | H8: 1 | J8: eCommerce | K8: CISO | L8: =N8/O8*100 -> 2.3809524 | M8: =SUMIF($J:$J,J8,$L:$L) -> 100 | N8: =COUNTIFS(E:E,K8,D:D,J8) -> 1 | O8: =SUMIF($J:$J,J8,$N:$N) -> 42 | P8: =SUMIFS(F:F,E:E,K8,D:D,J8) -> 1 | Q8: =SUMIF($J:$J,N8,$N:$N) -> 0 | S8: Fulfilment | T8: 4 | W8: Data & AI | X8: =SUMIF($E:$E,W8,$F:$F) -> 6 | Z8: IAD | AA8: =SUMIF($C:$C,Z8,$F:$F) -> 5.1428571 | AB8: =VLOOKUP(Z8,$AD:$AE,2,FALSE) -> Data & AI | AD8: DNI | AE8: Commercial | AG8: IDEA > Ready for Solution | AH8: {=_xlfn.TEXTSPLIT(AG8,">",)} -> IDEA | AI8: Ready for Solution
B9: 7 | C9: GS | D9: Business Solutions | E9: =VLOOKUP($C9,$AD:$AE,2,FALSE) -> Commercial | F9: =H9*SUMIFS($H:$H,$J:$J,D9,$K:$K,E9)/G9 -> 0.1 | G9: =SUMIFS($H$2:$H$1000,$E$2:$E$1000,E9,$D$2:$D$1000,D9) -> 10 | H9: 1 | J9: Mail | K9: Commercial | L9: =N9/O9*100 -> 28.125 | M9: =SUMIF($J:$J,J9,$L:$L) -> 100 | N9: =COUNTIFS(E:E,K9,D:D,J9) -> 9 | O9: =SUMIF($J:$J,J9,$N:$N) -> 32 | P9: =SUMIFS(F:F,E:E,K9,D:D,J9) -> 1 | Q9: =SUMIF($J:$J,N9,$N:$N) -> 0 | S9: Banco CTT | T9: 0 | W9: 0 | X9: =SUMIF($E:$E,W9,$F:$F) -> 0 | Z9: GS | AA9: =SUMIF($C:$C,Z9,$F:$F) -> 0.64166667 | AB9: =VLOOKUP(Z9,$AD:$AE,2,FALSE) -> Commercial | AD9: ECM | AE9: Commercial | AG9: SOLUTION > High Level Design | AH9: {=_xlfn.TEXTSPLIT(AG9,">",)} -> SOLUTION | AI9: High Level Design
B10: 8 | C10: ACR | D10: Business Solutions | E10: =VLOOKUP($C10,$AD:$AE,2,FALSE) -> Corporate | F10: =H10*SUMIFS($H:$H,$J:$J,D10,$K:$K,E10)/G10 -> 0.076923077 | G10: =SUMIFS($H$2:$H$1000,$E$2:$E$1000,E10,$D$2:$D$1000,D10) -> 13 | H10: 1 | J10: Mail | K10: Operations | L10: =N10/O10*100 -> 9.375 | M10: =SUMIF($J:$J,J10,$L:$L) -> 100 | N10: =COUNTIFS(E:E,K10,D:D,J10) -> 3 | O10: =SUMIF($J:$J,J10,$N:$N) -> 32 | P10: =SUMIFS(F:F,E:E,K10,D:D,J10) -> 1 | Q10: =SUMIF($J:$J,N10,$N:$N) -> 0 | X10: =SUMIF($E:$E,W10,$F:$F) -> 0 | Z10: ACR | AA10: =SUMIF($C:$C,Z10,$F:$F) -> 0.48824786 | AB10: =VLOOKUP(Z10,$AD:$AE,2,FALSE) -> Corporate | AD10: GP B2B | AE10: Commercial | AG10: SOLUTION > Ready for Development | AH10: {=_xlfn.TEXTSPLIT(AG10,">",)} -> SOLUTION | AI10: Ready for Development
B11: 9 | C11: EDO | D11: Business Solutions | E11: =VLOOKUP($C11,$AD:$AE,2,FALSE) -> Operations | F11: =H11*SUMIFS($H:$H,$J:$J,D11,$K:$K,E11)/G11 -> 0.33333333 | G11: =SUMIFS($H$2:$H$1000,$E$2:$E$1000,E11,$D$2:$D$1000,D11) -> 3 | H11: 1 | J11: Mail | K11: Corporate | L11: =N11/O11*100 -> 40.625 | M11: =SUMIF($J:$J,J11,$L:$L) -> 100 | N11: =COUNTIFS(E:E,K11,D:D,J11) -> 13 | O11: =SUMIF($J:$J,J11,$N:$N) -> 32 | P11: =SUMIFS(F:F,E:E,K11,D:D,J11) -> 1 | Q11: =SUMIF($J:$J,N11,$N:$N) -> 0 | X11: =SUMIF($E:$E,W11,$F:$F) -> 0 | Z11: EDO | AA11: =SUMIF($C:$C,Z11,$F:$F) -> 1.9166667 | AB11: =VLOOKUP(Z11,$AD:$AE,2,FALSE) -> Operations | AD11: GP B2C | AE11: Commercial | AG11: SOLUTION > In Definition | AH11: {=_xlfn.TEXTSPLIT(AG11,">",)} -> SOLUTION | AI11: In Definition
B12: 10 | C12: SI-OPS | D12: Business Solutions | E12: =VLOOKUP($C12,$AD:$AE,2,FALSE) -> Technology | F12: =H12*SUMIFS($H:$H,$J:$J,D12,$K:$K,E12)/G12 -> 0.2 | G12: =SUMIFS($H$2:$H$1000,$E$2:$E$1000,E12,$D$2:$D$1000,D12) -> 5 | H12: 1 | J12: Mail | K12: Technology | L12: =N12/O12*100 -> 15.625 | M12: =SUMIF($J:$J,J12,$L:$L) -> 100 | N12: =COUNTIFS(E:E,K12,D:D,J12) -> 5 | O12: =SUMIF($J:$J,J12,$N:$N) -> 32 | P12: =SUMIFS(F:F,E:E,K12,D:D,J12) -> 1 | Q12: =SUMIF($J:$J,N12,$N:$N) -> 0 | X12: =SUMIF($E:$E,W12,$F:$F) -> 0 | Z12: SI-OPS | AA12: =SUMIF($C:$C,Z12,$F:$F) -> 1.1666667 | AB12: =VLOOKUP(Z12,$AD:$AE,2,FALSE) -> Technology | AD12: GP ECL | AE12: Commercial
B13: 11 | C13: DNI | D13: Business Solutions | E13: =VLOOKUP($C13,$AD:$AE,2,FALSE) -> Commercial | F13: =H13*SUMIFS($H:$H,$J:$J,D13,$K:$K,E13)/G13 -> 0.1 | G13: =SUMIFS($H$2:$H$1000,$E$2:$E$1000,E13,$D$2:$D$1000,D13) -> 10 | H13: 1 | J13: Mail | K13: Data & AI | L13: =N13/O13*100 -> 3.125 | M13: =SUMIF($J:$J,J13,$L:$L) -> 100 | N13: =COUNTIFS(E:E,K13,D:D,J13) -> 1 | O13: =SUMIF($J:$J,J13,$N:$N) -> 32 | P13: =SUMIFS(F:F,E:E,K13,D:D,J13) -> 1 | Q13: =SUMIF($J:$J,N13,$N:$N) -> 0 | X13: =SUMIF($E:$E,W13,$F:$F) -> 0 | Z13: DNI | AA13: =SUMIF($C:$C,Z13,$F:$F) -> 0.64166667 | AB13: =VLOOKUP(Z13,$AD:$AE,2,FALSE) -> Commercial | AD13: GPG | AE13: Commercial
B14: 12 | C14: AVC | D14: Business Solutions | E14: =VLOOKUP($C14,$AD:$AE,2,FALSE) -> Corporate | F14: =H14*SUMIFS($H:$H,$J:$J,D14,$K:$K,E14)/G14 -> 0.076923077 | G14: =SUMIFS($H$2:$H$1000,$E$2:$E$1000,E14,$D$2:$D$1000,D14) -> 13 | H14: 1 | J14: Mail | K14: CISO | L14: =N14/O14*100 -> 3.125 | M14: =SUMIF($J:$J,J14,$L:$L) -> 100 | N14: =COUNTIFS(E:E,K14,D:D,J14) -> 1 | O14: =SUMIF($J:$J,J14,$N:$N) -> 32 | P14: =SUMIFS(F:F,E:E,K14,D:D,J14) -> 1 | Q14: =SUMIF($J:$J,N14,$N:$N) -> 0 | X14: =SUMIF($E:$E,W14,$F:$F) -> 0 | Z14: AVC | AA14: =SUMIF($C:$C,Z14,$F:$F) -> 0.48824786 | AB14: =VLOOKUP(Z14,$AD:$AE,2,FALSE) -> Corporate | AD14: GS | AE14: Commercial
B15: 13 | C15: EM | D15: Business Solutions | E15: =VLOOKUP($C15,$AD:$AE,2,FALSE) -> Operations | F15: =H15*SUMIFS($H:$H,$J:$J,D15,$K:$K,E15)/G15 -> 0.33333333 | G15: =SUMIFS($H$2:$H$1000,$E$2:$E$1000,E15,$D$2:$D$1000,D15) -> 3 | H15: 1 | J15: Business Solutions | K15: Commercial | L15: =N15/O15*100 -> 30.30303 | M15: =SUMIF($J:$J,J15,$L:$L) -> 100 | N15: =COUNTIFS(E:E,K15,D:D,J15) -> 10 | O15: =SUMIF($J:$J,J15,$N:$N) -> 33 | P15: =SUMIFS(F:F,E:E,K15,D:D,J15) -> 1 | Q15: =SUMIF($J:$J,N15,$N:$N) -> 0 | Z15: EM | AA15: =SUMIF($C:$C,Z15,$F:$F) -> 1.9166667 | AB15: =VLOOKUP(Z15,$AD:$AE,2,FALSE) -> Operations | AD15: IDC | AE15: Commercial
B16: 14 | C16: SI-PRD | D16: Business Solutions | E16: =VLOOKUP($C16,$AD:$AE,2,FALSE) -> Technology | F16: =H16*SUMIFS($H:$H,$J:$J,D16,$K:$K,E16)/G16 -> 0.2 | G16: =SUMIFS($H$2:$H$1000,$E$2:$E$1000,E16,$D$2:$D$1000,D16) -> 5 | H16: 1 | J16: Business Solutions | K16: Operations | L16: =N16/O16*100 -> 9.0909091 | M16: =SUMIF($J:$J,J16,$L:$L) -> 100 | N16: =COUNTIFS(E:E,K16,D:D,J16) -> 3 | O16: =SUMIF($J:$J,J16,$N:$N) -> 33 | P16: =SUMIFS(F:F,E:E,K16,D:D,J16) -> 1 | Q16: =SUMIF($J:$J,N16,$N:$N) -> 0 | Z16: SI-PRD | AA16: =SUMIF($C:$C,Z16,$F:$F) -> 1.1666667 | AB16: =VLOOKUP(Z16,$AD:$AE,2,FALSE) -> Technology | AD16: ACR | AE16: Corporate
B17: 15 | C17: CSI | D17: Business Solutions | E17: =VLOOKUP($C17,$AD:$AE,2,FALSE) -> Commercial | F17: =H17*SUMIFS($H:$H,$J:$J,D17,$K:$K,E17)/G17 -> 0.1 | G17: =SUMIFS($H$2:$H$1000,$E$2:$E$1000,E17,$D$2:$D$1000,D17) -> 10 | H17: 1 | J17: Business Solutions | K17: Corporate | L17: =N17/O17*100 -> 39.393939 | M17: =SUMIF($J:$J,J17,$L:$L) -> 100 | N17: =COUNTIFS(E:E,K17,D:D,J17) -> 13 | O17: =SUMIF($J:$J,J17,$N:$N) -> 33 | P17: =SUMIFS(F:F,E:E,K17,D:D,J17) -> 1 | Q17: =SUMIF($J:$J,N17,$N:$N) -> 0 | Z17: CSI | AA17: =SUMIF($C:$C,Z17,$F:$F) -> 0.64166667 | AB17: =VLOOKUP(Z17,$AD:$AE,2,FALSE) -> Commercial | AD17: ATC | AE17: Corporate
B18: 16 | C18: GT | D18: Business Solutions | E18: =VLOOKUP($C18,$AD:$AE,2,FALSE) -> Corporate | F18: =H18*SUMIFS($H:$H,$J:$J,D18,$K:$K,E18)/G18 -> 0.076923077 | G18: =SUMIFS($H$2:$H$1000,$E$2:$E$1000,E18,$D$2:$D$1000,D18) -> 13 | H18: 1 | J18: Business Solutions | K18: Technology | L18: =N18/O18*100 -> 15.151515 | M18: =SUMIF($J:$J,J18,$L:$L) -> 100 | N18: =COUNTIFS(E:E,K18,D:D,J18) -> 5 | O18: =SUMIF($J:$J,J18,$N:$N) -> 33 | P18: =SUMIFS(F:F,E:E,K18,D:D,J18) -> 1 | Q18: =SUMIF($J:$J,N18,$N:$N) -> 0 | Z18: GT | AA18: =SUMIF($C:$C,Z18,$F:$F) -> 0.48824786 | AB18: =VLOOKUP(Z18,$AD:$AE,2,FALSE) -> Corporate | AD18: AVC | AE18: Corporate
B19: 17 | C19: BCTT | D19: Business Solutions | E19: =VLOOKUP($C19,$AD:$AE,2,FALSE) -> Technology | F19: =H19*SUMIFS($H:$H,$J:$J,D19,$K:$K,E19)/G19 -> 0.2 | G19: =SUMIFS($H$2:$H$1000,$E$2:$E$1000,E19,$D$2:$D$1000,D19) -> 5 | H19: 1 | J19: Business Solutions | K19: Data & AI | L19: =N19/O19*100 -> 3.030303 | M19: =SUMIF($J:$J,J19,$L:$L) -> 100 | N19: =COUNTIFS(E:E,K19,D:D,J19) -> 1 | O19: =SUMIF($J:$J,J19,$N:$N) -> 33 | P19: =SUMIFS(F:F,E:E,K19,D:D,J19) -> 1 | Q19: =SUMIF($J:$J,N19,$N:$N) -> 0 | Z19: BCTT | AA19: =SUMIF($C:$C,Z19,$F:$F) -> 1.1666667 | AB19: =VLOOKUP(Z19,$AD:$AE,2,FALSE) -> Technology | AD19: CF | AE19: Corporate
B20: 18 | C20: GP B2C | D20: Business Solutions | E20: =VLOOKUP($C20,$AD:$AE,2,FALSE) -> Commercial | F20: =H20*SUMIFS($H:$H,$J:$J,D20,$K:$K,E20)/G20 -> 0.1 | G20: =SUMIFS($H$2:$H$1000,$E$2:$E$1000,E20,$D$2:$D$1000,D20) -> 10 | H20: 1 | J20: Business Solutions | K20: CISO | L20: =N20/O20*100 -> 3.030303 | M20: =SUMIF($J:$J,J20,$L:$L) -> 100 | N20: =COUNTIFS(E:E,K20,D:D,J20) -> 1 | O20: =SUMIF($J:$J,J20,$N:$N) -> 33 | P20: =SUMIFS(F:F,E:E,K20,D:D,J20) -> 1 | Q20: =SUMIF($J:$J,N20,$N:$N) -> 0 | Z20: GP B2C | AA20: =SUMIF($C:$C,Z20,$F:$F) -> 0.64166667 | AB20: =VLOOKUP(Z20,$AD:$AE,2,FALSE) -> Commercial | AD20: CFO | AE20: Corporate
B21: 19 | C21: GRH | D21: Business Solutions | E21: =VLOOKUP($C21,$AD:$AE,2,FALSE) -> Corporate | F21: =H21*SUMIFS($H:$H,$J:$J,D21,$K:$K,E21)/G21 -> 0.076923077 | G21: =SUMIFS($H$2:$H$1000,$E$2:$E$1000,E21,$D$2:$D$1000,D21) -> 13 | H21: 1 | J21: Retail & Financial Services | K21: Commercial | L21: =N21/O21*100 -> 25 | M21: =SUMIF($J:$J,J21,$L:$L) -> 100 | N21: =COUNTIFS(E:E,K21,D:D,J21) -> 8 | O21: =SUMIF($J:$J,J21,$N:$N) -> 32 | P21: =SUMIFS(F:F,E:E,K21,D:D,J21) -> 1 | Q21: =SUMIF($J:$J,N21,$N:$N) -> 0 | Z21: GRH | AA21: =SUMIF($C:$C,Z21,$F:$F) -> 0.48824786 | AB21: =VLOOKUP(Z21,$AD:$AE,2,FALSE) -> Corporate | AD21: CHR | AE21: Corporate
B22: 20 | C22: SI-CRP | D22: Business Solutions | E22: =VLOOKUP($C22,$AD:$AE,2,FALSE) -> Technology | F22: =H22*SUMIFS($H:$H,$J:$J,D22,$K:$K,E22)/G22 -> 0.2 | G22: =SUMIFS($H$2:$H$1000,$E$2:$E$1000,E22,$D$2:$D$1000,D22) -> 5 | H22: 1 | J22: Retail & Financial Services | K22: Operations | L22: =N22/O22*100 -> 9.375 | M22: =SUMIF($J:$J,J22,$L:$L) -> 100 | N22: =COUNTIFS(E:E,K22,D:D,J22) -> 3 | O22: =SUMIF($J:$J,J22,$N:$N) -> 32 | P22: =SUMIFS(F:F,E:E,K22,D:D,J22) -> 1 | Q22: =SUMIF($J:$J,N22,$N:$N) -> 0 | Z22: SI-CRP | AA22: =SUMIF($C:$C,Z22,$F:$F) -> 1.1666667 | AB22: =VLOOKUP(Z22,$AD:$AE,2,FALSE) -> Technology | AD22: CL | AE22: Corporate
B23: 21 | C23: GP ECL | D23: Business Solutions | E23: =VLOOKUP($C23,$AD:$AE,2,FALSE) -> Commercial | F23: =H23*SUMIFS($H:$H,$J:$J,D23,$K:$K,E23)/G23 -> 0.1 | G23: =SUMIFS($H$2:$H$1000,$E$2:$E$1000,E23,$D$2:$D$1000,D23) -> 10 | H23: 1 | J23: Retail & Financial Services | K23: Corporate | L23: =N23/O23*100 -> 25 | M23: =SUMIF($J:$J,J23,$L:$L) -> 100 | N23: =COUNTIFS(E:E,K23,D:D,J23) -> 8 | O23: =SUMIF($J:$J,J23,$N:$N) -> 32 | P23: =SUMIFS(F:F,E:E,K23,D:D,J23) -> 1 | Q23: =SUMIF($J:$J,N23,$N:$N) -> 0 | Z23: GP ECL | AA23: =SUMIF($C:$C,Z23,$F:$F) -> 0.64166667 | AB23: =VLOOKUP(Z23,$AD:$AE,2,FALSE) -> Commercial | AD23: CMP | AE23: Corporate
B24: 22 | C24: PC | D24: Business Solutions | E24: =VLOOKUP($C24,$AD:$AE,2,FALSE) -> Corporate | F24: =H24*SUMIFS($H:$H,$J:$J,D24,$K:$K,E24)/G24 -> 0.076923077 | G24: =SUMIFS($H$2:$H$1000,$E$2:$E$1000,E24,$D$2:$D$1000,D24) -> 13 | H24: 1 | J24: Retail & Financial Services | K24: Technology | L24: =N24/O24*100 -> 15.625 | M24: =SUMIF($J:$J,J24,$L:$L) -> 100 | N24: =COUNTIFS(E:E,K24,D:D,J24) -> 5 | O24: =SUMIF($J:$J,J24,$N:$N) -> 32 | P24: =SUMIFS(F:F,E:E,K24,D:D,J24) -> 1 | Q24: =SUMIF($J:$J,N24,$N:$N) -> 0 | Z24: PC | AA24: =SUMIF($C:$C,Z24,$F:$F) -> 0.48824786 | AB24: =VLOOKUP(Z24,$AD:$AE,2,FALSE) -> Corporate | AD24: COM | AE24: Corporate
B25: 23 | C25: GPG | D25: Business Solutions | E25: =VLOOKUP($C25,$AD:$AE,2,FALSE) -> Commercial | F25: =H25*SUMIFS($H:$H,$J:$J,D25,$K:$K,E25)/G25 -> 0.1 | G25: =SUMIFS($H$2:$H$1000,$E$2:$E$1000,E25,$D$2:$D$1000,D25) -> 10 | H25: 1 | J25: Retail & Financial Services | K25: Data & AI | L25: =N25/O25*100 -> 21.875 | M25: =SUMIF($J:$J,J25,$L:$L) -> 100 | N25: =COUNTIFS(E:E,K25,D:D,J25) -> 7 | O25: =SUMIF($J:$J,J25,$N:$N) -> 32 | P25: =SUMIFS(F:F,E:E,K25,D:D,J25) -> 1 | Q25: =SUMIF($J:$J,N25,$N:$N) -> 0 | Z25: GPG | AA25: =SUMIF($C:$C,Z25,$F:$F) -> 0.64166667 | AB25: =VLOOKUP(Z25,$AD:$AE,2,FALSE) -> Commercial | AD25: DPO | AE25: Corporate
B26: 24 | C26: RS | D26: Business Solutions | E26: =VLOOKUP($C26,$AD:$AE,2,FALSE) -> Corporate | F26: =H26*SUMIFS($H:$H,$J:$J,D26,$K:$K,E26)/G26 -> 0.076923077 | G26: =SUMIFS($H$2:$H$1000,$E$2:$E$1000,E26,$D$2:$D$1000,D26) -> 13 | H26: 1 | J26: Retail & Financial Services | K26: CISO | L26: =N26/O26*100 -> 3.125 | M26: =SUMIF($J:$J,J26,$L:$L) -> 100 | N26: =COUNTIFS(E:E,K26,D:D,J26) -> 1 | O26: =SUMIF($J:$J,J26,$N:$N) -> 32 | P26: =SUMIFS(F:F,E:E,K26,D:D,J26) -> 1 | Q26: =SUMIF($J:$J,N26,$N:$N) -> 0 | Z26: RS | AA26: =SUMIF($C:$C,Z26,$F:$F) -> 0.48824786 | AB26: =VLOOKUP(Z26,$AD:$AE,2,FALSE) -> Corporate | AD26: FL | AE26: Corporate
... B38: 3 | C38: ATC | D38: eCommerce | E38: =VLOOKUP($C38,$AD:$AE,2,FALSE) -> Corporate | F38: =H38*SUMIFS($H:$H,$J:$J,D38,$K:$K,E38)/G38 -> 0.055555556 | G38: =SUMIFS($H$2:$H$1000,$E$2:$E$1000,E38,$D$2:$D$1000,D38) -> 18 | H38: 1 | J38: Fulfilment | K38: CISO | L38: =N38/O38*100 -> 3.125 | M38: =SUMIF($J:$J,J38,$L:$L) -> 100 | N38: =COUNTIFS(E:E,K38,D:D,J38) -> 1 | O38: =SUMIF($J:$J,J38,$N:$N) -> 32 | P38: =SUMIFS(F:F,E:E,K38,D:D,J38) -> 1 | Q38: =SUMIF($J:$J,N38,$N:$N) -> 0 | Z38: ATC | AA38: =SUMIF($C:$C,Z38,$F:$F) -> 0.055555556 | AB38: =VLOOKUP(Z38,$AD:$AE,2,FALSE) -> Corporate | AD38: SEO | AE38: Operations
B39: 4 | C39: CCO | D39: eCommerce | E39: =VLOOKUP($C39,$AD:$AE,2,FALSE) -> Commercial | F39: =H39*SUMIFS($H:$H,$J:$J,D39,$K:$K,E39)/G39 -> 0.083333333 | G39: =SUMIFS($H$2:$H$1000,$E$2:$E$1000,E39,$D$2:$D$1000,D39) -> 12 | H39: 1 | J39: Mail & Services | K39: Commercial | L39: 38 | Z39: CCO | AA39: =SUMIF($C:$C,Z39,$F:$F) -> 0.083333333 | AB39: =VLOOKUP(Z39,$AD:$AE,2,FALSE) -> Commercial | AD39: BCTT | AE39: Technology
B40: 5 | C40: IDC | D40: eCommerce | E40: =VLOOKUP($C40,$AD:$AE,2,FALSE) -> Commercial | F40: =H40*SUMIFS($H:$H,$J:$J,D40,$K:$K,E40)/G40 -> 0.083333333 | G40: =SUMIFS($H$2:$H$1000,$E$2:$E$1000,E40,$D$2:$D$1000,D40) -> 12 | H40: 1 | J40: Mail & Services | K40: Operations | L40: 19 | Z40: IDC | AA40: =SUMIF($C:$C,Z40,$F:$F) -> 0.083333333 | AB40: =VLOOKUP(Z40,$AD:$AE,2,FALSE) -> Commercial | AD40: CIO | AE40: Technology
B41: 6 | C41: CFO | D41: eCommerce | E41: =VLOOKUP($C41,$AD:$AE,2,FALSE) -> Corporate | F41: =H41*SUMIFS($H:$H,$J:$J,D41,$K:$K,E41)/G41 -> 0.055555556 | G41: =SUMIFS($H$2:$H$1000,$E$2:$E$1000,E41,$D$2:$D$1000,D41) -> 18 | H41: 1 | J41: Mail & Services | K41: Corporate | L41: 19 | Z41: CFO | AA41: =SUMIF($C:$C,Z41,$F:$F) -> 0.055555556 | AB41: =VLOOKUP(Z41,$AD:$AE,2,FALSE) -> Corporate | AD41: SI | AE41: Technology
B42: 7 | C42: CIO | D42: eCommerce | E42: =VLOOKUP($C42,$AD:$AE,2,FALSE) -> Technology | F42: =H42*SUMIFS($H:$H,$J:$J,D42,$K:$K,E42)/G42 -> 0.16666667 | G42: =SUMIFS($H$2:$H$1000,$E$2:$E$1000,E42,$D$2:$D$1000,D42) -> 6 | H42: 1 | J42: Mail & Services | K42: Technology | L42: 17 | Z42: CIO | AA42: =SUMIF($C:$C,Z42,$F:$F) -> 0.16666667 | AB42: =VLOOKUP(Z42,$AD:$AE,2,FALSE) -> Technology | AD42: SI-CRP | AE42: Technology
B43: 8 | C43: PRO | D43: eCommerce | E43: =VLOOKUP($C43,$AD:$AE,2,FALSE) -> Corporate | F43: =H43*SUMIFS($H:$H,$J:$J,D43,$K:$K,E43)/G43 -> 0.055555556 | G43: =SUMIFS($H$2:$H$1000,$E$2:$E$1000,E43,$D$2:$D$1000,D43) -> 18 | H43: 1 | J43: Mail & Services | K43: Data & AI | L43: 5 | Z43: PRO | AA43: =SUMIF($C:$C,Z43,$F:$F) -> 0.055555556 | AB43: =VLOOKUP(Z43,$AD:$AE,2,FALSE) -> Corporate | AD43: SI-OPS | AE43: Technology
B44: 9 | C44: CHR | D44: eCommerce | E44: =VLOOKUP($C44,$AD:$AE,2,FALSE) -> Corporate | F44: =H44*SUMIFS($H:$H,$J:$J,D44,$K:$K,E44)/G44 -> 0.055555556 | G44: =SUMIFS($H$2:$H$1000,$E$2:$E$1000,E44,$D$2:$D$1000,D44) -> 18 | H44: 1 | J44: Mail & Services | K44: CISO | L44: 2 | Z44: CHR | AA44: =SUMIF($C:$C,Z44,$F:$F) -> 0.055555556 | AB44: =VLOOKUP(Z44,$AD:$AE,2,FALSE) -> Corporate | AD44: SI-PRD | AE44: Technology
B45: 11 | C45: GP ECL | D45: eCommerce | E45: =VLOOKUP($C45,$AD:$AE,2,FALSE) -> Commercial | F45: =H45*SUMIFS($H:$H,$J:$J,D45,$K:$K,E45)/G45 -> 0.083333333 | G45: =SUMIFS($H$2:$H$1000,$E$2:$E$1000,E45,$D$2:$D$1000,D45) -> 12 | H45: 1 | Z45: COM | AD45: IAD | AE45: Data & AI
B46: 12 | C46: CISO | D46: eCommerce | E46: =VLOOKUP($C46,$AD:$AE,2,FALSE) -> CISO | F46: =H46*SUMIFS($H:$H,$J:$J,D46,$K:$K,E46)/G46 -> 1 | G46: =SUMIFS($H$2:$H$1000,$E$2:$E$1000,E46,$D$2:$D$1000,D46) -> 1 | H46: 1 | Z46: 0 | AD46: NSP | AE46: Commercial
B47: 13 | C47: IAD | D47: eCommerce | E47: =VLOOKUP($C47,$AD:$AE,2,FALSE) -> Data & AI | F47: =H47*SUMIFS($H:$H,$J:$J,D47,$K:$K,E47)/G47 -> 1 | G47: =SUMIFS($H$2:$H$1000,$E$2:$E$1000,E47,$D$2:$D$1000,D47) -> 1 | H47: 1
B48: 14 | C48: GS | D48: eCommerce | E48: =VLOOKUP($C48,$AD:$AE,2,FALSE) -> Commercial | F48: =H48*SUMIFS($H:$H,$J:$J,D48,$K:$K,E48)/G48 -> 0.083333333 | G48: =SUMIFS($H$2:$H$1000,$E$2:$E$1000,E48,$D$2:$D$1000,D48) -> 12 | H48: 1
B49: 15 | C49: EDO | D49: eCommerce | E49: =VLOOKUP($C49,$AD:$AE,2,FALSE) -> Operations | F49: =H49*SUMIFS($H:$H,$J:$J,D49,$K:$K,E49)/G49 -> 0.25 | G49: =SUMIFS($H$2:$H$1000,$E$2:$E$1000,E49,$D$2:$D$1000,D49) -> 4 | H49: 1
B50: 16 | C50: ACR | D50: eCommerce | E50: =VLOOKUP($C50,$AD:$AE,2,FALSE) -> Corporate | F50: =H50*SUMIFS($H:$H,$J:$J,D50,$K:$K,E50)/G50 -> 0.055555556 | G50: =SUMIFS($H$2:$H$1000,$E$2:$E$1000,E50,$D$2:$D$1000,D50) -> 18 | H50: 1
B51: 17 | C51: SI | D51: eCommerce | E51: =VLOOKUP($C51,$AD:$AE,2,FALSE) -> Technology | F51: =H51*SUMIFS($H:$H,$J:$J,D51,$K:$K,E51)/G51 -> 0.16666667 | G51: =SUMIFS($H$2:$H$1000,$E$2:$E$1000,E51,$D$2:$D$1000,D51) -> 6 | H51: 1
...

Sheet tom_demand_setup (25)
B1: order | C1: EXPORT CSV | D1: WEIGHTS_RA | J1: EXPORT CSV | K1: Peso BG por RS | U1: EXPORT CSV | V1: WEIGHTS_RS | AF1: REF DATA | AJ1: REF DATA
B2: # | C2: RequestingArea | D2: RevenueStream | E2: BudgetGroup | F2: Weight | G2: Weight-RS+BG | H2: Weight-Base | J2: RevenueStream | K2: BudgetGroup | L2: Weight | M2: Check | N2: weight | O2: Check | P2: Count | Q2: Check | R2: Weight | S2: Check | U2: RevenueStream | V2: Weight | W2: Check | Y2: {=_xlfn.UNIQUE(E2:E1003)} -> BudgetGroup | Z2: Check | AB2: {=_xlfn.UNIQUE(C2:C1003)} -> RequestingArea | AC2: Check | AD2: hasBG? | AF2: RequestingArea | AG2: BudgetGroup | AH2: BusinessGroup | AJ2: MicroPhase bmap | AK2: MicroPhase Macro | AL2: MicroPhase Demand
B3: 1 | C3: GP B2B | D3: Business Solutions | E3: =VLOOKUP($C3,$AF:$AG,2,FALSE) -> Commercial | F3: =H3*SUMIFS($H:$H,$J:$J,D3,$K:$K,E3)/G3 -> 0.11111111 | G3: =SUMIFS($H$2:$H$1003,$E$2:$E$1003,E3,$D$2:$D$1003,D3) -> 9 | H3: 1 | J3: eCommerce | K3: Operations | L3: 25 | M3: =SUMIF($J:$J,J3,$L:$L) -> 100 | N3: =P3/Q3*100 -> 9.5238095 | O3: =SUMIF($J:$J,J3,$N:$N) -> 100 | P3: =COUNTIFS(E:E,K3,D:D,J3) -> 4 | Q3: =SUMIF($J:$J,J3,$P:$P) -> 42 | R3: =SUMIFS(F:F,E:E,K3,D:D,J3) -> 20.000003 | S3: =SUMIF($J:$J,P3,$P:$P) -> 0 | U3: eCommerce | V3: 40 | W3: =SUM(V3:V18) -> 100 | Y3: Commercial | Z3: =SUMIF($E:$E,Y3,$F:$F) -> 133.00002 | AB3: GP B2B | AC3: =SUMIF($C:$C,AB3,$F:$F) -> 16.569446 | AD3: =VLOOKUP(AB3,$AF:$AG,2,FALSE) -> Commercial | AF3: CISO | AG3: CISO | AJ3: IDEA > Backlog | AK3: {=_xlfn.TEXTSPLIT(AJ3,">",)} -> IDEA | AL3: Backlog
B4: 2 | C4: SEO | D4: Business Solutions | E4: =VLOOKUP($C4,$AF:$AG,2,FALSE) -> Operations | F4: =H4*SUMIFS($H:$H,$J:$J,D4,$K:$K,E4)/G4 -> 0.33333333 | G4: =SUMIFS($H$2:$H$1003,$E$2:$E$1003,E4,$D$2:$D$1003,D4) -> 3 | H4: 1 | J4: eCommerce | K4: Commercial | L4: 25 | M4: =SUMIF($J:$J,J4,$L:$L) -> 100 | N4: =P4/Q4*100 -> 28.571429 | O4: =SUMIF($J:$J,J4,$N:$N) -> 100 | P4: =COUNTIFS(E:E,K4,D:D,J4) -> 12 | Q4: =SUMIF($J:$J,J4,$P:$P) -> 42 | R4: =SUMIFS(F:F,E:E,K4,D:D,J4) -> 28.000009 | S4: =SUMIF($J:$J,P4,$P:$P) -> 0 | U4: Mail | V4: 22 | Y4: Operations | Z4: =SUMIF($E:$E,Y4,$F:$F) -> 125.00001 | AB4: SEO | AC4: =SUMIF($C:$C,AB4,$F:$F) -> 36.666669 | AD4: =VLOOKUP(AB4,$AF:$AG,2,FALSE) -> Operations | AF4: CCO | AG4: Commercial | AJ4: IDEA > Pitch | AK4: {=_xlfn.TEXTSPLIT(AJ4,">",)} -> IDEA | AL4: Pitch
B5: 3 | C5: CF | D5: Business Solutions | E5: =VLOOKUP($C5,$AF:$AG,2,FALSE) -> Corporate | F5: =H5*SUMIFS($H:$H,$J:$J,D5,$K:$K,E5)/G5 -> 0.071428571 | G5: =SUMIFS($H$2:$H$1003,$E$2:$E$1003,E5,$D$2:$D$1003,D5) -> 14 | H5: 1 | J5: eCommerce | K5: Corporate | L5: 20 | M5: =SUMIF($J:$J,J5,$L:$L) -> 100 | N5: =P5/Q5*100 -> 42.857143 | O5: =SUMIF($J:$J,J5,$N:$N) -> 100 | P5: =COUNTIFS(E:E,K5,D:D,J5) -> 18 | Q5: =SUMIF($J:$J,J5,$P:$P) -> 42 | R5: =SUMIFS(F:F,E:E,K5,D:D,J5) -> 37.000013 | S5: =SUMIF($J:$J,P5,$P:$P) -> 0 | U5: Business Solutions | V5: 16 | Y5: Corporate | Z5: =SUMIF($E:$E,Y5,$F:$F) -> 142.00003 | AB5: CF | AC5: =SUMIF($C:$C,AB5,$F:$F) -> 7.0938665 | AD5: =VLOOKUP(AB5,$AF:$AG,2,FALSE) -> Corporate | AF5: CMO | AG5: Commercial | AJ5: IDEA > In Definition | AK5: {=_xlfn.TEXTSPLIT(AJ5,">",)} -> IDEA | AL5: In Definition
B6: 4 | C6: SI | D6: Business Solutions | E6: =VLOOKUP($C6,$AF:$AG,2,FALSE) -> Technology | F6: =H6*SUMIFS($H:$H,$J:$J,D6,$K:$K,E6)/G6 -> 0.2 | G6: =SUMIFS($H$2:$H$1003,$E$2:$E$1003,E6,$D$2:$D$1003,D6) -> 5 | H6: 1 | J6: eCommerce | K6: Technology | L6: 20 | M6: =SUMIF($J:$J,J6,$L:$L) -> 100 | N6: =P6/Q6*100 -> 14.285714 | O6: =SUMIF($J:$J,J6,$N:$N) -> 100 | P6: =COUNTIFS(E:E,K6,D:D,J6) -> 6 | Q6: =SUMIF($J:$J,J6,$P:$P) -> 42 | R6: =SUMIFS(F:F,E:E,K6,D:D,J6) -> 15.000005 | S6: =SUMIF($J:$J,P6,$P:$P) -> 0 | U6: Retail & Financial Services | V6: 10 | Y6: Technology | Z6: =SUMIF($E:$E,Y6,$F:$F) -> 120.00001 | AB6: SI | AC6: =SUMIF($C:$C,AB6,$F:$F) -> 41.000002 | AD6: =VLOOKUP(AB6,$AF:$AG,2,FALSE) -> Technology | AF6: CSI | AG6: Commercial | AJ6: SOLUTION > In Approval | AK6: {=_xlfn.TEXTSPLIT(AJ6,">",)} -> SOLUTION | AL6: In Approval
B7: 5 | C7: CISO | D7: Business Solutions | E7: =VLOOKUP($C7,$AF:$AG,2,FALSE) -> CISO | F7: =H7*SUMIFS($H:$H,$J:$J,D7,$K:$K,E7)/G7 -> 1 | G7: =SUMIFS($H$2:$H$1003,$E$2:$E$1003,E7,$D$2:$D$1003,D7) -> 1 | H7: 1 | J7: eCommerce | K7: Data & AI | L7: 5 | M7: =SUMIF($J:$J,J7,$L:$L) -> 100 | N7: =P7/Q7*100 -> 2.3809524 | O7: =SUMIF($J:$J,J7,$N:$N) -> 100 | P7: =COUNTIFS(E:E,K7,D:D,J7) -> 1 | Q7: =SUMIF($J:$J,J7,$P:$P) -> 42 | R7: =SUMIFS(F:F,E:E,K7,D:D,J7) -> 1e-06 | S7: =SUMIF($J:$J,P7,$P:$P) -> 0 | U7: Payments | V7: 8 | Y7: CISO | Z7: =SUMIF($E:$E,Y7,$F:$F) -> 105 | AB7: CISO | AC7: =SUMIF($C:$C,AB7,$F:$F) -> 105 | AD7: =VLOOKUP(AB7,$AF:$AG,2,FALSE) -> CISO | AF7: CTTE | AG7: Commercial | AJ7: SOLUTION > Ready for Approval | AK7: {=_xlfn.TEXTSPLIT(AJ7,">",)} -> SOLUTION | AL7: Ready for Approval
B8: 6 | C8: IAD | D8: Business Solutions | E8: =VLOOKUP($C8,$AF:$AG,2,FALSE) -> Data & AI | F8: =H8*SUMIFS($H:$H,$J:$J,D8,$K:$K,E8)/G8 -> 1 | G8: =SUMIFS($H$2:$H$1003,$E$2:$E$1003,E8,$D$2:$D$1003,D8) -> 1 | H8: 1 | J8: eCommerce | K8: CISO | L8: 5 | M8: =SUMIF($J:$J,J8,$L:$L) -> 100 | N8: =P8/Q8*100 -> 2.3809524 | O8: =SUMIF($J:$J,J8,$N:$N) -> 100 | P8: =COUNTIFS(E:E,K8,D:D,J8) -> 1 | Q8: =SUMIF($J:$J,J8,$P:$P) -> 42 | R8: =SUMIFS(F:F,E:E,K8,D:D,J8) -> 1e-06 | S8: =SUMIF($J:$J,P8,$P:$P) -> 0 | U8: Fulfilment | V8: 4 | Y8: Data & AI | Z8: =SUMIF($E:$E,Y8,$F:$F) -> 105 | AB8: IAD | AC8: =SUMIF($C:$C,AB8,$F:$F) -> 104.14286 | AD8: =VLOOKUP(AB8,$AF:$AG,2,FALSE) -> Data & AI | AF8: DNI | AG8: Commercial | AJ8: IDEA > Ready for Solution | AK8: {=_xlfn.TEXTSPLIT(AJ8,">",)} -> IDEA | AL8: Ready for Solution
B9: 7 | C9: GS | D9: Business Solutions | E9: =VLOOKUP($C9,$AF:$AG,2,FALSE) -> Commercial | F9: =H9*SUMIFS($H:$H,$J:$J,D9,$K:$K,E9)/G9 -> 0.11111111 | G9: =SUMIFS($H$2:$H$1003,$E$2:$E$1003,E9,$D$2:$D$1003,D9) -> 9 | H9: 1 | J9: Mail | K9: Commercial | L9: 25 | M9: =SUMIF($J:$J,J9,$L:$L) -> 100 | N9: =P9/Q9*100 -> 28.125 | O9: =SUMIF($J:$J,J9,$N:$N) -> 100 | P9: =COUNTIFS(E:E,K9,D:D,J9) -> 9 | Q9: =SUMIF($J:$J,J9,$P:$P) -> 32 | R9: =SUMIFS(F:F,E:E,K9,D:D,J9) -> 1 | S9: =SUMIF($J:$J,P9,$P:$P) -> 0 | U9: Banco CTT | V9: 0 | Y9: 0 | Z9: =SUMIF($E:$E,Y9,$F:$F) -> 0 | AB9: GS | AC9: =SUMIF($C:$C,AB9,$F:$F) -> 12.569446 | AD9: =VLOOKUP(AB9,$AF:$AG,2,FALSE) -> Commercial | AF9: ECM | AG9: Commercial | AJ9: SOLUTION > High Level Design | AK9: {=_xlfn.TEXTSPLIT(AJ9,">",)} -> SOLUTION | AL9: High Level Design
B10: 8 | C10: ACR | D10: Business Solutions | E10: =VLOOKUP($C10,$AF:$AG,2,FALSE) -> Corporate | F10: =H10*SUMIFS($H:$H,$J:$J,D10,$K:$K,E10)/G10 -> 0.071428571 | G10: =SUMIFS($H$2:$H$1003,$E$2:$E$1003,E10,$D$2:$D$1003,D10) -> 14 | H10: 1 | J10: Mail | K10: Operations | L10: 25 | M10: =SUMIF($J:$J,J10,$L:$L) -> 100 | N10: =P10/Q10*100 -> 9.375 | O10: =SUMIF($J:$J,J10,$N:$N) -> 100 | P10: =COUNTIFS(E:E,K10,D:D,J10) -> 3 | Q10: =SUMIF($J:$J,J10,$P:$P) -> 32 | R10: =SUMIFS(F:F,E:E,K10,D:D,J10) -> 1 | S10: =SUMIF($J:$J,P10,$P:$P) -> 0 | Z10: =SUMIF($E:$E,Y10,$F:$F) -> 0 | AB10: ACR | AC10: =SUMIF($C:$C,AB10,$F:$F) -> 7.0938665 | AD10: =VLOOKUP(AB10,$AF:$AG,2,FALSE) -> Corporate | AF10: GP B2B | AG10: Commercial | AJ10: SOLUTION > Ready for Development | AK10: {=_xlfn.TEXTSPLIT(AJ10,">",)} -> SOLUTION | AL10: Ready for Development
B11: 9 | C11: EDO | D11: Business Solutions | E11: =VLOOKUP($C11,$AF:$AG,2,FALSE) -> Operations | F11: =H11*SUMIFS($H:$H,$J:$J,D11,$K:$K,E11)/G11 -> 0.33333333 | G11: =SUMIFS($H$2:$H$1003,$E$2:$E$1003,E11,$D$2:$D$1003,D11) -> 3 | H11: 1 | J11: Mail | K11: Corporate | L11: 20 | M11: =SUMIF($J:$J,J11,$L:$L) -> 100 | N11: =P11/Q11*100 -> 40.625 | O11: =SUMIF($J:$J,J11,$N:$N) -> 100 | P11: =COUNTIFS(E:E,K11,D:D,J11) -> 13 | Q11: =SUMIF($J:$J,J11,$P:$P) -> 32 | R11: =SUMIFS(F:F,E:E,K11,D:D,J11) -> 1 | S11: =SUMIF($J:$J,P11,$P:$P) -> 0 | Z11: =SUMIF($E:$E,Y11,$F:$F) -> 0 | AB11: EDO | AC11: =SUMIF($C:$C,AB11,$F:$F) -> 36.666669 | AD11: =VLOOKUP(AB11,$AF:$AG,2,FALSE) -> Operations | AF11: GP B2C | AG11: Commercial | AJ11: SOLUTION > In Definition | AK11: {=_xlfn.TEXTSPLIT(AJ11,">",)} -> SOLUTION | AL11: In Definition
B12: 10 | C12: SI-OPS | D12: Business Solutions | E12: =VLOOKUP($C12,$AF:$AG,2,FALSE) -> Technology | F12: =H12*SUMIFS($H:$H,$J:$J,D12,$K:$K,E12)/G12 -> 0.2 | G12: =SUMIFS($H$2:$H$1003,$E$2:$E$1003,E12,$D$2:$D$1003,D12) -> 5 | H12: 1 | J12: Mail | K12: Technology | L12: 20 | M12: =SUMIF($J:$J,J12,$L:$L) -> 100 | N12: =P12/Q12*100 -> 15.625 | O12: =SUMIF($J:$J,J12,$N:$N) -> 100 | P12: =COUNTIFS(E:E,K12,D:D,J12) -> 5 | Q12: =SUMIF($J:$J,J12,$P:$P) -> 32 | R12: =SUMIFS(F:F,E:E,K12,D:D,J12) -> 1 | S12: =SUMIF($J:$J,P12,$P:$P) -> 0 | Z12: =SUMIF($E:$E,Y12,$F:$F) -> 0 | AB12: SI-OPS | AC12: =SUMIF($C:$C,AB12,$F:$F) -> 16.000002 | AD12: =VLOOKUP(AB12,$AF:$AG,2,FALSE) -> Technology | AF12: GP ECL | AG12: Commercial
B13: 11 | C13: DNI | D13: Business Solutions | E13: =VLOOKUP($C13,$AF:$AG,2,FALSE) -> Commercial | F13: =H13*SUMIFS($H:$H,$J:$J,D13,$K:$K,E13)/G13 -> 0.11111111 | G13: =SUMIFS($H$2:$H$1003,$E$2:$E$1003,E13,$D$2:$D$1003,D13) -> 9 | H13: 1 | J13: Mail | K13: Data & AI | L13: 5 | M13: =SUMIF($J:$J,J13,$L:$L) -> 100 | N13: =P13/Q13*100 -> 3.125 | O13: =SUMIF($J:$J,J13,$N:$N) -> 100 | P13: =COUNTIFS(E:E,K13,D:D,J13) -> 1 | Q13: =SUMIF($J:$J,J13,$P:$P) -> 32 | R13: =SUMIFS(F:F,E:E,K13,D:D,J13) -> 1 | S13: =SUMIF($J:$J,P13,$P:$P) -> 0 | Z13: =SUMIF($E:$E,Y13,$F:$F) -> 0 | AB13: DNI | AC13: =SUMIF($C:$C,AB13,$F:$F) -> 16.569446 | AD13: =VLOOKUP(AB13,$AF:$AG,2,FALSE) -> Commercial | AF13: GPG | AG13: Commercial
B14: 12 | C14: AVC | D14: Business Solutions | E14: =VLOOKUP($C14,$AF:$AG,2,FALSE) -> Corporate | F14: =H14*SUMIFS($H:$H,$J:$J,D14,$K:$K,E14)/G14 -> 0.071428571 | G14: =SUMIFS($H$2:$H$1003,$E$2:$E$1003,E14,$D$2:$D$1003,D14) -> 14 | H14: 1 | J14: Mail | K14: CISO | L14: 5 | M14: =SUMIF($J:$J,J14,$L:$L) -> 100 | N14: =P14/Q14*100 -> 3.125 | O14: =SUMIF($J:$J,J14,$N:$N) -> 100 | P14: =COUNTIFS(E:E,K14,D:D,J14) -> 1 | Q14: =SUMIF($J:$J,J14,$P:$P) -> 32 | R14: =SUMIFS(F:F,E:E,K14,D:D,J14) -> 1 | S14: =SUMIF($J:$J,P14,$P:$P) -> 0 | Z14: =SUMIF($E:$E,Y14,$F:$F) -> 0 | AB14: AVC | AC14: =SUMIF($C:$C,AB14,$F:$F) -> 7.0938665 | AD14: =VLOOKUP(AB14,$AF:$AG,2,FALSE) -> Corporate | AF14: GS | AG14: Commercial
B15: 13 | C15: EM | D15: Business Solutions | E15: =VLOOKUP($C15,$AF:$AG,2,FALSE) -> Operations | F15: =H15*SUMIFS($H:$H,$J:$J,D15,$K:$K,E15)/G15 -> 0.33333333 | G15: =SUMIFS($H$2:$H$1003,$E$2:$E$1003,E15,$D$2:$D$1003,D15) -> 3 | H15: 1 | J15: Business Solutions | K15: Commercial | L15: 25 | M15: =SUMIF($J:$J,J15,$L:$L) -> 100 | N15: =P15/Q15*100 -> 27.272727 | O15: =SUMIF($J:$J,J15,$N:$N) -> 100 | P15: =COUNTIFS(E:E,K15,D:D,J15) -> 9 | Q15: =SUMIF($J:$J,J15,$P:$P) -> 33 | R15: =SUMIFS(F:F,E:E,K15,D:D,J15) -> 1 | S15: =SUMIF($J:$J,P15,$P:$P) -> 0 | AB15: EM | AC15: =SUMIF($C:$C,AB15,$F:$F) -> 31.666669 | AD15: =VLOOKUP(AB15,$AF:$AG,2,FALSE) -> Operations | AF15: IDC | AG15: Commercial
B16: 14 | C16: SI-PRD | D16: Business Solutions | E16: =VLOOKUP($C16,$AF:$AG,2,FALSE) -> Technology | F16: =H16*SUMIFS($H:$H,$J:$J,D16,$K:$K,E16)/G16 -> 0.2 | G16: =SUMIFS($H$2:$H$1003,$E$2:$E$1003,E16,$D$2:$D$1003,D16) -> 5 | H16: 1 | J16: Business Solutions | K16: Operations | L16: 25 | M16: =SUMIF($J:$J,J16,$L:$L) -> 100 | N16: =P16/Q16*100 -> 9.0909091 | O16: =SUMIF($J:$J,J16,$N:$N) -> 100 | P16: =COUNTIFS(E:E,K16,D:D,J16) -> 3 | Q16: =SUMIF($J:$J,J16,$P:$P) -> 33 | R16: =SUMIFS(F:F,E:E,K16,D:D,J16) -> 1 | S16: =SUMIF($J:$J,P16,$P:$P) -> 0 | AB16: SI-PRD | AC16: =SUMIF($C:$C,AB16,$F:$F) -> 16.000002 | AD16: =VLOOKUP(AB16,$AF:$AG,2,FALSE) -> Technology | AF16: ACR | AG16: Corporate
B17: 15 | C17: CSI | D17: Business Solutions | E17: =VLOOKUP($C17,$AF:$AG,2,FALSE) -> Commercial | F17: =H17*SUMIFS($H:$H,$J:$J,D17,$K:$K,E17)/G17 -> 0.11111111 | G17: =SUMIFS($H$2:$H$1003,$E$2:$E$1003,E17,$D$2:$D$1003,D17) -> 9 | H17: 1 | J17: Business Solutions | K17: Corporate | L17: 20 | M17: =SUMIF($J:$J,J17,$L:$L) -> 100 | N17: =P17/Q17*100 -> 42.424242 | O17: =SUMIF($J:$J,J17,$N:$N) -> 100 | P17: =COUNTIFS(E:E,K17,D:D,J17) -> 14 | Q17: =SUMIF($J:$J,J17,$P:$P) -> 33 | R17: =SUMIFS(F:F,E:E,K17,D:D,J17) -> 1 | S17: =SUMIF($J:$J,P17,$P:$P) -> 0 | AB17: CSI | AC17: =SUMIF($C:$C,AB17,$F:$F) -> 10.569446 | AD17: =VLOOKUP(AB17,$AF:$AG,2,FALSE) -> Commercial | AF17: ATC | AG17: Corporate
B18: 16 | C18: GT | D18: Business Solutions | E18: =VLOOKUP($C18,$AF:$AG,2,FALSE) -> Corporate | F18: =H18*SUMIFS($H:$H,$J:$J,D18,$K:$K,E18)/G18 -> 0.071428571 | G18: =SUMIFS($H$2:$H$1003,$E$2:$E$1003,E18,$D$2:$D$1003,D18) -> 14 | H18: 1 | J18: Business Solutions | K18: Technology | L18: 20 | M18: =SUMIF($J:$J,J18,$L:$L) -> 100 | N18: =P18/Q18*100 -> 15.151515 | O18: =SUMIF($J:$J,J18,$N:$N) -> 100 | P18: =COUNTIFS(E:E,K18,D:D,J18) -> 5 | Q18: =SUMIF($J:$J,J18,$P:$P) -> 33 | R18: =SUMIFS(F:F,E:E,K18,D:D,J18) -> 1 | S18: =SUMIF($J:$J,P18,$P:$P) -> 0 | U18: RevenueStream;BudgetGroup;Weight | AB18: GT | AC18: =SUMIF($C:$C,AB18,$F:$F) -> 7.0938665 | AD18: =VLOOKUP(AB18,$AF:$AG,2,FALSE) -> Corporate | AF18: AVC | AG18: Corporate
B19: 17 | C19: BCTT | D19: Business Solutions | E19: =VLOOKUP($C19,$AF:$AG,2,FALSE) -> Technology | F19: =H19*SUMIFS($H:$H,$J:$J,D19,$K:$K,E19)/G19 -> 0.2 | G19: =SUMIFS($H$2:$H$1003,$E$2:$E$1003,E19,$D$2:$D$1003,D19) -> 5 | H19: 1 | J19: Business Solutions | K19: Data & AI | L19: 5 | M19: =SUMIF($J:$J,J19,$L:$L) -> 100 | N19: =P19/Q19*100 -> 3.030303 | O19: =SUMIF($J:$J,J19,$N:$N) -> 100 | P19: =COUNTIFS(E:E,K19,D:D,J19) -> 1 | Q19: =SUMIF($J:$J,J19,$P:$P) -> 33 | R19: =SUMIFS(F:F,E:E,K19,D:D,J19) -> 1 | S19: =SUMIF($J:$J,P19,$P:$P) -> 0 | AB19: BCTT | AC19: =SUMIF($C:$C,AB19,$F:$F) -> 16.000002 | AD19: =VLOOKUP(AB19,$AF:$AG,2,FALSE) -> Technology | AF19: CF | AG19: Corporate
B20: 18 | C20: GP B2C | D20: Business Solutions | E20: =VLOOKUP($C20,$AF:$AG,2,FALSE) -> Commercial | F20: =H20*SUMIFS($H:$H,$J:$J,D20,$K:$K,E20)/G20 -> 0.11111111 | G20: =SUMIFS($H$2:$H$1003,$E$2:$E$1003,E20,$D$2:$D$1003,D20) -> 9 | H20: 1 | J20: Business Solutions | K20: CISO | L20: 5 | M20: =SUMIF($J:$J,J20,$L:$L) -> 100 | N20: =P20/Q20*100 -> 3.030303 | O20: =SUMIF($J:$J,J20,$N:$N) -> 100 | P20: =COUNTIFS(E:E,K20,D:D,J20) -> 1 | Q20: =SUMIF($J:$J,J20,$P:$P) -> 33 | R20: =SUMIFS(F:F,E:E,K20,D:D,J20) -> 1 | S20: =SUMIF($J:$J,P20,$P:$P) -> 0 | AB20: GP B2C | AC20: =SUMIF($C:$C,AB20,$F:$F) -> 9.5694464 | AD20: =VLOOKUP(AB20,$AF:$AG,2,FALSE) -> Commercial | AF20: CFO | AG20: Corporate
B21: 19 | C21: GRH | D21: Business Solutions | E21: =VLOOKUP($C21,$AF:$AG,2,FALSE) -> Corporate | F21: =H21*SUMIFS($H:$H,$J:$J,D21,$K:$K,E21)/G21 -> 0.071428571 | G21: =SUMIFS($H$2:$H$1003,$E$2:$E$1003,E21,$D$2:$D$1003,D21) -> 14 | H21: 1 | J21: Retail & Financial Services | K21: Commercial | L21: 25 | M21: =SUMIF($J:$J,J21,$L:$L) -> 100 | N21: =P21/Q21*100 -> 25 | O21: =SUMIF($J:$J,J21,$N:$N) -> 100 | P21: =COUNTIFS(E:E,K21,D:D,J21) -> 8 | Q21: =SUMIF($J:$J,J21,$P:$P) -> 32 | R21: =SUMIFS(F:F,E:E,K21,D:D,J21) -> 1 | S21: =SUMIF($J:$J,P21,$P:$P) -> 0 | AB21: GRH | AC21: =SUMIF($C:$C,AB21,$F:$F) -> 7.0938665 | AD21: =VLOOKUP(AB21,$AF:$AG,2,FALSE) -> Corporate | AF21: CHR | AG21: Corporate
B22: 20 | C22: SI-CRP | D22: Business Solutions | E22: =VLOOKUP($C22,$AF:$AG,2,FALSE) -> Technology | F22: =H22*SUMIFS($H:$H,$J:$J,D22,$K:$K,E22)/G22 -> 0.2 | G22: =SUMIFS($H$2:$H$1003,$E$2:$E$1003,E22,$D$2:$D$1003,D22) -> 5 | H22: 1 | J22: Retail & Financial Services | K22: Operations | L22: 25 | M22: =SUMIF($J:$J,J22,$L:$L) -> 100 | N22: =P22/Q22*100 -> 9.375 | O22: =SUMIF($J:$J,J22,$N:$N) -> 100 | P22: =COUNTIFS(E:E,K22,D:D,J22) -> 3 | Q22: =SUMIF($J:$J,J22,$P:$P) -> 32 | R22: =SUMIFS(F:F,E:E,K22,D:D,J22) -> 1 | S22: =SUMIF($J:$J,P22,$P:$P) -> 0 | AB22: SI-CRP | AC22: =SUMIF($C:$C,AB22,$F:$F) -> 16.000002 | AD22: =VLOOKUP(AB22,$AF:$AG,2,FALSE) -> Technology | AF22: CL | AG22: Corporate
B23: 21 | C23: GP ECL | D23: Business Solutions | E23: =VLOOKUP($C23,$AF:$AG,2,FALSE) -> Commercial | F23: =H23*SUMIFS($H:$H,$J:$J,D23,$K:$K,E23)/G23 -> 0.11111111 | G23: =SUMIFS($H$2:$H$1003,$E$2:$E$1003,E23,$D$2:$D$1003,D23) -> 9 | H23: 1 | J23: Retail & Financial Services | K23: Corporate | L23: 20 | M23: =SUMIF($J:$J,J23,$L:$L) -> 100 | N23: =P23/Q23*100 -> 25 | O23: =SUMIF($J:$J,J23,$N:$N) -> 100 | P23: =COUNTIFS(E:E,K23,D:D,J23) -> 8 | Q23: =SUMIF($J:$J,J23,$P:$P) -> 32 | R23: =SUMIFS(F:F,E:E,K23,D:D,J23) -> 1 | S23: =SUMIF($J:$J,P23,$P:$P) -> 0 | AB23: GP ECL | AC23: =SUMIF($C:$C,AB23,$F:$F) -> 16.569446 | AD23: =VLOOKUP(AB23,$AF:$AG,2,FALSE) -> Commercial | AF23: CMP | AG23: Corporate
B24: 22 | C24: PC | D24: Business Solutions | E24: =VLOOKUP($C24,$AF:$AG,2,FALSE) -> Corporate | F24: =H24*SUMIFS($H:$H,$J:$J,D24,$K:$K,E24)/G24 -> 0.071428571 | G24: =SUMIFS($H$2:$H$1003,$E$2:$E$1003,E24,$D$2:$D$1003,D24) -> 14 | H24: 1 | J24: Retail & Financial Services | K24: Technology | L24: 20 | M24: =SUMIF($J:$J,J24,$L:$L) -> 100 | N24: =P24/Q24*100 -> 15.625 | O24: =SUMIF($J:$J,J24,$N:$N) -> 100 | P24: =COUNTIFS(E:E,K24,D:D,J24) -> 5 | Q24: =SUMIF($J:$J,J24,$P:$P) -> 32 | R24: =SUMIFS(F:F,E:E,K24,D:D,J24) -> 1 | S24: =SUMIF($J:$J,P24,$P:$P) -> 0 | AB24: PC | AC24: =SUMIF($C:$C,AB24,$F:$F) -> 7.0938665 | AD24: =VLOOKUP(AB24,$AF:$AG,2,FALSE) -> Corporate | AF24: COM | AG24: Corporate
B25: 23 | C25: GPG | D25: Business Solutions | E25: =VLOOKUP($C25,$AF:$AG,2,FALSE) -> Commercial | F25: =H25*SUMIFS($H:$H,$J:$J,D25,$K:$K,E25)/G25 -> 0.11111111 | G25: =SUMIFS($H$2:$H$1003,$E$2:$E$1003,E25,$D$2:$D$1003,D25) -> 9 | H25: 1 | J25: Retail & Financial Services | K25: Data & AI | L25: 5 | M25: =SUMIF($J:$J,J25,$L:$L) -> 100 | N25: =P25/Q25*100 -> 21.875 | O25: =SUMIF($J:$J,J25,$N:$N) -> 100 | P25: =COUNTIFS(E:E,K25,D:D,J25) -> 7 | Q25: =SUMIF($J:$J,J25,$P:$P) -> 32 | R25: =SUMIFS(F:F,E:E,K25,D:D,J25) -> 1 | S25: =SUMIF($J:$J,P25,$P:$P) -> 0 | AB25: GPG | AC25: =SUMIF($C:$C,AB25,$F:$F) -> 9.5694464 | AD25: =VLOOKUP(AB25,$AF:$AG,2,FALSE) -> Commercial | AF25: DPO | AG25: Corporate
B26: 24 | C26: RS | D26: Business Solutions | E26: =VLOOKUP($C26,$AF:$AG,2,FALSE) -> Corporate | F26: =H26*SUMIFS($H:$H,$J:$J,D26,$K:$K,E26)/G26 -> 0.071428571 | G26: =SUMIFS($H$2:$H$1003,$E$2:$E$1003,E26,$D$2:$D$1003,D26) -> 14 | H26: 1 | J26: Retail & Financial Services | K26: CISO | L26: 5 | M26: =SUMIF($J:$J,J26,$L:$L) -> 100 | N26: =P26/Q26*100 -> 3.125 | O26: =SUMIF($J:$J,J26,$N:$N) -> 100 | P26: =COUNTIFS(E:E,K26,D:D,J26) -> 1 | Q26: =SUMIF($J:$J,J26,$P:$P) -> 32 | R26: =SUMIFS(F:F,E:E,K26,D:D,J26) -> 1 | S26: =SUMIF($J:$J,P26,$P:$P) -> 0 | AB26: RS | AC26: =SUMIF($C:$C,AB26,$F:$F) -> 7.0938665 | AD26: =VLOOKUP(AB26,$AF:$AG,2,FALSE) -> Corporate | AF26: FL | AG26: Corporate
B27: 25 | C27: ECM | D27: Business Solutions | E27: =VLOOKUP($C27,$AF:$AG,2,FALSE) -> Commercial | F27: =H27*SUMIFS($H:$H,$J:$J,D27,$K:$K,E27)/G27 -> 0.11111111 | G27: =SUMIFS($H$2:$H$1003,$E$2:$E$1003,E27,$D$2:$D$1003,D27) -> 9 | H27: 1 | J27: Payments | K27: Commercial | L27: 25 | M27: =SUMIF($J:$J,J27,$L:$L) -> 100 | N27: =P27/Q27*100 -> 28.125 | O27: =SUMIF($J:$J,J27,$N:$N) -> 100 | P27: =COUNTIFS(E:E,K27,D:D,J27) -> 9 | Q27: =SUMIF($J:$J,J27,$P:$P) -> 32 | R27: =SUMIFS(F:F,E:E,K27,D:D,J27) -> 1 | S27: =SUMIF($J:$J,P27,$P:$P) -> 0 | AB27: ECM | AC27: =SUMIF($C:$C,AB27,$F:$F) -> 3.5694464 | AD27: =VLOOKUP(AB27,$AF:$AG,2,FALSE) -> Commercial | AF27: GRH | AG27: Corporate
B28: 26 | C28: CL | D28: Business Solutions | E28: =VLOOKUP($C28,$AF:$AG,2,FALSE) -> Corporate | F28: =H28*SUMIFS($H:$H,$J:$J,D28,$K:$K,E28)/G28 -> 0.071428571 | G28: =SUMIFS($H$2:$H$1003,$E$2:$E$1003,E28,$D$2:$D$1003,D28) -> 14 | H28: 1 | J28: Payments | K28: Operations | L28: 25 | M28: =SUMIF($J:$J,J28,$L:$L) -> 100 | N28: =P28/Q28*100 -> 9.375 | O28: =SUMIF($J:$J,J28,$N:$N) -> 100 | P28: =COUNTIFS(E:E,K28,D:D,J28) -> 3 | Q28: =SUMIF($J:$J,J28,$P:$P) -> 32 | R28: =SUMIFS(F:F,E:E,K28,D:D,J28) -> 1 | S28: =SUMIF($J:$J,P28,$P:$P) -> 0 | AB28: CL | AC28: =SUMIF($C:$C,AB28,$F:$F) -> 7.0938665 | AD28: =VLOOKUP(AB28,$AF:$AG,2,FALSE) -> Corporate | AF28: GT | AG28: Corporate
B29: 27 | C29: CTTE | D29: Business Solutions | E29: =VLOOKUP($C29,$AF:$AG,2,FALSE) -> Commercial | F29: =H29*SUMIFS($H:$H,$J:$J,D29,$K:$K,E29)/G29 -> 0.11111111 | G29: =SUMIFS($H$2:$H$1003,$E$2:$E$1003,E29,$D$2:$D$1003,D29) -> 9 | H29: 1 | J29: Payments | K29: Corporate | L29: 20 | M29: =SUMIF($J:$J,J29,$L:$L) -> 100 | N29: =P29/Q29*100 -> 40.625 | O29: =SUMIF($J:$J,J29,$N:$N) -> 100 | P29: =COUNTIFS(E:E,K29,D:D,J29) -> 13 | Q29: =SUMIF($J:$J,J29,$P:$P) -> 32 | R29: =SUMIFS(F:F,E:E,K29,D:D,J29) -> 1 | S29: =SUMIF($J:$J,P29,$P:$P) -> 0 | AB29: CTTE | AC29: =SUMIF($C:$C,AB29,$F:$F) -> 9.5873036 | AD29: =VLOOKUP(AB29,$AF:$AG,2,FALSE) -> Commercial | AF29: PC | AG29: Corporate
B30: 28 | C30: DPO | D30: Business Solutions | E30: =VLOOKUP($C30,$AF:$AG,2,FALSE) -> Corporate | F30: =H30*SUMIFS($H:$H,$J:$J,D30,$K:$K,E30)/G30 -> 0.071428571 | G30: =SUMIFS($H$2:$H$1003,$E$2:$E$1003,E30,$D$2:$D$1003,D30) -> 14 | H30: 1 | J30: Payments | K30: Technology | L30: 20 | M30: =SUMIF($J:$J,J30,$L:$L) -> 100 | N30: =P30/Q30*100 -> 15.625 | O30: =SUMIF($J:$J,J30,$N:$N) -> 100 | P30: =COUNTIFS(E:E,K30,D:D,J30) -> 5 | Q30: =SUMIF($J:$J,J30,$P:$P) -> 32 | R30: =SUMIFS(F:F,E:E,K30,D:D,J30) -> 1 | S30: =SUMIF($J:$J,P30,$P:$P) -> 0 | AB30: DPO | AC30: =SUMIF($C:$C,AB30,$F:$F) -> 7.1117236 | AD30: =VLOOKUP(AB30,$AF:$AG,2,FALSE) -> Corporate | AF30: PRO | AG30: Corporate
... B35: 33 | C35: NSP | D35: Business Solutions | E35: =VLOOKUP($C35,$AF:$AG,2,FALSE) -> Corporate | F35: =H35*SUMIFS($H:$H,$J:$J,D35,$K:$K,E35)/G35 -> 0.071428571 | G35: =SUMIFS($H$2:$H$1003,$E$2:$E$1003,E35,$D$2:$D$1003,D35) -> 14 | H35: 1 | J35: Fulfilment | K35: Corporate | L35: 20 | M35: =SUMIF($J:$J,J35,$L:$L) -> 100 | N35: =P35/Q35*100 -> 40.625 | O35: =SUMIF($J:$J,J35,$N:$N) -> 100 | P35: =COUNTIFS(E:E,K35,D:D,J35) -> 13 | Q35: =SUMIF($J:$J,J35,$P:$P) -> 32 | R35: =SUMIFS(F:F,E:E,K35,D:D,J35) -> 1 | S35: =SUMIF($J:$J,P35,$P:$P) -> 0 | AB35: NSP | AC35: =SUMIF($C:$C,AB35,$F:$F) -> 6.7380952 | AD35: =VLOOKUP(AB35,$AF:$AG,2,FALSE) -> Corporate | AF35: EDO | AG35: Operations
B36: 1 | C36: COO | D36: eCommerce | E36: =VLOOKUP($C36,$AF:$AG,2,FALSE) -> Operations | F36: 20 | G36: =SUMIFS($H$2:$H$1003,$E$2:$E$1003,E36,$D$2:$D$1003,D36) -> 4 | H36: 1 | J36: Fulfilment | K36: Technology | L36: 20 | M36: =SUMIF($J:$J,J36,$L:$L) -> 100 | N36: =P36/Q36*100 -> 15.625 | O36: =SUMIF($J:$J,J36,$N:$N) -> 100 | P36: =COUNTIFS(E:E,K36,D:D,J36) -> 5 | Q36: =SUMIF($J:$J,J36,$P:$P) -> 32 | R36: =SUMIFS(F:F,E:E,K36,D:D,J36) -> 1 | S36: =SUMIF($J:$J,P36,$P:$P) -> 0 | AB36: COO | AC36: =SUMIF($C:$C,AB36,$F:$F) -> 20.000001 | AD36: =VLOOKUP(AB36,$AF:$AG,2,FALSE) -> Operations | AF36: EM | AG36: Operations
B37: 2 | C37: CMO | D37: eCommerce | E37: =VLOOKUP($C37,$AF:$AG,2,FALSE) -> Commercial | F37: 12 | G37: =SUMIFS($H$2:$H$1003,$E$2:$E$1003,E37,$D$2:$D$1003,D37) -> 12 | H37: 1 | J37: Fulfilment | K37: Data & AI | L37: 5 | M37: =SUMIF($J:$J,J37,$L:$L) -> 100 | N37: =P37/Q37*100 -> 3.125 | O37: =SUMIF($J:$J,J37,$N:$N) -> 100 | P37: =COUNTIFS(E:E,K37,D:D,J37) -> 1 | Q37: =SUMIF($J:$J,J37,$P:$P) -> 32 | R37: =SUMIFS(F:F,E:E,K37,D:D,J37) -> 1 | S37: =SUMIF($J:$J,P37,$P:$P) -> 0 | AB37: CMO | AC37: =SUMIF($C:$C,AB37,$F:$F) -> 12.000001 | AD37: =VLOOKUP(AB37,$AF:$AG,2,FALSE) -> Commercial | AF37: EM | AG37: Operations
B38: 3 | C38: ATC | D38: eCommerce | E38: =VLOOKUP($C38,$AF:$AG,2,FALSE) -> Corporate | F38: 12 | G38: =SUMIFS($H$2:$H$1003,$E$2:$E$1003,E38,$D$2:$D$1003,D38) -> 18 | H38: 1 | J38: Fulfilment | K38: CISO | L38: 5 | M38: =SUMIF($J:$J,J38,$L:$L) -> 100 | N38: =P38/Q38*100 -> 3.125 | O38: =SUMIF($J:$J,J38,$N:$N) -> 100 | P38: =COUNTIFS(E:E,K38,D:D,J38) -> 1 | Q38: =SUMIF($J:$J,J38,$P:$P) -> 32 | R38: =SUMIFS(F:F,E:E,K38,D:D,J38) -> 1 | S38: =SUMIF($J:$J,P38,$P:$P) -> 0 | AB38: ATC | AC38: =SUMIF($C:$C,AB38,$F:$F) -> 12.000001 | AD38: =VLOOKUP(AB38,$AF:$AG,2,FALSE) -> Corporate | AF38: SEO | AG38: Operations
B39: 4 | C39: CCO | D39: eCommerce | E39: =VLOOKUP($C39,$AF:$AG,2,FALSE) -> Commercial | F39: 8 | G39: =SUMIFS($H$2:$H$1003,$E$2:$E$1003,E39,$D$2:$D$1003,D39) -> 12 | H39: 1 | J39: Mail & Services | K39: Commercial | L39: 25 | N39: 38 | AB39: CCO | AC39: =SUMIF($C:$C,AB39,$F:$F) -> 8.000001 | AD39: =VLOOKUP(AB39,$AF:$AG,2,FALSE) -> Commercial | AF39: BCTT | AG39: Technology
B40: 5 | C40: IDC | D40: eCommerce | E40: =VLOOKUP($C40,$AF:$AG,2,FALSE) -> Commercial | F40: 8 | G40: =SUMIFS($H$2:$H$1003,$E$2:$E$1003,E40,$D$2:$D$1003,D40) -> 12 | H40: 1 | J40: Mail & Services | K40: Operations | L40: 25 | N40: 19 | AB40: IDC | AC40: =SUMIF($C:$C,AB40,$F:$F) -> 8.000001 | AD40: =VLOOKUP(AB40,$AF:$AG,2,FALSE) -> Commercial | AF40: CIO | AG40: Technology
B41: 6 | C41: CFO | D41: eCommerce | E41: =VLOOKUP($C41,$AF:$AG,2,FALSE) -> Corporate | F41: 12 | G41: =SUMIFS($H$2:$H$1003,$E$2:$E$1003,E41,$D$2:$D$1003,D41) -> 18 | H41: 1 | J41: Mail & Services | K41: Corporate | L41: 20 | N41: 19 | AB41: CFO | AC41: =SUMIF($C:$C,AB41,$F:$F) -> 12.000001 | AD41: =VLOOKUP(AB41,$AF:$AG,2,FALSE) -> Corporate | AF41: SI | AG41: Technology
B42: 7 | C42: CIO | D42: eCommerce | E42: =VLOOKUP($C42,$AF:$AG,2,FALSE) -> Technology | F42: 15 | G42: =SUMIFS($H$2:$H$1003,$E$2:$E$1003,E42,$D$2:$D$1003,D42) -> 6 | H42: 1 | J42: Mail & Services | K42: Technology | L42: 20 | N42: 17 | AB42: CIO | AC42: =SUMIF($C:$C,AB42,$F:$F) -> 15.000001 | AD42: =VLOOKUP(AB42,$AF:$AG,2,FALSE) -> Technology | AF42: SI-CRP | AG42: Technology
B43: 8 | C43: PRO | D43: eCommerce | E43: =VLOOKUP($C43,$AF:$AG,2,FALSE) -> Corporate | F43: 7 | G43: =SUMIFS($H$2:$H$1003,$E$2:$E$1003,E43,$D$2:$D$1003,D43) -> 18 | H43: 1 | J43: Mail & Services | K43: Data & AI | L43: 5 | N43: 5 | AB43: PRO | AC43: =SUMIF($C:$C,AB43,$F:$F) -> 7.000001 | AD43: =VLOOKUP(AB43,$AF:$AG,2,FALSE) -> Corporate | AF43: SI-OPS | AG43: Technology
B44: 9 | C44: CHR | D44: eCommerce | E44: =VLOOKUP($C44,$AF:$AG,2,FALSE) -> Corporate | F44: 3 | G44: =SUMIFS($H$2:$H$1003,$E$2:$E$1003,E44,$D$2:$D$1003,D44) -> 18 | H44: 1 | J44: Mail & Services | K44: CISO | L44: 5 | N44: 2 | AB44: CHR | AC44: =SUMIF($C:$C,AB44,$F:$F) -> 3.000001 | AD44: =VLOOKUP(AB44,$AF:$AG,2,FALSE) -> Corporate | AF44: SI-PRD | AG44: Technology
...

Sheet support >>
A1: backup

Sheet ideas-output
A1: Queue | B1: Method | C1: GlobalRank | D1: ID | E1: Name | F1: RequestingArea | G1: RevenueStream | H1: BudgetGroup | I1: MicroPhase | J1: PriorityRA | K1: WSJF_Score | L1: Value | M1: Urgency | N1: Risk | O1: Size | P1: TOP_X | Q1: 122
A2: LATER | B2: SainteLague | C2: 22 | D2: 129487 | E2: [PUDOS] - Lockers Locky - PT​ | F2: CMO | G2: eCommerce | H2: Commercial | I2: In Solution | J2: 0 | K2: 0.09 | L2: 3 | M2: 3 | N2: 3 | O2: 100 | P2: =AND(C2<$Q$1,IF(ISBLANK(C2),0,C2)>0) -> TRUE
A3: LATER | B3: SainteLague | C3: 23 | D3: 125697 | E3: DeMinimis EUA - Solução para retomar os envios de Bens para os EUA para os clientes não contratuais | F3: GP B2B | G3: Mail & Services | H3: Commercial | I3: In Definition | J3: 1 | K3: 3 | L3: 3 | M3: 3 | N3: 3 | O3: 3 | P3: =AND(C3<$Q$1,IF(ISBLANK(C3),0,C3)>0) -> TRUE
A4: LATER | B4: SainteLague | C4: 24 | D4: 130701 | E4: Nuevos desarrollos Normalización de direcciones | F4: COO | G4: eCommerce | H4: Operations | I4: In Solution | J4: 1 | K4: 0.03 | L4: 1 | M4: 1 | N4: 1 | O4: 100 | P4: =AND(C4<$Q$1,IF(ISBLANK(C4),0,C4)>0) -> TRUE
A5: LATER | B5: SainteLague | C5: 25 | D5: 122320 | E5: Implementação de modulo de Planeamento de Transportes em Drivian e Descontinuação do Sigest | F5: SEO | G5: Mail & Services | H5: Operations | I5: High Level Design | J5: 1 | K5: 4.5 | L5: 4 | M5: 2 | N5: 3 | O5: 2 | P5: =AND(C5<$Q$1,IF(ISBLANK(C5),0,C5)>0) -> TRUE
A6: LATER | B6: SainteLague | C6: 26 | D6: 130413 | E6: [Desconexión SGC] - Creación nuevo estado "No realizado" | F6: ATC | G6: eCommerce | H6: Corporate | I6: In Solution | J6: 3 | K6: 0.03 | L6: 1 | M6: 1 | N6: 1 | O6: 100 | P6: =AND(C6<$Q$1,IF(ISBLANK(C6),0,C6)>0) -> TRUE
A7: LATER | B7: SainteLague | C7: 27 | D7: 124871 | E7: Auditoria 2.0 - Criação de Data Lake para implementação de Auditoria Contínua e Auditoria à Distancia - Entrega Modelos Analíticos | F7: ACR | G7: Mail & Services | H7: Corporate | I7: In Definition | J7: 1 | K7: 0.03 | L7: 1 | M7: 1 | N7: 1 | O7: 100 | P7: =AND(C7<$Q$1,IF(ISBLANK(C7),0,C7)>0) -> TRUE
A8: LATER | B8: SainteLague | C8: 28 | D8: 130989 | E8: Desconexión de SGC - Definición del RoadMap | F8: CIO | G8: eCommerce | H8: Technology | I8: Backlog | J8: 1 | K8: 0.03 | L8: 1 | M8: 1 | N8: 1 | O8: 100 | P8: =AND(C8<$Q$1,IF(ISBLANK(C8),0,C8)>0) -> TRUE
A9: LATER | B9: SainteLague | C9: 29 | D9: 132298 | E9: Github Migration - Aplicações Canais Digitais | F9: SI | G9: Mail & Services | H9: Technology | I9: Ready for Approval | J9: 1 | K9: 5 | L9: 4 | M9: 3 | N9: 3 | O9: 2 | P9: =AND(C9<$Q$1,IF(ISBLANK(C9),0,C9)>0) -> TRUE
A10: LATER | B10: SainteLague | C10: 30 | D10: 130577 | E10: [Salesforce Sales] - Multi oportunidad en Cuentas | F10: CCO | G10: eCommerce | H10: Commercial | I10: High Level Design | J10: 3 | K10: 0.03 | L10: 1 | M10: 1 | N10: 1 | O10: 100 | P10: =AND(C10<$Q$1,IF(ISBLANK(C10),0,C10)>0) -> TRUE
A11: LATER | B11: SainteLague | C11: 31 | D11: 126574 | E11: DLP (Data Loss Prevention) - Wave 1 | F11: CISO | G11: Mail & Services | H11: CISO | I11: Backlog | J11: 2 | K11: 0.03 | L11: 1 | M11: 1 | N11: 1 | O11: 100 | P11: =AND(C11<$Q$1,IF(ISBLANK(C11),0,C11)>0) -> TRUE
A12: LATER | B12: SainteLague | C12: 32 | D12: 130894 | E12: Expansión de lectura en contenedores (Propios y de clientes) | F12: COO | G12: eCommerce | H12: Operations | I12: In Definition | J12: 2 | K12: 0.03 | L12: 1 | M12: 1 | N12: 1 | O12: 100 | P12: =AND(C12<$Q$1,IF(ISBLANK(C12),0,C12)>0) -> TRUE
A13: LATER | B13: SainteLague | C13: 33 | D13: 60579 | E13: Nexus | P&S | Implementação da oferta ibérica | F13: GP ECL | G13: Mail & Services | H13: Commercial | I13: High Level Design | J13: 1 | K13: 0.03 | L13: 1 | M13: 1 | N13: 1 | O13: 100 | P13: =AND(C13<$Q$1,IF(ISBLANK(C13),0,C13)>0) -> TRUE
... A881: NEXT | B881: WSJF | C881: 21 | D881: 130343 | E881: [Nuevo Producto]-[Minerva]-Producto 48h a Islas Canarias | F881: CMO | G881: eCommerce | H881: Commercial | I881: Ready for Development | J881: 4 | K881: 0.03 | L881: 1 | M881: 1 | N881: 1 | O881: 100 | P881: =AND(C881<$Q$1,IF(ISBLANK(C881),0,C881)>0) -> TRUE
A882: PRODUCTION | B882: sainte-lague | D882: 132113 | E882: Reduce SalesForce Storage before contract renewal | F882: CIO | G882: eCommerce | H882: Technology | I882: In Production | J882: 999 | L882: 4 | M882: 1 | N882: 3 | O882: 1 | P882: =AND(C882<$Q$1,IF(ISBLANK(C882),0,C882)>0) -> FALSE
A883: PRODUCTION | B883: sainte-lague | D883: 131163 | E883: [Web Pública] - Localizador de puntos - Actualizar texto de enlace | F883: CMO | G883: eCommerce | H883: Commercial | I883: In Production | J883: 999 | L883: 1 | M883: 1 | N883: 1 | O883: 100 | P883: =AND(C883<$Q$1,IF(ISBLANK(C883),0,C883)>0) -> FALSE
A884: PRODUCTION | B884: sainte-lague | D884: 131144 | E884: [Salesforce] Adición del campo Dirección en objeto user | F884: CIO | G884: eCommerce | H884: Technology | I884: In Production | J884: 999 | L884: 2 | M884: 1 | N884: 1 | O884: 1 | P884: =AND(C884<$Q$1,IF(ISBLANK(C884),0,C884)>0) -> FALSE
A885: PRODUCTION | B885: sainte-lague | D885: 131138 | E885: [WebHook] - Shein - LastMile - Modificación de destino HD a Pudo y su comunicación al cliente. | F885: COM | G885: eCommerce | H885: Corporate | I885: In Production | J885: 999 | L885: 1 | M885: 1 | N885: 1 | O885: 100 | P885: =AND(C885<$Q$1,IF(ISBLANK(C885),0,C885)>0) -> FALSE
A886: PRODUCTION | B886: sainte-lague | D886: 131009 | E886: Nuevo universo de envios Senda fin de semana | F886: COO | G886: eCommerce | H886: Operations | I886: In Production | J886: 42 | L886: 1 | M886: 1 | N886: 1 | O886: 100 | P886: =AND(C886<$Q$1,IF(ISBLANK(C886),0,C886)>0) -> FALSE
A887: PRODUCTION | B887: sainte-lague | D887: 130965 | E887: [SGC] - Omitir mensajes de Franquicias | F887: CCO | G887: eCommerce | H887: Commercial | I887: In Production | J887: 42 | L887: 1 | M887: 1 | N887: 1 | O887: 100 | P887: =AND(C887<$Q$1,IF(ISBLANK(C887),0,C887)>0) -> FALSE
A888: PRODUCTION | B888: sainte-lague | D888: 130928 | E888: Kafka - Upgrade MSK en AWS | F888: CIO | G888: eCommerce | H888: Technology | I888: In Production | J888: 7 | L888: 3 | M888: 3 | N888: 1 | O888: 100 | P888: =AND(C888<$Q$1,IF(ISBLANK(C888),0,C888)>0) -> FALSE
A889: PRODUCTION | B889: sainte-lague | D889: 130906 | E889: Tasa Gasoil Portugal | F889: COO | G889: eCommerce | H889: Operations | I889: In Production | J889: 5 | L889: 1 | M889: 1 | N889: 1 | O889: 100 | P889: =AND(C889<$Q$1,IF(ISBLANK(C889),0,C889)>0) -> FALSE
A890: PRODUCTION | B890: sainte-lague | D890: 130776 | E890: Actualizar lista de esquemas de documentación que permiten asociado | F890: COO | G890: eCommerce | H890: Operations | I890: In Production | J890: 0 | L890: 1 | M890: 1 | N890: 1 | O890: 100 | P890: =AND(C890<$Q$1,IF(ISBLANK(C890),0,C890)>0) -> FALSE
A891: PRODUCTION | B891: sainte-lague | D891: 130725 | E891: [DHL Parcel] Envíos PT - PT | F891: IDC | G891: eCommerce | H891: Commercial | I891: In Production | J891: 1 | L891: 1 | M891: 1 | N891: 1 | O891: 100 | P891: =AND(C891<$Q$1,IF(ISBLANK(C891),0,C891)>0) -> FALSE
A892: PRODUCTION | B892: sainte-lague | D892: 130712 | E892: [Notificaciones] - [Mail] - [Modificación] - Actualizar template notificaciones Custom para modificar imágenes | F892: CMO | G892: eCommerce | H892: Commercial | I892: In Production | J892: 0 | L892: 1 | M892: 1 | N892: 1 | O892: 100 | P892: =AND(C892<$Q$1,IF(ISBLANK(C892),0,C892)>0) -> FALSE
A893: PRODUCTION | B893: sainte-lague | D893: 130640 | E893: Portal Proveedores Linehaul - Incluir concepto peaje en la facturación | F893: COO | G893: eCommerce | H893: Operations | I893: In Production | J893: 0 | L893: 1 | M893: 1 | N893: 1 | O893: 100 | P893: =AND(C893<$Q$1,IF(ISBLANK(C893),0,C893)>0) -> FALSE
... A987: PRODUCTION | B987: sainte-lague | D987: 31832 | E987: Solução de Gestão de Despesas de colaborador | F987: CF | G987: Mail & Services | H987: Corporate | I987: In Production | J987: 999 | L987: 1 | M987: 1 | N987: 1 | O987: 100 | P987: =AND(C987<$Q$1,IF(ISBLANK(C987),0,C987)>0) -> FALSE
P988: =AND(C988<$Q$1,IF(ISBLANK(C988),0,C988)>0) -> FALSE
P989: =AND(C989<$Q$1,IF(ISBLANK(C989),0,C989)>0) -> FALSE
P990: =AND(C990<$Q$1,IF(ISBLANK(C990),0,C990)>0) -> FALSE
P991: =AND(C991<$Q$1,IF(ISBLANK(C991),0,C991)>0) -> FALSE
P992: =AND(C992<$Q$1,IF(ISBLANK(C992),0,C992)>0) -> FALSE
P993: =AND(C993<$Q$1,IF(ISBLANK(C993),0,C993)>0) -> FALSE
P994: =AND(C994<$Q$1,IF(ISBLANK(C994),0,C994)>0) -> FALSE
P995: =AND(C995<$Q$1,IF(ISBLANK(C995),0,C995)>0) -> FALSE
P996: =AND(C996<$Q$1,IF(ISBLANK(C996),0,C996)>0) -> FALSE
P997: =AND(C997<$Q$1,IF(ISBLANK(C997),0,C997)>0) -> FALSE
P998: =AND(C998<$Q$1,IF(ISBLANK(C998),0,C998)>0) -> FALSE
P999: =AND(C999<$Q$1,IF(ISBLANK(C999),0,C999)>0) -> FALSE

Sheet pivot
A3: Count of ID | B3: Column Labels
A4: Row Labels | B4: TRUE | C4: FALSE | D4: Grand Total
A5: LATER | B5: 100 | C5: 759 | D5: 859
A6: eCommerce | B6: 50 | C6: 398 | D6: 448
A7: Commercial | B7: 13 | C7: 216 | D7: 229
A8: Corporate | B8: 12 | C8: 94 | D8: 106
A9: Operations | B9: 13 | C9: 29 | D9: 42
A10: Technology | B10: 12 | C10: 59 | D10: 71
A11: Mail & Services | B11: 50 | C11: 361 | D11: 411
A12: CISO | B12: 6 | C12: 2 | D12: 8
A13: Commercial | B13: 11 | C13: 178 | D13: 189
A14: Corporate | B14: 11 | C14: 64 | D14: 75
A15: Operations | B15: 11 | C15: 13 | D15: 24
A16: Technology | B16: 11 | C16: 104 | D16: 115
A17: NEXT | B17: 1 | D17: 1
A18: eCommerce | B18: 1 | D18: 1
A19: Commercial | B19: 1 | D19: 1
A20: NOW | B20: 20 | D20: 20
A21: eCommerce | B21: 15 | D21: 15
A22: Commercial | B22: 5 | D22: 5
A23: Corporate | B23: 3 | D23: 3
A24: Operations | B24: 6 | D24: 6
A25: Technology | B25: 1 | D25: 1
A26: Mail & Services | B26: 5 | D26: 5
A27: CISO | B27: 1 | D27: 1
A28: Corporate | B28: 2 | D28: 2
A29: Technology | B29: 2 | D29: 2
A30: PRODUCTION | C30: 106 | D30: 106
A31: (blank)
A32: Grand Total | B32: 121 | C32: 865 | D32: 986

Sheet backup >> 

Sheet weights (base2026.02)
B1: EXPORT CSV | C1: WEIGHTS_RA | I1: Peso BG por RS | N1: EXPORT CSV | O1: WEIGHTS_RS | Y1: REF DATA | AB1: REF DATA
B2: RequestingArea | C2: RevenueStream | D2: BudgetGroup | E2: Weight | F2: Weight-RS+BG | G2: Weight-Base | I2: RevenueStream | J2: BudgetGroup | K2: Weight | L2: Check | N2: RevenueStream | O2: Weight | P2: Check | R2: {=_xlfn.UNIQUE(D2:D1000)} -> BudgetGroup | S2: Check | U2: {=_xlfn.UNIQUE(B2:B1000)} -> RequestingArea | V2: Check | W2: hasBG? | Y2: RequestingArea | Z2: BudgetGroup | AB2: MicroPhase bmap | AC2: MicroPhase Macro | AD2: MicroPhase Demand
B3: CISO | C3: Business Solutions | D3: =VLOOKUP($B3,$Y:$Z,2,FALSE) -> CISO | E3: =G3*SUMIFS($K:$K,$I:$I,C3,$J:$J,D3)/F3 -> 5 | F3: =SUMIFS($G$2:$G$1000,$D$2:$D$1000,D3,$C$2:$C$1000,C3) -> 5 | G3: 5 | I3: eCommerce | J3: CISO | K3: 5 | L3: =SUMIF($I:$I,I3,$K:$K) -> 100 | N3: eCommerce | O3: 26 | P3: =SUM(O3:O18) -> 100 | R3: CISO | S3: =SUMIF($D:$D,R3,$E:$E) -> 30 | U3: CISO | V3: =SUMIF($B:$B,U3,$E:$E) -> 30 | W3: =VLOOKUP(U3,$Y:$Z,2,FALSE) -> CISO | Y3: CISO | Z3: CISO | AB3: IDEA > Backlog | AC3: {=_xlfn.TEXTSPLIT(AB3,">",)} -> IDEA | AD3: Backlog
B4: CSI | C4: Business Solutions | D4: =VLOOKUP($B4,$Y:$Z,2,FALSE) -> Commercial | E4: =G4*SUMIFS($K:$K,$I:$I,C4,$J:$J,D4)/F4 -> 4 | F4: =SUMIFS($G$2:$G$1000,$D$2:$D$1000,D4,$C$2:$C$1000,C4) -> 100 | G4: 10 | I4: eCommerce | J4: Commercial | K4: 25 | L4: =SUMIF($I:$I,I4,$K:$K) -> 100 | N4: Mail | O4: 22 | R4: Commercial | S4: =SUMIF($D:$D,R4,$E:$E) -> 185 | U4: CSI | V4: =SUMIF($B:$B,U4,$E:$E) -> 16.652406 | W4: =VLOOKUP(U4,$Y:$Z,2,FALSE) -> Commercial | Y4: CCO | Z4: Commercial | AB4: IDEA > Pitch | AC4: {=_xlfn.TEXTSPLIT(AB4,">",)} -> IDEA | AD4: Pitch
