Workbook

Sheet DEMAND WEIGHTS
A1: DEMAND 2025
A2: PORTUGAL | W2: ESPAÑA
A3: PRODUCTS | B3: 0.38 | E3: OPERATIONS | F3: 0.19 | I3: CORPORATE | J3: 0.19 | M3: TECHNOLOGY | N3: 0.19 | Q3: DAT | R3: 0.05 | W3: operations | X3: commercial | Y3: corporate | Z3: commercial | AA3: commercial | AB3: corporate | AC3: technology | AD3: corporate | AE3: corporate | AF3: corporate
A4: GP ECL | B4: 0.16 | E4: EDO | F4: 0.35 | I4: ACR | J4: 0.066666667 | M4: SI | N4: 0.3 | W4: COO | X4: CMO | Y4: ATC | Z4: CCO | AA4: IDC | AB4: CFO | AC4: CIO | AD4: PRO | AE4: CHR | AF4: COM
A5: GP B2B | B5: 0.16 | E5: SEO | F5: 0.35 | I5: CF | J5: 0.066666667 | M5: CISO | N5: 0.2 | W5: 0.2 | X5: 0.12 | Y5: 0.12 | Z5: 0.08 | AA5: 0.08 | AB5: 0.12 | AC5: 0.15 | AD5: 0.07 | AE5: 0.03 | AF5: 0.03
A6: DNI | B6: 0.16 | E6: EM | F6: 0.3 | I6: RS | J6: 0.066666667 | M6: BCTT | N6: 0.2
A7: GS | B7: 0.12 | I7: AVC | J7: 0.066666667 | M7: SI-PRD | N7: 0.1
A8: CSI | B8: 0.1 | I8: GRH | J8: 0.066666667 | M8: SI-OPS | N8: 0.1
A9: GP B2C | B9: 0.09 | I9: GT | J9: 0.066666667 | M9: SI-CRP | N9: 0.1
A10: CTTE | B10: 0.09 | I10: CL | J10: 0.066666667
A11: GPG | B11: 0.09 | I11: ED | J11: 0.066666667
A12: ECM | B12: 0.03 | I12: CMP | J12: 0.066666667
I13: ST | J13: 0.066666667
I14: GFC | J14: 0.066666667
I15: TF | J15: 0.066666667
I16: DPO | J16: 0.066666667
I17: SSJ | J17: 0.066666667
I18: FL | J18: 0.066666667
A20: DEMAND 2026
A21: eCOMMERCE | B21: =VLOOKUP(A21,weights!$N:$O,2,FALSE) -> 26 | C21: =(B23+F23+J23+N23+R23+V23)=100 -> TRUE
A22: check | B22: =B23=SUM(B24:B32) -> TRUE | E22: check | F22: =F23=SUM(F24:F32) -> TRUE | I22: check | J22: =J23=SUM(J24:J32) -> TRUE | M22: check | N22: =N23=SUM(N24:N32) -> TRUE | Q22: check | R22: =R23=SUM(R24:R32) -> TRUE | U22: check | V22: =V23=SUM(V24:V32) -> TRUE
A23: Commercial | B23: 25 | C23: =B23*($B$21/100) -> 6.5 | E23: Operations | F23: 25 | G23: =F23*($B$21/100) -> 6.5 | I23: Corporate | J23: 20 | K23: =J23*($B$21/100) -> 5.2 | M23: Technology | N23: 20 | O23: =N23*($B$21/100) -> 5.2 | Q23: Data & AI | R23: 5 | S23: =R23*($B$21/100) -> 1.3 | U23: CISO | V23: 5 | W23: =V23*($B$21/100) -> 1.3 | X23: 25
A24: CMO | B24: 4 | C24: =B24*($B$21/100) -> 1.04 | E24: COO | F24: 8 | G24: =F24*($B$21/100) -> 2.08 | I24: ATC | J24: 8 | K24: =J24*($B$21/100) -> 2.08 | M24: CIO | N24: 20 | O24: =N24*($B$21/100) -> 5.2 | Q24: DAI | R24: 5 | S24: =R24*($B$21/100) -> 1.3 | U24: CISO | V24: 5 | W24: =V24*($B$21/100) -> 1.3 | X24: 25
A25: CCO | B25: 4 | C25: =B25*($B$21/100) -> 1.04 | E25: EDO | F25: 8 | G25: =F25*($B$21/100) -> 2.08 | I25: CFO | J25: 8 | K25: =J25*($B$21/100) -> 2.08 | O25: =N25*($B$21/100) -> 0 | S25: =R25*($B$21/100) -> 0 | W25: =V25*($B$21/100) -> 0 | X25: 20
A26: IDC | B26: 4 | C26: =B26*($B$21/100) -> 1.04 | E26: SEO | F26: 8 | G26: =F26*($B$21/100) -> 2.08 | I26: PRO | J26: 2 | K26: =J26*($B$21/100) -> 0.52 | O26: =N26*($B$21/100) -> 0 | S26: =R26*($B$21/100) -> 0 | W26: =V26*($B$21/100) -> 0 | X26: 20
A27: GP ECL | B27: 5 | C27: =B27*($B$21/100) -> 1.3 | E27: EM | F27: 1 | G27: =F27*($B$21/100) -> 0.26 | I27: CHR | J27: 1 | K27: =J27*($B$21/100) -> 0.26 | O27: =N27*($B$21/100) -> 0 | S27: =R27*($B$21/100) -> 0 | W27: =V27*($B$21/100) -> 0 | X27: 5
A28: DNI | B28: 2 | C28: =B28*($B$21/100) -> 0.52 | G28: =F28*($B$21/100) -> 0 | I28: COM | J28: 1 | K28: =J28*($B$21/100) -> 0.26 | O28: =N28*($B$21/100) -> 0 | S28: =R28*($B$21/100) -> 0 | W28: =V28*($B$21/100) -> 0 | X28: 5
A29: GS | B29: 2 | C29: =B29*($B$21/100) -> 0.52 | G29: =F29*($B$21/100) -> 0 | K29: =J29*($B$21/100) -> 0 | O29: =N29*($B$21/100) -> 0 | S29: =R29*($B$21/100) -> 0 | W29: =V29*($B$21/100) -> 0
A30: CSI | B30: 2 | C30: =B30*($B$21/100) -> 0.52 | G30: =F30*($B$21/100) -> 0 | K30: =J30*($B$21/100) -> 0 | O30: =N30*($B$21/100) -> 0 | S30: =R30*($B$21/100) -> 0 | W30: =V30*($B$21/100) -> 0
A31: GP B2C | B31: 2 | C31: =B31*($B$21/100) -> 0.52 | G31: =F31*($B$21/100) -> 0 | K31: =J31*($B$21/100) -> 0 | O31: =N31*($B$21/100) -> 0 | S31: =R31*($B$21/100) -> 0 | W31: =V31*($B$21/100) -> 0
A34: MAIL | B34: =VLOOKUP(A34,weights!$N:$O,2,FALSE) -> 22 | C34: =(B36+F36+J36+N36+R36+V36)=100 -> TRUE
A35: check | B35: =B36=SUM(B37:B52) -> TRUE | E35: check | F35: =F36=SUM(F37:F52) -> TRUE | I35: check | J35: =J36=SUM(J37:J52) -> TRUE | M35: check | N35: =N36=SUM(N37:N52) -> TRUE | Q35: check | R35: =R36=SUM(R37:R52) -> TRUE | U35: check | V35: =V36=SUM(V37:V52) -> TRUE
A36: Commercial | B36: 25 | C36: =B36*($B$34/100) -> 5.5 | E36: Operations | F36: 25 | G36: =F36*($B$34/100) -> 5.5 | I36: Corporate | J36: 20 | K36: =J36*($B$34/100) -> 4.4 | M36: Technology | N36: 20 | O36: =N36*($B$34/100) -> 4.4 | Q36: Data & AI | R36: 5 | S36: =R36*($B$34/100) -> 1.1 | U36: CISO | V36: 5 | W36: =V36*($B$34/100) -> 1.1 | X36: 25
A37: GP B2B | B37: 5 | C37: =B37*($B$34/100) -> 1.1 | E37: EDO | F37: 10 | G37: =F37*($B$34/100) -> 2.2 | I37: ACR | J37: 2 | K37: =J37*($B$34/100) -> 0.44 | M37: SI | N37: 10 | O37: =N37*($B$34/100) -> 2.2 | Q37: DAI | R37: 5 | S37: =R37*($B$34/100) -> 1.1 | U37: CISO | V37: 5 | W37: =V37*($B$34/100) -> 1.1 | X37: 25
A38: DNI | B38: 5 | C38: =B38*($B$34/100) -> 1.1 | E38: SEO | F38: 10 | G38: =F38*($B$34/100) -> 2.2 | I38: CF | J38: 2 | K38: =J38*($B$34/100) -> 0.44 | M38: BCTT | N38: 10 | O38: =N38*($B$34/100) -> 2.2 | S38: =R38*($B$34/100) -> 0 | W38: =V38*($B$34/100) -> 0
A39: GS | B39: 5 | C39: =B39*($B$34/100) -> 1.1 | E39: EM | F39: 5 | G39: =F39*($B$34/100) -> 1.1 | I39: RS | J39: 1 | K39: =J39*($B$34/100) -> 0.22 | O39: =N39*($B$34/100) -> 0 | S39: =R39*($B$34/100) -> 0 | W39: =V39*($B$34/100) -> 0
A40: CSI | B40: 5 | C40: =B40*($B$34/100) -> 1.1 | G40: =F40*($B$34/100) -> 0 | I40: AVC | J40: 2 | K40: =J40*($B$34/100) -> 0.44 | O40: =N40*($B$34/100) -> 0 | S40: =R40*($B$34/100) -> 0 | W40: =V40*($B$34/100) -> 0
A41: GP B2C | B41: 5 | C41: =B41*($B$34/100) -> 1.1 | G41: =F41*($B$34/100) -> 0 | I41: GRH | J41: 2 | K41: =J41*($B$34/100) -> 0.44 | O41: =N41*($B$34/100) -> 0 | S41: =R41*($B$34/100) -> 0 | W41: =V41*($B$34/100) -> 0
C42: =B42*($B$34/100) -> 0 | G42: =F42*($B$34/100) -> 0 | I42: GT | J42: 2 | K42: =J42*($B$34/100) -> 0.44 | O42: =N42*($B$34/100) -> 0 | S42: =R42*($B$34/100) -> 0 | W42: =V42*($B$34/100) -> 0
C43: =B43*($B$34/100) -> 0 | G43: =F43*($B$34/100) -> 0 | I43: CL | J43: 1 | K43: =J43*($B$34/100) -> 0.22 | O43: =N43*($B$34/100) -> 0 | S43: =R43*($B$34/100) -> 0 | W43: =V43*($B$34/100) -> 0
...

Sheet weights
B1: EXPORT CSV | C1: WEIGHTS_RA | I1: Peso BG por RS | N1: EXPORT CSV | O1: WEIGHTS_RS | Y1: REF DATA | AB1: REF DATA
B2: RequestingArea | C2: RevenueStream | D2: BudgetGroup | E2: Weight | F2: Weight-RS+BG | G2: Weight-Base | I2: RevenueStream | J2: BudgetGroup | K2: Weight | L2: Check | N2: RevenueStream | O2: Weight | P2: Check | R2: {=_xlfn.UNIQUE(D2:D1000)} -> BudgetGroup | S2: Check | U2: {=_xlfn.UNIQUE(B2:B1000)} -> RequestingArea | V2: Check | W2: hasBG? | Y2: RequestingArea | Z2: BudgetGroup | AB2: MicroPhase bmap | AC2: MicroPhase Macro | AD2: MicroPhase Demand
B3: CISO | C3: Business Solutions | D3: =VLOOKUP($B3,$Y:$Z,2,FALSE) -> CISO | E3: =G3*SUMIFS($K:$K,$I:$I,C3,$J:$J,D3)/F3 -> 5 | F3: =SUMIFS($G$2:$G$1000,$D$2:$D$1000,D3,$C$2:$C$1000,C3) -> 20 | G3: 20 | I3: eCommerce | J3: CISO | K3: 5 | L3: =SUMIF($I:$I,I3,$K:$K) -> 100 | N3: eCommerce | O3: 26 | P3: =SUM(O3:O18) -> 100 | R3: CISO | S3: =SUMIF($D:$D,R3,$E:$E) -> 30 | U3: CISO | V3: =SUMIF($B:$B,U3,$E:$E) -> 30 | W3: =VLOOKUP(U3,$Y:$Z,2,FALSE) -> CISO | Y3: CISO | Z3: CISO | AB3: IDEA > Backlog | AC3: {=_xlfn.TEXTSPLIT(AB3,">",)} -> IDEA | AD3: Backlog
B4: CSI | C4: Business Solutions | D4: =VLOOKUP($B4,$Y:$Z,2,FALSE) -> Commercial | E4: =G4*SUMIFS($K:$K,$I:$I,C4,$J:$J,D4)/F4 -> 4 | F4: =SUMIFS($G$2:$G$1000,$D$2:$D$1000,D4,$C$2:$C$1000,C4) -> 100 | G4: 10 | I4: eCommerce | J4: Commercial | K4: 25 | L4: =SUMIF($I:$I,I4,$K:$K) -> 100 | N4: Mail | O4: 22 | R4: Commercial | S4: =SUMIF($D:$D,R4,$E:$E) -> 185 | U4: CSI | V4: =SUMIF($B:$B,U4,$E:$E) -> 16.652406 | W4: =VLOOKUP(U4,$Y:$Z,2,FALSE) -> Commercial | Y4: CCO | Z4: Commercial | AB4: IDEA > Pitch | AC4: {=_xlfn.TEXTSPLIT(AB4,">",)} -> IDEA | AD4: Pitch
B5: CTTE | C5: Business Solutions | D5: =VLOOKUP($B5,$Y:$Z,2,FALSE) -> Commercial | E5: =G5*SUMIFS($K:$K,$I:$I,C5,$J:$J,D5)/F5 -> 4 | F5: =SUMIFS($G$2:$G$1000,$D$2:$D$1000,D5,$C$2:$C$1000,C5) -> 100 | G5: 10 | I5: eCommerce | J5: Corporate | K5: 20 | L5: =SUMIF($I:$I,I5,$K:$K) -> 100 | N5: Business Solutions | O5: 16 | R5: Corporate | S5: =SUMIF($D:$D,R5,$E:$E) -> 135 | U5: CTTE | V5: =SUMIF($B:$B,U5,$E:$E) -> 16.652406 | W5: =VLOOKUP(U5,$Y:$Z,2,FALSE) -> Commercial | Y5: CMO | Z5: Commercial | AB5: IDEA > In Definition | AC5: {=_xlfn.TEXTSPLIT(AB5,">",)} -> IDEA | AD5: In Definition
B6: DNI | C6: Business Solutions | D6: =VLOOKUP($B6,$Y:$Z,2,FALSE) -> Commercial | E6: =G6*SUMIFS($K:$K,$I:$I,C6,$J:$J,D6)/F6 -> 4 | F6: =SUMIFS($G$2:$G$1000,$D$2:$D$1000,D6,$C$2:$C$1000,C6) -> 100 | G6: 10 | I6: eCommerce | J6: Operations | K6: 25 | L6: =SUMIF($I:$I,I6,$K:$K) -> 100 | N6: Retail & Financial Services | O6: 14 | R6: Operations | S6: =SUMIF($D:$D,R6,$E:$E) -> 105 | U6: DNI | V6: =SUMIF($B:$B,U6,$E:$E) -> 16.652406 | W6: =VLOOKUP(U6,$Y:$Z,2,FALSE) -> Commercial | Y6: CSI | Z6: Commercial | AB6: SOLUTION > In Approval | AC6: {=_xlfn.TEXTSPLIT(AB6,">",)} -> SOLUTION | AD6: In Approval
B7: ECM | C7: Business Solutions | D7: =VLOOKUP($B7,$Y:$Z,2,FALSE) -> Commercial | E7: =G7*SUMIFS($K:$K,$I:$I,C7,$J:$J,D7)/F7 -> 4 | F7: =SUMIFS($G$2:$G$1000,$D$2:$D$1000,D7,$C$2:$C$1000,C7) -> 100 | G7: 10 | I7: eCommerce | J7: Technology | K7: 15 | L7: =SUMIF($I:$I,I7,$K:$K) -> 100 | N7: Payments | O7: 12 | R7: Technology | S7: =SUMIF($D:$D,R7,$E:$E) -> 110 | U7: ECM | V7: =SUMIF($B:$B,U7,$E:$E) -> 16.652406 | W7: =VLOOKUP(U7,$Y:$Z,2,FALSE) -> Commercial | Y7: CTTE | Z7: Commercial | AB7: SOLUTION > Ready for Approval | AC7: {=_xlfn.TEXTSPLIT(AB7,">",)} -> SOLUTION | AD7: Ready for Approval
B8: GP B2B | C8: Business Solutions | D8: =VLOOKUP($B8,$Y:$Z,2,FALSE) -> Commercial | E8: =G8*SUMIFS($K:$K,$I:$I,C8,$J:$J,D8)/F8 -> 8 | F8: =SUMIFS($G$2:$G$1000,$D$2:$D$1000,D8,$C$2:$C$1000,C8) -> 100 | G8: 20 | I8: eCommerce | J8: Data & AI | K8: 10 | L8: =SUMIF($I:$I,I8,$K:$K) -> 100 | N8: Fulfilment | O8: 10 | R8: Data & AI | S8: =SUMIF($D:$D,R8,$E:$E) -> 35 | U8: GP B2B | V8: =SUMIF($B:$B,U8,$E:$E) -> 23.379679 | W8: =VLOOKUP(U8,$Y:$Z,2,FALSE) -> Commercial | Y8: DNI | Z8: Commercial | AB8: IDEA > Ready for Solution | AC8: {=_xlfn.TEXTSPLIT(AB8,">",)} -> IDEA | AD8: Ready for Solution
B9: GP B2C | C9: Business Solutions | D9: =VLOOKUP($B9,$Y:$Z,2,FALSE) -> Commercial | E9: =G9*SUMIFS($K:$K,$I:$I,C9,$J:$J,D9)/F9 -> 4 | F9: =SUMIFS($G$2:$G$1000,$D$2:$D$1000,D9,$C$2:$C$1000,C9) -> 100 | G9: 10 | I9: Mail | J9: CISO | K9: 5 | L9: =SUMIF($I:$I,I9,$K:$K) -> 100 | N9: Banco CTT | O9: 0 | R9: 0 | S9: =SUMIF($D:$D,R9,$E:$E) -> 0 | U9: GP B2C | V9: =SUMIF($B:$B,U9,$E:$E) -> 19.379679 | W9: =VLOOKUP(U9,$Y:$Z,2,FALSE) -> Commercial | Y9: ECM | Z9: Commercial | AB9: SOLUTION > High Level Design | AC9: {=_xlfn.TEXTSPLIT(AB9,">",)} -> SOLUTION | AD9: High Level Design
B10: GP ECL | C10: Business Solutions | D10: =VLOOKUP($B10,$Y:$Z,2,FALSE) -> Commercial | E10: =G10*SUMIFS($K:$K,$I:$I,C10,$J:$J,D10)/F10 -> 4 | F10: =SUMIFS($G$2:$G$1000,$D$2:$D$1000,D10,$C$2:$C$1000,C10) -> 100 | G10: 10 | I10: Mail | J10: Commercial | K10: 30 | L10: =SUMIF($I:$I,I10,$K:$K) -> 100 | S10: =SUMIF($D:$D,R10,$E:$E) -> 0 | U10: GP ECL | V10: =SUMIF($B:$B,U10,$E:$E) -> 21.122995 | W10: =VLOOKUP(U10,$Y:$Z,2,FALSE) -> Commercial | Y10: GP B2B | Z10: Commercial | AB10: SOLUTION > Ready for Development | AC10: {=_xlfn.TEXTSPLIT(AB10,">",)} -> SOLUTION | AD10: Ready for Development
B11: GPG | C11: Business Solutions | D11: =VLOOKUP($B11,$Y:$Z,2,FALSE) -> Commercial | E11: =G11*SUMIFS($K:$K,$I:$I,C11,$J:$J,D11)/F11 -> 4 | F11: =SUMIFS($G$2:$G$1000,$D$2:$D$1000,D11,$C$2:$C$1000,C11) -> 100 | G11: 10 | I11: Mail | J11: Corporate | K11: 20 | L11: =SUMIF($I:$I,I11,$K:$K) -> 100 | S11: =SUMIF($D:$D,R11,$E:$E) -> 0 | U11: GPG | V11: =SUMIF($B:$B,U11,$E:$E) -> 19.379679 | W11: =VLOOKUP(U11,$Y:$Z,2,FALSE) -> Commercial | Y11: GP B2C | Z11: Commercial | AB11: SOLUTION > In Definition | AC11: {=_xlfn.TEXTSPLIT(AB11,">",)} -> SOLUTION | AD11: In Definition
B12: GS | C12: Business Solutions | D12: =VLOOKUP($B12,$Y:$Z,2,FALSE) -> Commercial | E12: =G12*SUMIFS($K:$K,$I:$I,C12,$J:$J,D12)/F12 -> 4 | F12: =SUMIFS($G$2:$G$1000,$D$2:$D$1000,D12,$C$2:$C$1000,C12) -> 100 | G12: 10 | I12: Mail | J12: Operations | K12: 20 | L12: =SUMIF($I:$I,I12,$K:$K) -> 100 | S12: =SUMIF($D:$D,R12,$E:$E) -> 0 | U12: GS | V12: =SUMIF($B:$B,U12,$E:$E) -> 26.304813 | W12: =VLOOKUP(U12,$Y:$Z,2,FALSE) -> Commercial | Y12: GP ECL | Z12: Commercial
B13: ACR | C13: Business Solutions | D13: =VLOOKUP($B13,$Y:$Z,2,FALSE) -> Corporate | E13: =G13*SUMIFS($K:$K,$I:$I,C13,$J:$J,D13)/F13 -> 1.4285714 | F13: =SUMIFS($G$2:$G$1000,$D$2:$D$1000,D13,$C$2:$C$1000,C13) -> 140 | G13: 10 | I13: Mail | J13: Technology | K13: 20 | L13: =SUMIF($I:$I,I13,$K:$K) -> 100 | S13: =SUMIF($D:$D,R13,$E:$E) -> 0 | U13: ACR | V13: =SUMIF($B:$B,U13,$E:$E) -> 9.1233766 | W13: =VLOOKUP(U13,$Y:$Z,2,FALSE) -> Corporate | Y13: GPG | Z13: Commercial
B14: AVC | C14: Business Solutions | D14: =VLOOKUP($B14,$Y:$Z,2,FALSE) -> Corporate | E14: =G14*SUMIFS($K:$K,$I:$I,C14,$J:$J,D14)/F14 -> 1.4285714 | F14: =SUMIFS($G$2:$G$1000,$D$2:$D$1000,D14,$C$2:$C$1000,C14) -> 140 | G14: 10 | I14: Mail | J14: Data & AI | K14: 5 | L14: =SUMIF($I:$I,I14,$K:$K) -> 100 | S14: =SUMIF($D:$D,R14,$E:$E) -> 0 | U14: AVC | V14: =SUMIF($B:$B,U14,$E:$E) -> 9.1233766 | W14: =VLOOKUP(U14,$Y:$Z,2,FALSE) -> Corporate | Y14: GS | Z14: Commercial
B15: CF | C15: Business Solutions | D15: =VLOOKUP($B15,$Y:$Z,2,FALSE) -> Corporate | E15: =G15*SUMIFS($K:$K,$I:$I,C15,$J:$J,D15)/F15 -> 2.8571429 | F15: =SUMIFS($G$2:$G$1000,$D$2:$D$1000,D15,$C$2:$C$1000,C15) -> 140 | G15: 20 | I15: Business Solutions | J15: CISO | K15: 5 | L15: =SUMIF($I:$I,I15,$K:$K) -> 100 | U15: CF | V15: =SUMIF($B:$B,U15,$E:$E) -> 18.246753 | W15: =VLOOKUP(U15,$Y:$Z,2,FALSE) -> Corporate | Y15: IDC | Z15: Commercial
B16: CL | C16: Business Solutions | D16: =VLOOKUP($B16,$Y:$Z,2,FALSE) -> Corporate | E16: =G16*SUMIFS($K:$K,$I:$I,C16,$J:$J,D16)/F16 -> 1.4285714 | F16: =SUMIFS($G$2:$G$1000,$D$2:$D$1000,D16,$C$2:$C$1000,C16) -> 140 | G16: 10 | I16: Business Solutions | J16: Commercial | K16: 40 | L16: =SUMIF($I:$I,I16,$K:$K) -> 100 | U16: CL | V16: =SUMIF($B:$B,U16,$E:$E) -> 9.1233766 | W16: =VLOOKUP(U16,$Y:$Z,2,FALSE) -> Corporate | Y16: ACR | Z16: Corporate
B17: CMP | C17: Business Solutions | D17: =VLOOKUP($B17,$Y:$Z,2,FALSE) -> Corporate | E17: =G17*SUMIFS($K:$K,$I:$I,C17,$J:$J,D17)/F17 -> 1.4285714 | F17: =SUMIFS($G$2:$G$1000,$D$2:$D$1000,D17,$C$2:$C$1000,C17) -> 140 | G17: 10 | I17: Business Solutions | J17: Corporate | K17: 20 | L17: =SUMIF($I:$I,I17,$K:$K) -> 100 | U17: CMP | V17: =SUMIF($B:$B,U17,$E:$E) -> 9.1233766 | W17: =VLOOKUP(U17,$Y:$Z,2,FALSE) -> Corporate | Y17: ATC | Z17: Corporate
B18: DPO | C18: Business Solutions | D18: =VLOOKUP($B18,$Y:$Z,2,FALSE) -> Corporate | E18: =G18*SUMIFS($K:$K,$I:$I,C18,$J:$J,D18)/F18 -> 1.4285714 | F18: =SUMIFS($G$2:$G$1000,$D$2:$D$1000,D18,$C$2:$C$1000,C18) -> 140 | G18: 10 | I18: Business Solutions | J18: Operations | K18: 10 | L18: =SUMIF($I:$I,I18,$K:$K) -> 100 | U18: DPO | V18: =SUMIF($B:$B,U18,$E:$E) -> 9.1233766 | W18: =VLOOKUP(U18,$Y:$Z,2,FALSE) -> Corporate | Y18: AVC | Z18: Corporate
B19: FL | C19: Business Solutions | D19: =VLOOKUP($B19,$Y:$Z,2,FALSE) -> Corporate | E19: =G19*SUMIFS($K:$K,$I:$I,C19,$J:$J,D19)/F19 -> 1.4285714 | F19: =SUMIFS($G$2:$G$1000,$D$2:$D$1000,D19,$C$2:$C$1000,C19) -> 140 | G19: 10 | I19: Business Solutions | J19: Technology | K19: 20 | L19: =SUMIF($I:$I,I19,$K:$K) -> 100 | U19: FL | V19: =SUMIF($B:$B,U19,$E:$E) -> 9.1233766 | W19: =VLOOKUP(U19,$Y:$Z,2,FALSE) -> Corporate | Y19: CF | Z19: Corporate
B20: GRH | C20: Business Solutions | D20: =VLOOKUP($B20,$Y:$Z,2,FALSE) -> Corporate | E20: =G20*SUMIFS($K:$K,$I:$I,C20,$J:$J,D20)/F20 -> 1.4285714 | F20: =SUMIFS($G$2:$G$1000,$D$2:$D$1000,D20,$C$2:$C$1000,C20) -> 140 | G20: 10 | I20: Business Solutions | J20: Data & AI | K20: 5 | L20: =SUMIF($I:$I,I20,$K:$K) -> 100 | U20: GRH | V20: =SUMIF($B:$B,U20,$E:$E) -> 9.1233766 | W20: =VLOOKUP(U20,$Y:$Z,2,FALSE) -> Corporate | Y20: CFO | Z20: Corporate
B21: GT | C21: Business Solutions | D21: =VLOOKUP($B21,$Y:$Z,2,FALSE) -> Corporate | E21: =G21*SUMIFS($K:$K,$I:$I,C21,$J:$J,D21)/F21 -> 1.4285714 | F21: =SUMIFS($G$2:$G$1000,$D$2:$D$1000,D21,$C$2:$C$1000,C21) -> 140 | G21: 10 | I21: Retail & Financial Services | J21: CISO | K21: 5 | L21: =SUMIF($I:$I,I21,$K:$K) -> 100 | U21: GT | V21: =SUMIF($B:$B,U21,$E:$E) -> 9.1233766 | W21: =VLOOKUP(U21,$Y:$Z,2,FALSE) -> Corporate | Y21: CHR | Z21: Corporate
B22: PC | C22: Business Solutions | D22: =VLOOKUP($B22,$Y:$Z,2,FALSE) -> Corporate | E22: =G22*SUMIFS($K:$K,$I:$I,C22,$J:$J,D22)/F22 -> 1.4285714 | F22: =SUMIFS($G$2:$G$1000,$D$2:$D$1000,D22,$C$2:$C$1000,C22) -> 140 | G22: 10 | I22: Retail & Financial Services | J22: Commercial | K22: 30 | L22: =SUMIF($I:$I,I22,$K:$K) -> 100 | U22: PC | V22: =SUMIF($B:$B,U22,$E:$E) -> 10.032468 | W22: =VLOOKUP(U22,$Y:$Z,2,FALSE) -> Corporate | Y22: CL | Z22: Corporate
B23: RS | C23: Business Solutions | D23: =VLOOKUP($B23,$Y:$Z,2,FALSE) -> Corporate | E23: =G23*SUMIFS($K:$K,$I:$I,C23,$J:$J,D23)/F23 -> 1.4285714 | F23: =SUMIFS($G$2:$G$1000,$D$2:$D$1000,D23,$C$2:$C$1000,C23) -> 140 | G23: 10 | I23: Retail & Financial Services | J23: Corporate | K23: 30 | L23: =SUMIF($I:$I,I23,$K:$K) -> 100 | U23: RS | V23: =SUMIF($B:$B,U23,$E:$E) -> 9.1233766 | W23: =VLOOKUP(U23,$Y:$Z,2,FALSE) -> Corporate | Y23: CMP | Z23: Corporate
B24: ST | C24: Business Solutions | D24: =VLOOKUP($B24,$Y:$Z,2,FALSE) -> Corporate | E24: =G24*SUMIFS($K:$K,$I:$I,C24,$J:$J,D24)/F24 -> 1.4285714 | F24: =SUMIFS($G$2:$G$1000,$D$2:$D$1000,D24,$C$2:$C$1000,C24) -> 140 | G24: 10 | I24: Retail & Financial Services | J24: Operations | K24: 10 | L24: =SUMIF($I:$I,I24,$K:$K) -> 100 | U24: ST | V24: =SUMIF($B:$B,U24,$E:$E) -> 9.1233766 | W24: =VLOOKUP(U24,$Y:$Z,2,FALSE) -> Corporate | Y24: COM | Z24: Corporate
B25: TF | C25: Business Solutions | D25: =VLOOKUP($B25,$Y:$Z,2,FALSE) -> Corporate | E25: =G25*SUMIFS($K:$K,$I:$I,C25,$J:$J,D25)/F25 -> 1.4285714 | F25: =SUMIFS($G$2:$G$1000,$D$2:$D$1000,D25,$C$2:$C$1000,C25) -> 140 | G25: 10 | I25: Retail & Financial Services | J25: Technology | K25: 20 | L25: =SUMIF($I:$I,I25,$K:$K) -> 100 | U25: TF | V25: =SUMIF($B:$B,U25,$E:$E) -> 9.1233766 | W25: =VLOOKUP(U25,$Y:$Z,2,FALSE) -> Corporate | Y25: DPO | Z25: Corporate
B26: EDO | C26: Business Solutions | D26: =VLOOKUP($B26,$Y:$Z,2,FALSE) -> Operations | E26: =G26*SUMIFS($K:$K,$I:$I,C26,$J:$J,D26)/F26 -> 3.3333333 | F26: =SUMIFS($G$2:$G$1000,$D$2:$D$1000,D26,$C$2:$C$1000,C26) -> 30 | G26: 10 | I26: Retail & Financial Services | J26: Data & AI | K26: 5 | L26: =SUMIF($I:$I,I26,$K:$K) -> 100 | U26: EDO | V26: =SUMIF($B:$B,U26,$E:$E) -> 36.333333 | W26: =VLOOKUP(U26,$Y:$Z,2,FALSE) -> Operations | Y26: FL | Z26: Corporate
... B38: CTTE | C38: eCommerce | D38: =VLOOKUP($B38,$Y:$Z,2,FALSE) -> Commercial | E38: =G38*SUMIFS($K:$K,$I:$I,C38,$J:$J,D38)/F38 -> 1.4705882 | F38: =SUMIFS($G$2:$G$1000,$D$2:$D$1000,D38,$C$2:$C$1000,C38) -> 170 | G38: 10 | I38: Fulfilment | J38: Data & AI | K38: 5 | L38: =SUMIF($I:$I,I38,$K:$K) -> 100 | U38: CFO | V38: =SUMIF($B:$B,U38,$E:$E) -> 1.8181818 | W38: =VLOOKUP(U38,$Y:$Z,2,FALSE) -> Corporate | Y38: SEO | Z38: Operations
B39: DNI | C39: eCommerce | D39: =VLOOKUP($B39,$Y:$Z,2,FALSE) -> Commercial | E39: =G39*SUMIFS($K:$K,$I:$I,C39,$J:$J,D39)/F39 -> 1.4705882 | F39: =SUMIFS($G$2:$G$1000,$D$2:$D$1000,D39,$C$2:$C$1000,C39) -> 170 | G39: 10 | U39: CHR | V39: =SUMIF($B:$B,U39,$E:$E) -> 0.90909091 | W39: =VLOOKUP(U39,$Y:$Z,2,FALSE) -> Corporate | Y39: BCTT | Z39: Technology
B40: ECM | C40: eCommerce | D40: =VLOOKUP($B40,$Y:$Z,2,FALSE) -> Commercial | E40: =G40*SUMIFS($K:$K,$I:$I,C40,$J:$J,D40)/F40 -> 1.4705882 | F40: =SUMIFS($G$2:$G$1000,$D$2:$D$1000,D40,$C$2:$C$1000,C40) -> 170 | G40: 10 | U40: COM | V40: =SUMIF($B:$B,U40,$E:$E) -> 0.90909091 | W40: =VLOOKUP(U40,$Y:$Z,2,FALSE) -> Corporate | Y40: CIO | Z40: Technology
B41: GP B2B | C41: eCommerce | D41: =VLOOKUP($B41,$Y:$Z,2,FALSE) -> Commercial | E41: =G41*SUMIFS($K:$K,$I:$I,C41,$J:$J,D41)/F41 -> 1.4705882 | F41: =SUMIFS($G$2:$G$1000,$D$2:$D$1000,D41,$C$2:$C$1000,C41) -> 170 | G41: 10 | U41: PRO | V41: =SUMIF($B:$B,U41,$E:$E) -> 0.90909091 | W41: =VLOOKUP(U41,$Y:$Z,2,FALSE) -> Corporate | Y41: SI | Z41: Technology
B42: GP B2C | C42: eCommerce | D42: =VLOOKUP($B42,$Y:$Z,2,FALSE) -> Commercial | E42: =G42*SUMIFS($K:$K,$I:$I,C42,$J:$J,D42)/F42 -> 1.4705882 | F42: =SUMIFS($G$2:$G$1000,$D$2:$D$1000,D42,$C$2:$C$1000,C42) -> 170 | G42: 10 | U42: COO | V42: =SUMIF($B:$B,U42,$E:$E) -> 8.3333333 | W42: =VLOOKUP(U42,$Y:$Z,2,FALSE) -> Operations | Y42: SI-CRP | Z42: Technology
B43: GP ECL | C43: eCommerce | D43: =VLOOKUP($B43,$Y:$Z,2,FALSE) -> Commercial | E43: =G43*SUMIFS($K:$K,$I:$I,C43,$J:$J,D43)/F43 -> 2.9411765 | F43: =SUMIFS($G$2:$G$1000,$D$2:$D$1000,D43,$C$2:$C$1000,C43) -> 170 | G43: 20 | U43: CIO | V43: =SUMIF($B:$B,U43,$E:$E) -> 3.75 | W43: =VLOOKUP(U43,$Y:$Z,2,FALSE) -> Technology | Y43: SI-OPS | Z43: Technology
B44: GPG | C44: eCommerce | D44: =VLOOKUP($B44,$Y:$Z,2,FALSE) -> Commercial | E44: =G44*SUMIFS($K:$K,$I:$I,C44,$J:$J,D44)/F44 -> 1.4705882 | F44: =SUMIFS($G$2:$G$1000,$D$2:$D$1000,D44,$C$2:$C$1000,C44) -> 170 | G44: 10 | U44: IAD | V44: =SUMIF($B:$B,U44,$E:$E) -> 35 | W44: =VLOOKUP(U44,$Y:$Z,2,FALSE) -> Data & AI | Y44: SI-PRD | Z44: Technology
B45: GS | C45: eCommerce | D45: =VLOOKUP($B45,$Y:$Z,2,FALSE) -> Commercial | E45: =G45*SUMIFS($K:$K,$I:$I,C45,$J:$J,D45)/F45 -> 2.9411765 | F45: =SUMIFS($G$2:$G$1000,$D$2:$D$1000,D45,$C$2:$C$1000,C45) -> 170 | G45: 20 | U45: 0 | Y45: IAD | Z45: Data & AI
B46: IDC | C46: eCommerce | D46: =VLOOKUP($B46,$Y:$Z,2,FALSE) -> Commercial | E46: =G46*SUMIFS($K:$K,$I:$I,C46,$J:$J,D46)/F46 -> 2.9411765 | F46: =SUMIFS($G$2:$G$1000,$D$2:$D$1000,D46,$C$2:$C$1000,C46) -> 170 | G46: 20
B47: ACR | C47: eCommerce | D47: =VLOOKUP($B47,$Y:$Z,2,FALSE) -> Corporate | E47: =G47*SUMIFS($K:$K,$I:$I,C47,$J:$J,D47)/F47 -> 0.90909091 | F47: =SUMIFS($G$2:$G$1000,$D$2:$D$1000,D47,$C$2:$C$1000,C47) -> 220 | G47: 10
B48: ATC | C48: eCommerce | D48: =VLOOKUP($B48,$Y:$Z,2,FALSE) -> Corporate | E48: =G48*SUMIFS($K:$K,$I:$I,C48,$J:$J,D48)/F48 -> 1.8181818 | F48: =SUMIFS($G$2:$G$1000,$D$2:$D$1000,D48,$C$2:$C$1000,C48) -> 220 | G48: 20
B49: AVC | C49: eCommerce | D49: =VLOOKUP($B49,$Y:$Z,2,FALSE) -> Corporate | E49: =G49*SUMIFS($K:$K,$I:$I,C49,$J:$J,D49)/F49 -> 0.90909091 | F49: =SUMIFS($G$2:$G$1000,$D$2:$D$1000,D49,$C$2:$C$1000,C49) -> 220 | G49: 10
B50: CF | C50: eCommerce | D50: =VLOOKUP($B50,$Y:$Z,2,FALSE) -> Corporate | E50: =G50*SUMIFS($K:$K,$I:$I,C50,$J:$J,D50)/F50 -> 1.8181818 | F50: =SUMIFS($G$2:$G$1000,$D$2:$D$1000,D50,$C$2:$C$1000,C50) -> 220 | G50: 20
B51: CFO | C51: eCommerce | D51: =VLOOKUP($B51,$Y:$Z,2,FALSE) -> Corporate | E51: =G51*SUMIFS($K:$K,$I:$I,C51,$J:$J,D51)/F51 -> 1.8181818 | F51: =SUMIFS($G$2:$G$1000,$D$2:$D$1000,D51,$C$2:$C$1000,C51) -> 220 | G51: 20
...

Sheet ideas-test
A1: ID | B1: Name | C1: RequestingArea | D1: RevenueStream | E1: BudgetGroup | F1: MicroPhase | G1: PriorityRA | H1: Value | I1: Urgency | J1: Risk | K1: Size | N1: Ideas Check | O1: _RA
A2: IDEA001 | B2: New eCommerce Portal | C2: GP ECL | D2: eCommerce | E2: Commercial | F2: Backlog | G2: 4 | N2: =D2&"-"&C2 -> eCommerce-GP ECL | O2: =IF(ISNA(VLOOKUP(N2,weights!X:X,1,FALSE)),"ALERT","Ok") -> ALERT
A3: IDEA002 | B3: Checkout Optimization | C3: GP B2B | D3: Mail | E3: Commercial | F3: In Development | G3: 1 | N3: =D3&"-"&C3 -> Mail-GP B2B | O3: =IF(ISNA(VLOOKUP(N3,weights!X:X,1,FALSE)),"ALERT","Ok") -> ALERT
A4: IDEA003 | B4: Mail Sorting Automation | C4: EDO | D4: Mail | E4: Operations | F4: In Acceptance | G4: 1 | N4: =D4&"-"&C4 -> Mail-EDO | O4: =IF(ISNA(VLOOKUP(N4,weights!X:X,1,FALSE)),"ALERT","Ok") -> ALERT
A5: IDEA004 | B5: ML Recommendations | C5: DAI | D5: eCommerce | E5: Data&AI | F5: Ready for Execution | G5: 1 | N5: =D5&"-"&C5 -> eCommerce-DAI | O5: =IF(ISNA(VLOOKUP(N5,weights!X:X,1,FALSE)),"ALERT","Ok") -> ALERT
A6: IDEA005 | B6: Mobile Payment System | C6: GPG | D6: Payments | E6: Commercial | F6: In Development | G6: 1 | N6: =D6&"-"&C6 -> Payments-GPG | O6: =IF(ISNA(VLOOKUP(N6,weights!X:X,1,FALSE)),"ALERT","Ok") -> ALERT
A7: IDEA006 | B7: Customer Portal Enhancement | C7: GP ECL | D7: eCommerce | E7: Commercial | F7: Backlog | G7: 3 | N7: =D7&"-"&C7 -> eCommerce-GP ECL | O7: =IF(ISNA(VLOOKUP(N7,weights!X:X,1,FALSE)),"ALERT","Ok") -> ALERT
A8: IDEA007 | B8: Fulfilment Tracking System | C8: GP ECL | D8: Fulfilment | E8: Operations | F8: Ready for Acceptance | G8: 1 | N8: =D8&"-"&C8 -> Fulfilment-GP ECL | O8: =IF(ISNA(VLOOKUP(N8,weights!X:X,1,FALSE)),"ALERT","Ok") -> ALERT
A9: IDEA008 | B9: Business Analytics Dashboard | C9: DAI | D9: Business Solutions | E9: Data&AI | F9: Pitch | G9: 2 | N9: =D9&"-"&C9 -> Business Solutions-DAI | O9: =IF(ISNA(VLOOKUP(N9,weights!X:X,1,FALSE)),"ALERT","Ok") -> ALERT
A10: IDEA009 | B10: Mail API Integration | C10: SI | D10: Mail | E10: Technology | F10: Ready for Execution | G10: 2 | N10: =D10&"-"&C10 -> Mail-SI | O10: =IF(ISNA(VLOOKUP(N10,weights!X:X,1,FALSE)),"ALERT","Ok") -> ALERT
A11: IDEA010 | B11: Retail POS Upgrade | C11: GP B2C | D11: Retail & Financial Services | E11: Commercial | F11: In Approval | G11: 1 | N11: =D11&"-"&C11 -> Retail & Financial Services-GP B2C | O11: =IF(ISNA(VLOOKUP(N11,weights!X:X,1,FALSE)),"ALERT","Ok") -> ALERT
A12: IDEA011 | B12: Security Compliance Update | C12: CISO | D12: eCommerce | E12: CISO | F12: Ready for Execution | G12: 1 | N12: =D12&"-"&C12 -> eCommerce-CISO | O12: =IF(ISNA(VLOOKUP(N12,weights!X:X,1,FALSE)),"ALERT","Ok") -> ALERT
A13: IDEA012 | B13: Banco CTT Mobile App | C13: BCTT | D13: Mail | E13: Corporate | F13: In Rollout | G13: 1 | N13: =D13&"-"&C13 -> Mail-BCTT | O13: =IF(ISNA(VLOOKUP(N13,weights!X:X,1,FALSE)),"ALERT","Ok") -> ALERT
... A21: IDEA020 | B21: Banco CTT Security Enhancement | C21: CISO | D21: Banco CTT | E21: CISO | F21: In Development | G21: 2 | N21: =D21&"-"&C21 -> Banco CTT-CISO | O21: =IF(ISNA(VLOOKUP(N21,weights!X:X,1,FALSE)),"ALERT","Ok") -> ALERT
A22: IDEA021 | B22: System 1 | C22: SI | D22: Mail | E22: Technology | F22: Ready for Execution | G22: 4 | H22: 2 | N22: =D22&"-"&C22 -> Mail-SI
A23: IDEA022 | B23: System 2 | C23: SI | D23: Mail | E23: Technology | F23: Ready for Execution | G23: 5 | H23: 3
A24: IDEA023 | B24: System 3 | C24: SI | D24: Mail | E24: Technology | F24: Ready for Execution | G24: 6 | H24: 4
A25: IDEA024 | B25: System 4 | C25: SI | D25: Mail | E25: Technology | F25: Ready for Execution | G25: 7 | H25: 5
A26: IDEA025 | B26: System 5 | C26: SI | D26: eCommerce | E26: Technology | F26: Ready for Execution | G26: 8 | H26: 6
A27: IDEA026 | B27: System 6 | C27: SI | D27: eCommerce | E27: Technology | F27: Ready for Execution | G27: 9 | H27: 7
A28: IDEA027 | B28: System 7 | C28: SI | D28: eCommerce | E28: Technology | F28: Ready for Execution | G28: 10 | H28: 8
A29: IDEA028 | B29: System 8 | C29: SI | D29: eCommerce | E29: Technology | F29: Ready for Execution | G29: 11 | H29: 9
