Workbook

Sheet pivot
A1: top x | B1: TRUE | F1: top x | G1: TRUE | J1: top x | K1: TRUE | N1: top x | O1: TRUE
A2: Queue | B2: LATER | F2: Queue | G2: LATER | J2: Queue | K2: LATER | N2: Queue | O2: LATER
A4: Count of ID | B4: Column Labels | F4: Count of ID | G4: Column Labels | J4: Count of ID | K4: Column Labels | N4: Count of ID | O4: Column Labels
A5: Row Labels | B5: eCommerce | C5: Grand Total | F5: Row Labels | G5: Mail | H5: Grand Total | J5: Row Labels | K5: Business Solutions | L5: Grand Total | N5: Row Labels | O5: Retail & Financial Services | P5: Grand Total
A6: Commercial | B6: 12 | C6: 12 | F6: CISO | G6: 1 | H6: 1 | J6: Commercial | K6: 8 | L6: 8 | N6: Commercial | O6: 10 | P6: 10
A7: CCO | B7: 2 | C7: 2 | F7: CISO | G7: 1 | H7: 1 | J7: GP B2B | K7: 7 | L7: 7 | N7: GS | O7: 5 | P7: 5
A8: CMO | B8: 2 | C8: 2 | F8: Commercial | G8: 4 | H8: 4 | J8: GS | K8: 1 | L8: 1 | N8: GP B2C | O8: 5 | P8: 5
A9: DNI | B9: 2 | C9: 2 | F9: GS | G9: 1 | H9: 1 | J9: Technology | K9: 8 | L9: 8 | N9: Grand Total | O9: 10 | P9: 10
A10: GP ECL | B10: 2 | C10: 2 | F10: GP B2B | G10: 1 | H10: 1 | J10: SI-PRD | K10: 8 | L10: 8
A11: GS | B11: 2 | C11: 2 | F11: CSI | G11: 1 | H11: 1 | J11: Grand Total | K11: 16 | L11: 16
A12: IDC | B12: 2 | C12: 2 | F12: DNI | G12: 1 | H12: 1
A13: Corporate | B13: 11 | C13: 11 | F13: Corporate | G13: 12 | H13: 12
A14: ATC | B14: 2 | C14: 2 | F14: GRH | G14: 1 | H14: 1
A15: AVC | B15: 2 | C15: 2 | F15: ST | G15: 1 | H15: 1
A16: CFO | B16: 2 | C16: 2 | F16: PC | G16: 1 | H16: 1
A17: COM | B17: 1 | C17: 1 | F17: AVC | G17: 1 | H17: 1
A18: PC | B18: 2 | C18: 2 | F18: FL | G18: 1 | H18: 1
A19: PRO | B19: 2 | C19: 2 | F19: CF | G19: 1 | H19: 1
A20: Operations | B20: 10 | C20: 10 | F20: GT | G20: 1 | H20: 1
A21: COO | B21: 4 | C21: 4 | F21: CL | G21: 1 | H21: 1
A22: EDO | B22: 3 | C22: 3 | F22: RS | G22: 1 | H22: 1
A23: EM | B23: 1 | C23: 1 | F23: CMP | G23: 1 | H23: 1
... A30: Grand Total | B30: 41 | C30: 41 | F30: SI-PRD | G30: 1 | H30: 1
F31: SI-OPS | G31: 1 | H31: 1
F32: BCTT | G32: 1 | H32: 1
F33: SI | G33: 1 | H33: 1
F34: Grand Total | G34: 23 | H34: 23

Sheet demand
A1: Queue | B1: Method | C1: GlobalRank | D1: ID | E1: Name | F1: RequestingArea | G1: RevenueStream | H1: BudgetGroup | I1: MicroPhase | J1: PriorityRA | K1: WSJF_Score | L1: Value | M1: Urgency | N1: Risk | O1: Size | P1: top x | Q1: 108
A2: LATER | B2: SainteLague | C2: 9 | D2: 130701 | E2: Nuevos desarrollos Normalizaci√õn de direcciones | F2: COO | G2: eCommerce | H2: Operations | I2: In Definition | J2: 2 | K2: 0.03 | L2: 1 | M2: 1 | N2: 1 | O2: 100 | P2: =C2<($Q$1+1) -> TRUE
A3: LATER | B3: SainteLague | C3: 10 | D3: 125697 | E3: DeMinimis EUA - Solu√Å‚Äûo para retomar os envios de Bens para os EUA para os clientes n‚Äûo contratuais | F3: GP B2B | G3: Mail | H3: Commercial | I3: Backlog | J3: 1 | K3: 3 | L3: 3 | M3: 3 | N3: 3 | O3: 3 | P3: =C3<($Q$1+1) -> TRUE
A4: LATER | B4: SainteLague | C4: 11 | D4: 135288 | E4: Desenvolvimentos CNE no ‚Äömbito do Correio Inteligente | F4: GP B2B | G4: Business Solutions | H4: Commercial | I4: Backlog | J4: 8 | K4: 0.03 | L4: 1 | M4: 1 | N4: 1 | O4: 100 | P4: =C4<($Q$1+1) -> TRUE
A5: LATER | B5: SainteLague | C5: 12 | D5: 115295 | E5: Nexus - Piloto Operacional Fase 2 | F5: EDO | G5: eCommerce | H5: Operations | I5: In Definition | J5: 2 | K5: 0.03 | L5: 1 | M5: 1 | N5: 1 | O5: 100 | P5: =C5<($Q$1+1) -> TRUE
A6: LATER | B6: SainteLague | C6: 13 | D6: 118174 | E6: GPB2C | Parceria Unic‚Äömbio - Operacionaliza√Å‚Äûo de servi√Åo de cambio | F6: GP B2C | G6: Retail & Financial Services | H6: Commercial | I6: Backlog | J6: 1 | K6: 0.03 | L6: 1 | M6: 1 | N6: 1 | O6: 100 | P6: =C6<($Q$1+1) -> TRUE
A7: LATER | B7: SainteLague | C7: 14 | D7: 77828 | E7: Base Dados Modelo de Incentivos CTT Expresso | F7: SEO | G7: eCommerce | H7: Operations | I7: In Definition | J7: 2 | K7: 0.03 | L7: 1 | M7: 1 | N7: 1 | O7: 100 | P7: =C7<($Q$1+1) -> TRUE
A8: LATER | B8: SainteLague | C8: 15 | D8: 168516 | E8: Gera√Å‚Äûo de ficheiro excel com dados NEV | F8: GPG | G8: Payments | H8: Commercial | I8: In Definition | J8: 1 | K8: 0.03 | L8: 1 | M8: 1 | N8: 1 | O8: 100 | P8: =C8<($Q$1+1) -> TRUE
A9: LATER | B9: SainteLague | C9: 16 | D9: 122320 | E9: Implementa√Å‚Äûo de modulo de Planeamento de Transportes em Drivian e Descontinua√Å‚Äûo do Sigest | F9: SEO | G9: Mail | H9: Operations | I9: High Level Design | J9: 1 | K9: 4.5 | L9: 4 | M9: 2 | N9: 3 | O9: 2 | P9: =C9<($Q$1+1) -> TRUE
A10: LATER | B10: SainteLague | C10: 17 | D10: 60579 | E10: Nexus | P&S | Implementa√Å‚Äûo da oferta ib√àrica | F10: GP ECL | G10: eCommerce | H10: Commercial | I10: High Level Design | J10: 1 | K10: 0.03 | L10: 1 | M10: 1 | N10: 1 | O10: 100 | P10: =C10<($Q$1+1) -> TRUE
A11: LATER | B11: SainteLague | C11: 18 | D11: 120972 | E11: Cliente EDP - WS P&F- Novo Campo Data | F11: GS | G11: Business Solutions | H11: Commercial | I11: Backlog | J11: 4 | K11: 0.03 | L11: 1 | M11: 1 | N11: 1 | O11: 100 | P11: =C11<($Q$1+1) -> TRUE
A12: LATER | B12: SainteLague | C12: 19 | D12: 129984 | E12: Reconciliaci√õn bancaria de Cobros por tarjeta y Bizum | F12: CFO | G12: eCommerce | H12: Corporate | I12: High Level Design | J12: 1 | K12: 0.03 | L12: 1 | M12: 1 | N12: 1 | O12: 100 | P12: =C12<($Q$1+1) -> TRUE
A13: LATER | B13: SainteLague | C13: 20 | D13: 126644 | E13: GENAI- Rossum | F13: CF | G13: Mail | H13: Corporate | I13: Backlog | J13: 1 | K13: 0.03 | L13: 1 | M13: 1 | N13: 1 | O13: 100 | P13: =C13<($Q$1+1) -> TRUE
... A953: NEXT | B953: WSJF | C953: 8 | D953: 99510 | E953: SAPSF - Solu√Å‚Äûo de Interoperabilidade com a Seguran√Åa Social (Regulat√õrio) | F953: GRH | G953: Mail | H953: Corporate | I953: Ready for Development | J953: 2 | K953: 0.03 | L953: 1 | M953: 1 | N953: 1 | O953: 100 | P953: =C953<($Q$1+1) -> TRUE

Sheet refData
B1: EXPORT CSV | C1: WEIGHTS_RA | G1: ALTERAR | I1: REF DATA | N1: EXPORT CSV | O1: WEIGHTS_RS | R1: REF DATA | U1: REF DATA
B2: RequestingArea | C2: RevenueStream | D2: BudgetGroup | E2: Weight | F2: Weight-RS+BG | G2: Weight-Base | I2: RevenueStream | J2: BudgetGroup | K2: Weight | L2: Check | N2: RevenueStream | O2: Weight | P2: Check | R2: RequestingArea | S2: BudgetGroup | U2: MicroPhase bmap | V2: MicroPhase Macro | W2: MicroPhase Demand
B3: CISO | C3: Business Solutions | D3: =VLOOKUP($B3,$R:$S,2,FALSE) -> CISO | E3: =G3*SUMIFS($K:$K,$I:$I,C3,$J:$J,D3)/F3 -> 5 | F3: =SUMIFS($G$2:$G$1000,$D$2:$D$1000,D3,$C$2:$C$1000,C3) -> 20 | G3: 20 | I3: eCommerce | J3: CISO | K3: 5 | L3: =SUMIF($I:$I,I3,$K:$K) -> 100 | N3: eCommerce | O3: 26 | P3: =SUM(O3:O18) -> 100 | R3: CISO | S3: CISO | U3: IDEA > Backlog | V3: {=_xlfn.TEXTSPLIT(U3,">",)} -> IDEA | W3: Backlog
B4: CSI | C4: Business Solutions | D4: =VLOOKUP($B4,$R:$S,2,FALSE) -> Commercial | E4: =G4*SUMIFS($K:$K,$I:$I,C4,$J:$J,D4)/F4 -> 4 | F4: =SUMIFS($G$2:$G$1000,$D$2:$D$1000,D4,$C$2:$C$1000,C4) -> 100 | G4: 10 | I4: eCommerce | J4: Commercial | K4: 25 | L4: =SUMIF($I:$I,I4,$K:$K) -> 100 | N4: Mail | O4: 22 | R4: CCO | S4: Commercial | U4: IDEA > Pitch | V4: {=_xlfn.TEXTSPLIT(U4,">",)} -> IDEA | W4: Pitch
B5: CTTE | C5: Business Solutions | D5: =VLOOKUP($B5,$R:$S,2,FALSE) -> Commercial | E5: =G5*SUMIFS($K:$K,$I:$I,C5,$J:$J,D5)/F5 -> 4 | F5: =SUMIFS($G$2:$G$1000,$D$2:$D$1000,D5,$C$2:$C$1000,C5) -> 100 | G5: 10 | I5: eCommerce | J5: Corporate | K5: 20 | L5: =SUMIF($I:$I,I5,$K:$K) -> 100 | N5: Business Solutions | O5: 16 | R5: CMO | S5: Commercial | U5: IDEA > In Definition | V5: {=_xlfn.TEXTSPLIT(U5,">",)} -> IDEA | W5: In Definition
B6: DNI | C6: Business Solutions | D6: =VLOOKUP($B6,$R:$S,2,FALSE) -> Commercial | E6: =G6*SUMIFS($K:$K,$I:$I,C6,$J:$J,D6)/F6 -> 4 | F6: =SUMIFS($G$2:$G$1000,$D$2:$D$1000,D6,$C$2:$C$1000,C6) -> 100 | G6: 10 | I6: eCommerce | J6: Operations | K6: 25 | L6: =SUMIF($I:$I,I6,$K:$K) -> 100 | N6: Retail & Financial Services | O6: 14 | R6: CSI | S6: Commercial | U6: SOLUTION > In Approval | V6: {=_xlfn.TEXTSPLIT(U6,">",)} -> SOLUTION | W6: In Approval
B7: ECM | C7: Business Solutions | D7: =VLOOKUP($B7,$R:$S,2,FALSE) -> Commercial | E7: =G7*SUMIFS($K:$K,$I:$I,C7,$J:$J,D7)/F7 -> 4 | F7: =SUMIFS($G$2:$G$1000,$D$2:$D$1000,D7,$C$2:$C$1000,C7) -> 100 | G7: 10 | I7: eCommerce | J7: Technology | K7: 15 | L7: =SUMIF($I:$I,I7,$K:$K) -> 100 | N7: Payments | O7: 12 | R7: CTTE | S7: Commercial | U7: SOLUTION > Ready for Approval | V7: {=_xlfn.TEXTSPLIT(U7,">",)} -> SOLUTION | W7: Ready for Approval
B8: GP B2B | C8: Business Solutions | D8: =VLOOKUP($B8,$R:$S,2,FALSE) -> Commercial | E8: =G8*SUMIFS($K:$K,$I:$I,C8,$J:$J,D8)/F8 -> 8 | F8: =SUMIFS($G$2:$G$1000,$D$2:$D$1000,D8,$C$2:$C$1000,C8) -> 100 | G8: 20 | I8: eCommerce | J8: Data & AI | K8: 10 | L8: =SUMIF($I:$I,I8,$K:$K) -> 100 | N8: Fulfilment | O8: 10 | R8: DNI | S8: Commercial | U8: IDEA > Ready for Solution | V8: {=_xlfn.TEXTSPLIT(U8,">",)} -> IDEA | W8: Ready for Solution
B9: GP B2C | C9: Business Solutions | D9: =VLOOKUP($B9,$R:$S,2,FALSE) -> Commercial | E9: =G9*SUMIFS($K:$K,$I:$I,C9,$J:$J,D9)/F9 -> 4 | F9: =SUMIFS($G$2:$G$1000,$D$2:$D$1000,D9,$C$2:$C$1000,C9) -> 100 | G9: 10 | I9: Mail | J9: CISO | K9: 5 | L9: =SUMIF($I:$I,I9,$K:$K) -> 100 | N9: Banco CTT | O9: 0 | R9: ECM | S9: Commercial | U9: SOLUTION > High Level Design | V9: {=_xlfn.TEXTSPLIT(U9,">",)} -> SOLUTION | W9: High Level Design
B10: GP ECL | C10: Business Solutions | D10: =VLOOKUP($B10,$R:$S,2,FALSE) -> Commercial | E10: =G10*SUMIFS($K:$K,$I:$I,C10,$J:$J,D10)/F10 -> 4 | F10: =SUMIFS($G$2:$G$1000,$D$2:$D$1000,D10,$C$2:$C$1000,C10) -> 100 | G10: 10 | I10: Mail | J10: Commercial | K10: 30 | L10: =SUMIF($I:$I,I10,$K:$K) -> 100 | R10: GP B2B | S10: Commercial | U10: SOLUTION > Ready for Development | V10: {=_xlfn.TEXTSPLIT(U10,">",)} -> SOLUTION | W10: Ready for Development
B11: GPG | C11: Business Solutions | D11: =VLOOKUP($B11,$R:$S,2,FALSE) -> Commercial | E11: =G11*SUMIFS($K:$K,$I:$I,C11,$J:$J,D11)/F11 -> 4 | F11: =SUMIFS($G$2:$G$1000,$D$2:$D$1000,D11,$C$2:$C$1000,C11) -> 100 | G11: 10 | I11: Mail | J11: Corporate | K11: 20 | L11: =SUMIF($I:$I,I11,$K:$K) -> 100 | R11: GP B2C | S11: Commercial | U11: SOLUTION > In Definition | V11: {=_xlfn.TEXTSPLIT(U11,">",)} -> SOLUTION | W11: In Definition
B12: GS | C12: Business Solutions | D12: =VLOOKUP($B12,$R:$S,2,FALSE) -> Commercial | E12: =G12*SUMIFS($K:$K,$I:$I,C12,$J:$J,D12)/F12 -> 4 | F12: =SUMIFS($G$2:$G$1000,$D$2:$D$1000,D12,$C$2:$C$1000,C12) -> 100 | G12: 10 | I12: Mail | J12: Operations | K12: 20 | L12: =SUMIF($I:$I,I12,$K:$K) -> 100 | R12: GP ECL | S12: Commercial
B13: ACR | C13: Business Solutions | D13: =VLOOKUP($B13,$R:$S,2,FALSE) -> Corporate | E13: =G13*SUMIFS($K:$K,$I:$I,C13,$J:$J,D13)/F13 -> 1.4285714 | F13: =SUMIFS($G$2:$G$1000,$D$2:$D$1000,D13,$C$2:$C$1000,C13) -> 140 | G13: 10 | I13: Mail | J13: Technology | K13: 20 | L13: =SUMIF($I:$I,I13,$K:$K) -> 100 | R13: GPG | S13: Commercial
B14: AVC | C14: Business Solutions | D14: =VLOOKUP($B14,$R:$S,2,FALSE) -> Corporate | E14: =G14*SUMIFS($K:$K,$I:$I,C14,$J:$J,D14)/F14 -> 1.4285714 | F14: =SUMIFS($G$2:$G$1000,$D$2:$D$1000,D14,$C$2:$C$1000,C14) -> 140 | G14: 10 | I14: Mail | J14: Data & AI | K14: 5 | L14: =SUMIF($I:$I,I14,$K:$K) -> 100 | R14: GS | S14: Commercial
B15: CF | C15: Business Solutions | D15: =VLOOKUP($B15,$R:$S,2,FALSE) -> Corporate | E15: =G15*SUMIFS($K:$K,$I:$I,C15,$J:$J,D15)/F15 -> 2.8571429 | F15: =SUMIFS($G$2:$G$1000,$D$2:$D$1000,D15,$C$2:$C$1000,C15) -> 140 | G15: 20 | I15: Business Solutions | J15: CISO | K15: 5 | L15: =SUMIF($I:$I,I15,$K:$K) -> 100 | R15: IDC | S15: Commercial
B16: CL | C16: Business Solutions | D16: =VLOOKUP($B16,$R:$S,2,FALSE) -> Corporate | E16: =G16*SUMIFS($K:$K,$I:$I,C16,$J:$J,D16)/F16 -> 1.4285714 | F16: =SUMIFS($G$2:$G$1000,$D$2:$D$1000,D16,$C$2:$C$1000,C16) -> 140 | G16: 10 | I16: Business Solutions | J16: Commercial | K16: 40 | L16: =SUMIF($I:$I,I16,$K:$K) -> 100 | R16: ACR | S16: Corporate
B17: CMP | C17: Business Solutions | D17: =VLOOKUP($B17,$R:$S,2,FALSE) -> Corporate | E17: =G17*SUMIFS($K:$K,$I:$I,C17,$J:$J,D17)/F17 -> 1.4285714 | F17: =SUMIFS($G$2:$G$1000,$D$2:$D$1000,D17,$C$2:$C$1000,C17) -> 140 | G17: 10 | I17: Business Solutions | J17: Corporate | K17: 20 | L17: =SUMIF($I:$I,I17,$K:$K) -> 100 | R17: ATC | S17: Corporate
B18: DPO | C18: Business Solutions | D18: =VLOOKUP($B18,$R:$S,2,FALSE) -> Corporate | E18: =G18*SUMIFS($K:$K,$I:$I,C18,$J:$J,D18)/F18 -> 1.4285714 | F18: =SUMIFS($G$2:$G$1000,$D$2:$D$1000,D18,$C$2:$C$1000,C18) -> 140 | G18: 10 | I18: Business Solutions | J18: Operations | K18: 10 | L18: =SUMIF($I:$I,I18,$K:$K) -> 100 | R18: AVC | S18: Corporate
B19: FL | C19: Business Solutions | D19: =VLOOKUP($B19,$R:$S,2,FALSE) -> Corporate | E19: =G19*SUMIFS($K:$K,$I:$I,C19,$J:$J,D19)/F19 -> 1.4285714 | F19: =SUMIFS($G$2:$G$1000,$D$2:$D$1000,D19,$C$2:$C$1000,C19) -> 140 | G19: 10 | I19: Business Solutions | J19: Technology | K19: 20 | L19: =SUMIF($I:$I,I19,$K:$K) -> 100 | R19: CF | S19: Corporate
B20: GRH | C20: Business Solutions | D20: =VLOOKUP($B20,$R:$S,2,FALSE) -> Corporate | E20: =G20*SUMIFS($K:$K,$I:$I,C20,$J:$J,D20)/F20 -> 1.4285714 | F20: =SUMIFS($G$2:$G$1000,$D$2:$D$1000,D20,$C$2:$C$1000,C20) -> 140 | G20: 10 | I20: Business Solutions | J20: Data & AI | K20: 5 | L20: =SUMIF($I:$I,I20,$K:$K) -> 100 | R20: CFO | S20: Corporate
B21: GT | C21: Business Solutions | D21: =VLOOKUP($B21,$R:$S,2,FALSE) -> Corporate | E21: =G21*SUMIFS($K:$K,$I:$I,C21,$J:$J,D21)/F21 -> 1.4285714 | F21: =SUMIFS($G$2:$G$1000,$D$2:$D$1000,D21,$C$2:$C$1000,C21) -> 140 | G21: 10 | I21: Retail & Financial Services | J21: CISO | K21: 5 | L21: =SUMIF($I:$I,I21,$K:$K) -> 100 | R21: CHR | S21: Corporate
B22: PC | C22: Business Solutions | D22: =VLOOKUP($B22,$R:$S,2,FALSE) -> Corporate | E22: =G22*SUMIFS($K:$K,$I:$I,C22,$J:$J,D22)/F22 -> 1.4285714 | F22: =SUMIFS($G$2:$G$1000,$D$2:$D$1000,D22,$C$2:$C$1000,C22) -> 140 | G22: 10 | I22: Retail & Financial Services | J22: Commercial | K22: 30 | L22: =SUMIF($I:$I,I22,$K:$K) -> 100 | R22: CL | S22: Corporate
B23: RS | C23: Business Solutions | D23: =VLOOKUP($B23,$R:$S,2,FALSE) -> Corporate | E23: =G23*SUMIFS($K:$K,$I:$I,C23,$J:$J,D23)/F23 -> 1.4285714 | F23: =SUMIFS($G$2:$G$1000,$D$2:$D$1000,D23,$C$2:$C$1000,C23) -> 140 | G23: 10 | I23: Retail & Financial Services | J23: Corporate | K23: 30 | L23: =SUMIF($I:$I,I23,$K:$K) -> 100 | R23: CMP | S23: Corporate
... B38: CTTE | C38: eCommerce | D38: =VLOOKUP($B38,$R:$S,2,FALSE) -> Commercial | E38: =G38*SUMIFS($K:$K,$I:$I,C38,$J:$J,D38)/F38 -> 1.4705882 | F38: =SUMIFS($G$2:$G$1000,$D$2:$D$1000,D38,$C$2:$C$1000,C38) -> 170 | G38: 10 | I38: Fulfilment | J38: Data & AI | K38: 5 | L38: =SUMIF($I:$I,I38,$K:$K) -> 100 | R38: SEO | S38: Operations
B39: DNI | C39: eCommerce | D39: =VLOOKUP($B39,$R:$S,2,FALSE) -> Commercial | E39: =G39*SUMIFS($K:$K,$I:$I,C39,$J:$J,D39)/F39 -> 1.4705882 | F39: =SUMIFS($G$2:$G$1000,$D$2:$D$1000,D39,$C$2:$C$1000,C39) -> 170 | G39: 10 | R39: BCTT | S39: Technology
B40: ECM | C40: eCommerce | D40: =VLOOKUP($B40,$R:$S,2,FALSE) -> Commercial | E40: =G40*SUMIFS($K:$K,$I:$I,C40,$J:$J,D40)/F40 -> 1.4705882 | F40: =SUMIFS($G$2:$G$1000,$D$2:$D$1000,D40,$C$2:$C$1000,C40) -> 170 | G40: 10 | R40: CIO | S40: Technology
B41: GP B2B | C41: eCommerce | D41: =VLOOKUP($B41,$R:$S,2,FALSE) -> Commercial | E41: =G41*SUMIFS($K:$K,$I:$I,C41,$J:$J,D41)/F41 -> 1.4705882 | F41: =SUMIFS($G$2:$G$1000,$D$2:$D$1000,D41,$C$2:$C$1000,C41) -> 170 | G41: 10 | R41: SI | S41: Technology
B42: GP B2C | C42: eCommerce | D42: =VLOOKUP($B42,$R:$S,2,FALSE) -> Commercial | E42: =G42*SUMIFS($K:$K,$I:$I,C42,$J:$J,D42)/F42 -> 1.4705882 | F42: =SUMIFS($G$2:$G$1000,$D$2:$D$1000,D42,$C$2:$C$1000,C42) -> 170 | G42: 10 | R42: SI-CRP | S42: Technology
B43: GP ECL | C43: eCommerce | D43: =VLOOKUP($B43,$R:$S,2,FALSE) -> Commercial | E43: =G43*SUMIFS($K:$K,$I:$I,C43,$J:$J,D43)/F43 -> 2.9411765 | F43: =SUMIFS($G$2:$G$1000,$D$2:$D$1000,D43,$C$2:$C$1000,C43) -> 170 | G43: 20 | R43: SI-OPS | S43: Technology
B44: GPG | C44: eCommerce | D44: =VLOOKUP($B44,$R:$S,2,FALSE) -> Commercial | E44: =G44*SUMIFS($K:$K,$I:$I,C44,$J:$J,D44)/F44 -> 1.4705882 | F44: =SUMIFS($G$2:$G$1000,$D$2:$D$1000,D44,$C$2:$C$1000,C44) -> 170 | G44: 10 | R44: SI-PRD | S44: Technology
B45: GS | C45: eCommerce | D45: =VLOOKUP($B45,$R:$S,2,FALSE) -> Commercial | E45: =G45*SUMIFS($K:$K,$I:$I,C45,$J:$J,D45)/F45 -> 2.9411765 | F45: =SUMIFS($G$2:$G$1000,$D$2:$D$1000,D45,$C$2:$C$1000,C45) -> 170 | G45: 20 | R45: IAD | S45: Data & AI
B46: IDC | C46: eCommerce | D46: =VLOOKUP($B46,$R:$S,2,FALSE) -> Commercial | E46: =G46*SUMIFS($K:$K,$I:$I,C46,$J:$J,D46)/F46 -> 2.9411765 | F46: =SUMIFS($G$2:$G$1000,$D$2:$D$1000,D46,$C$2:$C$1000,C46) -> 170 | G46: 20
B47: ACR | C47: eCommerce | D47: =VLOOKUP($B47,$R:$S,2,FALSE) -> Corporate | E47: =G47*SUMIFS($K:$K,$I:$I,C47,$J:$J,D47)/F47 -> 0.90909091 | F47: =SUMIFS($G$2:$G$1000,$D$2:$D$1000,D47,$C$2:$C$1000,C47) -> 220 | G47: 10
B48: ATC | C48: eCommerce | D48: =VLOOKUP($B48,$R:$S,2,FALSE) -> Corporate | E48: =G48*SUMIFS($K:$K,$I:$I,C48,$J:$J,D48)/F48 -> 1.8181818 | F48: =SUMIFS($G$2:$G$1000,$D$2:$D$1000,D48,$C$2:$C$1000,C48) -> 220 | G48: 20
B49: AVC | C49: eCommerce | D49: =VLOOKUP($B49,$R:$S,2,FALSE) -> Corporate | E49: =G49*SUMIFS($K:$K,$I:$I,C49,$J:$J,D49)/F49 -> 0.90909091 | F49: =SUMIFS($G$2:$G$1000,$D$2:$D$1000,D49,$C$2:$C$1000,C49) -> 220 | G49: 10
B50: CF | C50: eCommerce | D50: =VLOOKUP($B50,$R:$S,2,FALSE) -> Corporate | E50: =G50*SUMIFS($K:$K,$I:$I,C50,$J:$J,D50)/F50 -> 1.8181818 | F50: =SUMIFS($G$2:$G$1000,$D$2:$D$1000,D50,$C$2:$C$1000,C50) -> 220 | G50: 20
B51: CFO | C51: eCommerce | D51: =VLOOKUP($B51,$R:$S,2,FALSE) -> Corporate | E51: =G51*SUMIFS($K:$K,$I:$I,C51,$J:$J,D51)/F51 -> 1.8181818 | F51: =SUMIFS($G$2:$G$1000,$D$2:$D$1000,D51,$C$2:$C$1000,C51) -> 220 | G51: 20
B52: CHR | C52: eCommerce | D52: =VLOOKUP($B52,$R:$S,2,FALSE) -> Corporate | E52: =G52*SUMIFS($K:$K,$I:$I,C52,$J:$J,D52)/F52 -> 0.90909091 | F52: =SUMIFS($G$2:$G$1000,$D$2:$D$1000,D52,$C$2:$C$1000,C52) -> 220 | G52: 10
B53: CL | C53: eCommerce | D53: =VLOOKUP($B53,$R:$S,2,FALSE) -> Corporate | E53: =G53*SUMIFS($K:$K,$I:$I,C53,$J:$J,D53)/F53 -> 0.90909091 | F53: =SUMIFS($G$2:$G$1000,$D$2:$D$1000,D53,$C$2:$C$1000,C53) -> 220 | G53: 10
B54: CMP | C54: eCommerce | D54: =VLOOKUP($B54,$R:$S,2,FALSE) -> Corporate | E54: =G54*SUMIFS($K:$K,$I:$I,C54,$J:$J,D54)/F54 -> 0.90909091 | F54: =SUMIFS($G$2:$G$1000,$D$2:$D$1000,D54,$C$2:$C$1000,C54) -> 220 | G54: 10
...

Sheet demand_resp&weights
A1: DEMAND 2025
A2: PORTUGAL | W2: ESPAÑA
A3: PRODUCTS | B3: 0.38 | E3: OPERATIONS | F3: 0.19 | I3: CORPORATE | J3: 0.19 | M3: TECHNOLOGY | N3: 0.19 | Q3: DAT | R3: 0.05 | W3: operations | X3: commercial | Y3: corporate | Z3: commercial | AA3: commercial | AB3: corporate | AC3: technology | AD3: corporate | AE3: corporate | AF3: corporate
A4: GP ECL | B4: 0.16 | E4: EDO | F4: 0.35 | I4: ACR | J4: 0.066666667 | M4: SI | N4: 0.3 | W4: COO | X4: CMO | Y4: ATC | Z4: CCO | AA4: IDC | AB4: CFO | AC4: CIO | AD4: PRO | AE4: CHR | AF4: COM
A5: GP B2B | B5: 0.16 | E5: SEO | F5: 0.35 | I5: CF | J5: 0.066666667 | M5: CISO | N5: 0.2 | W5: 0.2 | X5: 0.12 | Y5: 0.12 | Z5: 0.08 | AA5: 0.08 | AB5: 0.12 | AC5: 0.15 | AD5: 0.07 | AE5: 0.03 | AF5: 0.03
A6: DNI | B6: 0.16 | E6: EM | F6: 0.3 | I6: RS | J6: 0.066666667 | M6: BCTT | N6: 0.2
A7: GS | B7: 0.12 | I7: AVC | J7: 0.066666667 | M7: SI-PRD | N7: 0.1
A8: CSI | B8: 0.1 | I8: GRH | J8: 0.066666667 | M8: SI-OPS | N8: 0.1
A9: GP B2C | B9: 0.09 | I9: GT | J9: 0.066666667 | M9: SI-CRP | N9: 0.1
A10: CTTE | B10: 0.09 | I10: CL | J10: 0.066666667
A11: GPG | B11: 0.09 | I11: ED | J11: 0.066666667
A12: ECM | B12: 0.03 | I12: CMP | J12: 0.066666667
I13: ST | J13: 0.066666667
I14: GFC | J14: 0.066666667
I15: TF | J15: 0.066666667
I16: DPO | J16: 0.066666667
I17: SSJ | J17: 0.066666667
I18: FL | J18: 0.066666667
A20: DEMAND 2026
A21: eCOMMERCE | B21: =VLOOKUP(A21,refData!$N:$O,2,FALSE) -> 26 | C21: =(B23+F23+J23+N23+R23+V23)=100 -> TRUE
A22: check | B22: =B23=SUM(B24:B32) -> TRUE | E22: check | F22: =F23=SUM(F24:F32) -> TRUE | I22: check | J22: =J23=SUM(J24:J32) -> TRUE | M22: check | N22: =N23=SUM(N24:N32) -> TRUE | Q22: check | R22: =R23=SUM(R24:R32) -> TRUE | U22: check | V22: =V23=SUM(V24:V32) -> TRUE
A23: Commercial | B23: 25 | C23: =B23*($B$21/100) -> 6.5 | E23: Operations | F23: 25 | G23: =F23*($B$21/100) -> 6.5 | I23: Corporate | J23: 20 | K23: =J23*($B$21/100) -> 5.2 | M23: Technology | N23: 20 | O23: =N23*($B$21/100) -> 5.2 | Q23: Data & AI | R23: 5 | S23: =R23*($B$21/100) -> 1.3 | U23: CISO | V23: 5 | W23: =V23*($B$21/100) -> 1.3 | X23: 25
A24: CMO | B24: 4 | C24: =B24*($B$21/100) -> 1.04 | E24: COO | F24: 8 | G24: =F24*($B$21/100) -> 2.08 | I24: ATC | J24: 8 | K24: =J24*($B$21/100) -> 2.08 | M24: CIO | N24: 20 | O24: =N24*($B$21/100) -> 5.2 | Q24: DAI | R24: 5 | S24: =R24*($B$21/100) -> 1.3 | U24: CISO | V24: 5 | W24: =V24*($B$21/100) -> 1.3 | X24: 25
A25: CCO | B25: 4 | C25: =B25*($B$21/100) -> 1.04 | E25: EDO | F25: 8 | G25: =F25*($B$21/100) -> 2.08 | I25: CFO | J25: 8 | K25: =J25*($B$21/100) -> 2.08 | O25: =N25*($B$21/100) -> 0 | S25: =R25*($B$21/100) -> 0 | W25: =V25*($B$21/100) -> 0 | X25: 20
A26: IDC | B26: 4 | C26: =B26*($B$21/100) -> 1.04 | E26: SEO | F26: 8 | G26: =F26*($B$21/100) -> 2.08 | I26: PRO | J26: 2 | K26: =J26*($B$21/100) -> 0.52 | O26: =N26*($B$21/100) -> 0 | S26: =R26*($B$21/100) -> 0 | W26: =V26*($B$21/100) -> 0 | X26: 20
A27: GP ECL | B27: 5 | C27: =B27*($B$21/100) -> 1.3 | E27: EM | F27: 1 | G27: =F27*($B$21/100) -> 0.26 | I27: CHR | J27: 1 | K27: =J27*($B$21/100) -> 0.26 | O27: =N27*($B$21/100) -> 0 | S27: =R27*($B$21/100) -> 0 | W27: =V27*($B$21/100) -> 0 | X27: 5
A28: DNI | B28: 2 | C28: =B28*($B$21/100) -> 0.52 | G28: =F28*($B$21/100) -> 0 | I28: COM | J28: 1 | K28: =J28*($B$21/100) -> 0.26 | O28: =N28*($B$21/100) -> 0 | S28: =R28*($B$21/100) -> 0 | W28: =V28*($B$21/100) -> 0 | X28: 5
A29: GS | B29: 2 | C29: =B29*($B$21/100) -> 0.52 | G29: =F29*($B$21/100) -> 0 | K29: =J29*($B$21/100) -> 0 | O29: =N29*($B$21/100) -> 0 | S29: =R29*($B$21/100) -> 0 | W29: =V29*($B$21/100) -> 0
A30: CSI | B30: 2 | C30: =B30*($B$21/100) -> 0.52 | G30: =F30*($B$21/100) -> 0 | K30: =J30*($B$21/100) -> 0 | O30: =N30*($B$21/100) -> 0 | S30: =R30*($B$21/100) -> 0 | W30: =V30*($B$21/100) -> 0
A31: GP B2C | B31: 2 | C31: =B31*($B$21/100) -> 0.52 | G31: =F31*($B$21/100) -> 0 | K31: =J31*($B$21/100) -> 0 | O31: =N31*($B$21/100) -> 0 | S31: =R31*($B$21/100) -> 0 | W31: =V31*($B$21/100) -> 0
A34: MAIL | B34: =VLOOKUP(A34,refData!$N:$O,2,FALSE) -> 22 | C34: =(B36+F36+J36+N36+R36+V36)=100 -> TRUE
A35: check | B35: =B36=SUM(B37:B52) -> TRUE | E35: check | F35: =F36=SUM(F37:F52) -> TRUE | I35: check | J35: =J36=SUM(J37:J52) -> TRUE | M35: check | N35: =N36=SUM(N37:N52) -> TRUE | Q35: check | R35: =R36=SUM(R37:R52) -> TRUE | U35: check | V35: =V36=SUM(V37:V52) -> TRUE
A36: Commercial | B36: 25 | C36: =B36*($B$34/100) -> 5.5 | E36: Operations | F36: 25 | G36: =F36*($B$34/100) -> 5.5 | I36: Corporate | J36: 20 | K36: =J36*($B$34/100) -> 4.4 | M36: Technology | N36: 20 | O36: =N36*($B$34/100) -> 4.4 | Q36: Data & AI | R36: 5 | S36: =R36*($B$34/100) -> 1.1 | U36: CISO | V36: 5 | W36: =V36*($B$34/100) -> 1.1 | X36: 25
A37: GP B2B | B37: 5 | C37: =B37*($B$34/100) -> 1.1 | E37: EDO | F37: 10 | G37: =F37*($B$34/100) -> 2.2 | I37: ACR | J37: 2 | K37: =J37*($B$34/100) -> 0.44 | M37: SI | N37: 10 | O37: =N37*($B$34/100) -> 2.2 | Q37: DAI | R37: 5 | S37: =R37*($B$34/100) -> 1.1 | U37: CISO | V37: 5 | W37: =V37*($B$34/100) -> 1.1 | X37: 25
A38: DNI | B38: 5 | C38: =B38*($B$34/100) -> 1.1 | E38: SEO | F38: 10 | G38: =F38*($B$34/100) -> 2.2 | I38: CF | J38: 2 | K38: =J38*($B$34/100) -> 0.44 | M38: BCTT | N38: 10 | O38: =N38*($B$34/100) -> 2.2 | S38: =R38*($B$34/100) -> 0 | W38: =V38*($B$34/100) -> 0
A39: GS | B39: 5 | C39: =B39*($B$34/100) -> 1.1 | E39: EM | F39: 5 | G39: =F39*($B$34/100) -> 1.1 | I39: RS | J39: 1 | K39: =J39*($B$34/100) -> 0.22 | O39: =N39*($B$34/100) -> 0 | S39: =R39*($B$34/100) -> 0 | W39: =V39*($B$34/100) -> 0
A40: CSI | B40: 5 | C40: =B40*($B$34/100) -> 1.1 | G40: =F40*($B$34/100) -> 0 | I40: AVC | J40: 2 | K40: =J40*($B$34/100) -> 0.44 | O40: =N40*($B$34/100) -> 0 | S40: =R40*($B$34/100) -> 0 | W40: =V40*($B$34/100) -> 0
A41: GP B2C | B41: 5 | C41: =B41*($B$34/100) -> 1.1 | G41: =F41*($B$34/100) -> 0 | I41: GRH | J41: 2 | K41: =J41*($B$34/100) -> 0.44 | O41: =N41*($B$34/100) -> 0 | S41: =R41*($B$34/100) -> 0 | W41: =V41*($B$34/100) -> 0
C42: =B42*($B$34/100) -> 0 | G42: =F42*($B$34/100) -> 0 | I42: GT | J42: 2 | K42: =J42*($B$34/100) -> 0.44 | O42: =N42*($B$34/100) -> 0 | S42: =R42*($B$34/100) -> 0 | W42: =V42*($B$34/100) -> 0
C43: =B43*($B$34/100) -> 0 | G43: =F43*($B$34/100) -> 0 | I43: CL | J43: 1 | K43: =J43*($B$34/100) -> 0.22 | O43: =N43*($B$34/100) -> 0 | S43: =R43*($B$34/100) -> 0 | W43: =V43*($B$34/100) -> 0
...
