Workbook

Sheet tom_demand_setup - TO BE
B1: order | C1: EXPORT CSV | D1: WEIGHTS_RA | J1: Peso BG por RS | S1: EXPORT CSV | T1: WEIGHTS_RS | AD1: REF DATA | AG1: REF DATA
B2: # | C2: RequestingArea | D2: RevenueStream | E2: BudgetGroup | F2: Weight | G2: Weight-RS+BG | H2: Weight-Base | J2: RevenueStream | K2: BudgetGroup | L2: Target | M2: Check | N2: Count | O2: Check | P2: Weight | Q2: Check | S2: RevenueStream | T2: Weight | U2: Check | W2: {=_xlfn.UNIQUE(E2:E1000)} -> BudgetGroup | X2: Check | Z2: {=_xlfn.UNIQUE(C2:C1000)} -> RequestingArea | AA2: Check | AB2: hasBG? | AD2: RequestingArea | AE2: BudgetGroup | AG2: MicroPhase bmap | AH2: MicroPhase Macro | AI2: MicroPhase Demand
B3: 1 | C3: GP B2B | D3: Business Solutions | E3: =VLOOKUP($C3,$AD:$AE,2,FALSE) -> Commercial | F3: =H3*SUMIFS($H:$H,$J:$J,D3,$K:$K,E3)/G3 -> 0.1 | G3: =SUMIFS($H$2:$H$1000,$E$2:$E$1000,E3,$D$2:$D$1000,D3) -> 10 | H3: 1 | J3: eCommerce | K3: Operations | L3: =N3/O3*100 -> 9.5238095 | M3: =SUMIF($J:$J,J3,$L:$L) -> 100 | N3: =COUNTIFS(E:E,K3,D:D,J3) -> 4 | O3: =SUMIF($J:$J,J3,$N:$N) -> 42 | P3: =SUMIFS(F:F,E:E,K3,D:D,J3) -> 1 | Q3: =SUMIF($J:$J,N3,$N:$N) -> 0 | S3: eCommerce | T3: 40 | U3: =SUM(T3:T18) -> 100 | W3: Commercial | X3: =SUMIF($E:$E,W3,$F:$F) -> 6 | Z3: GP B2B | AA3: =SUMIF($C:$C,Z3,$F:$F) -> 0.64166667 | AB3: =VLOOKUP(Z3,$AD:$AE,2,FALSE) -> Commercial | AD3: CISO | AE3: CISO | AG3: IDEA > Backlog | AH3: {=_xlfn.TEXTSPLIT(AG3,">",)} -> IDEA | AI3: Backlog
B4: 2 | C4: SEO | D4: Business Solutions | E4: =VLOOKUP($C4,$AD:$AE,2,FALSE) -> Operations | F4: =H4*SUMIFS($H:$H,$J:$J,D4,$K:$K,E4)/G4 -> 0.33333333 | G4: =SUMIFS($H$2:$H$1000,$E$2:$E$1000,E4,$D$2:$D$1000,D4) -> 3 | H4: 1 | J4: eCommerce | K4: Commercial | L4: =N4/O4*100 -> 28.571429 | M4: =SUMIF($J:$J,J4,$L:$L) -> 100 | N4: =COUNTIFS(E:E,K4,D:D,J4) -> 12 | O4: =SUMIF($J:$J,J4,$N:$N) -> 42 | P4: =SUMIFS(F:F,E:E,K4,D:D,J4) -> 1 | Q4: =SUMIF($J:$J,N4,$N:$N) -> 0 | S4: Mail | T4: 22 | W4: Operations | X4: =SUMIF($E:$E,W4,$F:$F) -> 6 | Z4: SEO | AA4: =SUMIF($C:$C,Z4,$F:$F) -> 1.9166667 | AB4: =VLOOKUP(Z4,$AD:$AE,2,FALSE) -> Operations | AD4: CCO | AE4: Commercial | AG4: IDEA > Pitch | AH4: {=_xlfn.TEXTSPLIT(AG4,">",)} -> IDEA | AI4: Pitch
B5: 3 | C5: CF | D5: Business Solutions | E5: =VLOOKUP($C5,$AD:$AE,2,FALSE) -> Corporate | F5: =H5*SUMIFS($H:$H,$J:$J,D5,$K:$K,E5)/G5 -> 0.076923077 | G5: =SUMIFS($H$2:$H$1000,$E$2:$E$1000,E5,$D$2:$D$1000,D5) -> 13 | H5: 1 | J5: eCommerce | K5: Corporate | L5: =N5/O5*100 -> 42.857143 | M5: =SUMIF($J:$J,J5,$L:$L) -> 100 | N5: =COUNTIFS(E:E,K5,D:D,J5) -> 18 | O5: =SUMIF($J:$J,J5,$N:$N) -> 42 | P5: =SUMIFS(F:F,E:E,K5,D:D,J5) -> 1 | Q5: =SUMIF($J:$J,N5,$N:$N) -> 0 | S5: Business Solutions | T5: 16 | W5: Corporate | X5: =SUMIF($E:$E,W5,$F:$F) -> 6 | Z5: CF | AA5: =SUMIF($C:$C,Z5,$F:$F) -> 0.48824786 | AB5: =VLOOKUP(Z5,$AD:$AE,2,FALSE) -> Corporate | AD5: CMO | AE5: Commercial | AG5: IDEA > In Definition | AH5: {=_xlfn.TEXTSPLIT(AG5,">",)} -> IDEA | AI5: In Definition
B6: 4 | C6: SI | D6: Business Solutions | E6: =VLOOKUP($C6,$AD:$AE,2,FALSE) -> Technology | F6: =H6*SUMIFS($H:$H,$J:$J,D6,$K:$K,E6)/G6 -> 0.2 | G6: =SUMIFS($H$2:$H$1000,$E$2:$E$1000,E6,$D$2:$D$1000,D6) -> 5 | H6: 1 | J6: eCommerce | K6: Technology | L6: =N6/O6*100 -> 14.285714 | M6: =SUMIF($J:$J,J6,$L:$L) -> 100 | N6: =COUNTIFS(E:E,K6,D:D,J6) -> 6 | O6: =SUMIF($J:$J,J6,$N:$N) -> 42 | P6: =SUMIFS(F:F,E:E,K6,D:D,J6) -> 1 | Q6: =SUMIF($J:$J,N6,$N:$N) -> 0 | S6: Retail & Financial Services | T6: 10 | W6: Technology | X6: =SUMIF($E:$E,W6,$F:$F) -> 6 | Z6: SI | AA6: =SUMIF($C:$C,Z6,$F:$F) -> 1.1666667 | AB6: =VLOOKUP(Z6,$AD:$AE,2,FALSE) -> Technology | AD6: CSI | AE6: Commercial | AG6: SOLUTION > In Approval | AH6: {=_xlfn.TEXTSPLIT(AG6,">",)} -> SOLUTION | AI6: In Approval
B7: 5 | C7: CISO | D7: Business Solutions | E7: =VLOOKUP($C7,$AD:$AE,2,FALSE) -> CISO | F7: =H7*SUMIFS($H:$H,$J:$J,D7,$K:$K,E7)/G7 -> 1 | G7: =SUMIFS($H$2:$H$1000,$E$2:$E$1000,E7,$D$2:$D$1000,D7) -> 1 | H7: 1 | J7: eCommerce | K7: Data & AI | L7: =N7/O7*100 -> 2.3809524 | M7: =SUMIF($J:$J,J7,$L:$L) -> 100 | N7: =COUNTIFS(E:E,K7,D:D,J7) -> 1 | O7: =SUMIF($J:$J,J7,$N:$N) -> 42 | P7: =SUMIFS(F:F,E:E,K7,D:D,J7) -> 1 | Q7: =SUMIF($J:$J,N7,$N:$N) -> 0 | S7: Payments | T7: 8 | W7: CISO | X7: =SUMIF($E:$E,W7,$F:$F) -> 6 | Z7: CISO | AA7: =SUMIF($C:$C,Z7,$F:$F) -> 6 | AB7: =VLOOKUP(Z7,$AD:$AE,2,FALSE) -> CISO | AD7: CTTE | AE7: Commercial | AG7: SOLUTION > Ready for Approval | AH7: {=_xlfn.TEXTSPLIT(AG7,">",)} -> SOLUTION | AI7: Ready for Approval
B8: 6 | C8: IAD | D8: Business Solutions | E8: =VLOOKUP($C8,$AD:$AE,2,FALSE) -> Data & AI | F8: =H8*SUMIFS($H:$H,$J:$J,D8,$K:$K,E8)/G8 -> 1 | G8: =SUMIFS($H$2:$H$1000,$E$2:$E$1000,E8,$D$2:$D$1000,D8) -> 1 | H8: 1 | J8: eCommerce | K8: CISO | L8: =N8/O8*100 -> 2.3809524 | M8: =SUMIF($J:$J,J8,$L:$L) -> 100 | N8: =COUNTIFS(E:E,K8,D:D,J8) -> 1 | O8: =SUMIF($J:$J,J8,$N:$N) -> 42 | P8: =SUMIFS(F:F,E:E,K8,D:D,J8) -> 1 | Q8: =SUMIF($J:$J,N8,$N:$N) -> 0 | S8: Fulfilment | T8: 4 | W8: Data & AI | X8: =SUMIF($E:$E,W8,$F:$F) -> 6 | Z8: IAD | AA8: =SUMIF($C:$C,Z8,$F:$F) -> 5.1428571 | AB8: =VLOOKUP(Z8,$AD:$AE,2,FALSE) -> Data & AI | AD8: DNI | AE8: Commercial | AG8: IDEA > Ready for Solution | AH8: {=_xlfn.TEXTSPLIT(AG8,">",)} -> IDEA | AI8: Ready for Solution
B9: 7 | C9: GS | D9: Business Solutions | E9: =VLOOKUP($C9,$AD:$AE,2,FALSE) -> Commercial | F9: =H9*SUMIFS($H:$H,$J:$J,D9,$K:$K,E9)/G9 -> 0.1 | G9: =SUMIFS($H$2:$H$1000,$E$2:$E$1000,E9,$D$2:$D$1000,D9) -> 10 | H9: 1 | J9: Mail | K9: Commercial | L9: =N9/O9*100 -> 28.125 | M9: =SUMIF($J:$J,J9,$L:$L) -> 100 | N9: =COUNTIFS(E:E,K9,D:D,J9) -> 9 | O9: =SUMIF($J:$J,J9,$N:$N) -> 32 | P9: =SUMIFS(F:F,E:E,K9,D:D,J9) -> 1 | Q9: =SUMIF($J:$J,N9,$N:$N) -> 0 | S9: Banco CTT | T9: 0 | W9: 0 | X9: =SUMIF($E:$E,W9,$F:$F) -> 0 | Z9: GS | AA9: =SUMIF($C:$C,Z9,$F:$F) -> 0.64166667 | AB9: =VLOOKUP(Z9,$AD:$AE,2,FALSE) -> Commercial | AD9: ECM | AE9: Commercial | AG9: SOLUTION > High Level Design | AH9: {=_xlfn.TEXTSPLIT(AG9,">",)} -> SOLUTION | AI9: High Level Design
B10: 8 | C10: ACR | D10: Business Solutions | E10: =VLOOKUP($C10,$AD:$AE,2,FALSE) -> Corporate | F10: =H10*SUMIFS($H:$H,$J:$J,D10,$K:$K,E10)/G10 -> 0.076923077 | G10: =SUMIFS($H$2:$H$1000,$E$2:$E$1000,E10,$D$2:$D$1000,D10) -> 13 | H10: 1 | J10: Mail | K10: Operations | L10: =N10/O10*100 -> 9.375 | M10: =SUMIF($J:$J,J10,$L:$L) -> 100 | N10: =COUNTIFS(E:E,K10,D:D,J10) -> 3 | O10: =SUMIF($J:$J,J10,$N:$N) -> 32 | P10: =SUMIFS(F:F,E:E,K10,D:D,J10) -> 1 | Q10: =SUMIF($J:$J,N10,$N:$N) -> 0 | X10: =SUMIF($E:$E,W10,$F:$F) -> 0 | Z10: ACR | AA10: =SUMIF($C:$C,Z10,$F:$F) -> 0.48824786 | AB10: =VLOOKUP(Z10,$AD:$AE,2,FALSE) -> Corporate | AD10: GP B2B | AE10: Commercial | AG10: SOLUTION > Ready for Development | AH10: {=_xlfn.TEXTSPLIT(AG10,">",)} -> SOLUTION | AI10: Ready for Development
B11: 9 | C11: EDO | D11: Business Solutions | E11: =VLOOKUP($C11,$AD:$AE,2,FALSE) -> Operations | F11: =H11*SUMIFS($H:$H,$J:$J,D11,$K:$K,E11)/G11 -> 0.33333333 | G11: =SUMIFS($H$2:$H$1000,$E$2:$E$1000,E11,$D$2:$D$1000,D11) -> 3 | H11: 1 | J11: Mail | K11: Corporate | L11: =N11/O11*100 -> 40.625 | M11: =SUMIF($J:$J,J11,$L:$L) -> 100 | N11: =COUNTIFS(E:E,K11,D:D,J11) -> 13 | O11: =SUMIF($J:$J,J11,$N:$N) -> 32 | P11: =SUMIFS(F:F,E:E,K11,D:D,J11) -> 1 | Q11: =SUMIF($J:$J,N11,$N:$N) -> 0 | X11: =SUMIF($E:$E,W11,$F:$F) -> 0 | Z11: EDO | AA11: =SUMIF($C:$C,Z11,$F:$F) -> 1.9166667 | AB11: =VLOOKUP(Z11,$AD:$AE,2,FALSE) -> Operations | AD11: GP B2C | AE11: Commercial | AG11: SOLUTION > In Definition | AH11: {=_xlfn.TEXTSPLIT(AG11,">",)} -> SOLUTION | AI11: In Definition
B12: 10 | C12: SI-OPS | D12: Business Solutions | E12: =VLOOKUP($C12,$AD:$AE,2,FALSE) -> Technology | F12: =H12*SUMIFS($H:$H,$J:$J,D12,$K:$K,E12)/G12 -> 0.2 | G12: =SUMIFS($H$2:$H$1000,$E$2:$E$1000,E12,$D$2:$D$1000,D12) -> 5 | H12: 1 | J12: Mail | K12: Technology | L12: =N12/O12*100 -> 15.625 | M12: =SUMIF($J:$J,J12,$L:$L) -> 100 | N12: =COUNTIFS(E:E,K12,D:D,J12) -> 5 | O12: =SUMIF($J:$J,J12,$N:$N) -> 32 | P12: =SUMIFS(F:F,E:E,K12,D:D,J12) -> 1 | Q12: =SUMIF($J:$J,N12,$N:$N) -> 0 | X12: =SUMIF($E:$E,W12,$F:$F) -> 0 | Z12: SI-OPS | AA12: =SUMIF($C:$C,Z12,$F:$F) -> 1.1666667 | AB12: =VLOOKUP(Z12,$AD:$AE,2,FALSE) -> Technology | AD12: GP ECL | AE12: Commercial
B13: 11 | C13: DNI | D13: Business Solutions | E13: =VLOOKUP($C13,$AD:$AE,2,FALSE) -> Commercial | F13: =H13*SUMIFS($H:$H,$J:$J,D13,$K:$K,E13)/G13 -> 0.1 | G13: =SUMIFS($H$2:$H$1000,$E$2:$E$1000,E13,$D$2:$D$1000,D13) -> 10 | H13: 1 | J13: Mail | K13: Data & AI | L13: =N13/O13*100 -> 3.125 | M13: =SUMIF($J:$J,J13,$L:$L) -> 100 | N13: =COUNTIFS(E:E,K13,D:D,J13) -> 1 | O13: =SUMIF($J:$J,J13,$N:$N) -> 32 | P13: =SUMIFS(F:F,E:E,K13,D:D,J13) -> 1 | Q13: =SUMIF($J:$J,N13,$N:$N) -> 0 | X13: =SUMIF($E:$E,W13,$F:$F) -> 0 | Z13: DNI | AA13: =SUMIF($C:$C,Z13,$F:$F) -> 0.64166667 | AB13: =VLOOKUP(Z13,$AD:$AE,2,FALSE) -> Commercial | AD13: GPG | AE13: Commercial
B14: 12 | C14: AVC | D14: Business Solutions | E14: =VLOOKUP($C14,$AD:$AE,2,FALSE) -> Corporate | F14: =H14*SUMIFS($H:$H,$J:$J,D14,$K:$K,E14)/G14 -> 0.076923077 | G14: =SUMIFS($H$2:$H$1000,$E$2:$E$1000,E14,$D$2:$D$1000,D14) -> 13 | H14: 1 | J14: Mail | K14: CISO | L14: =N14/O14*100 -> 3.125 | M14: =SUMIF($J:$J,J14,$L:$L) -> 100 | N14: =COUNTIFS(E:E,K14,D:D,J14) -> 1 | O14: =SUMIF($J:$J,J14,$N:$N) -> 32 | P14: =SUMIFS(F:F,E:E,K14,D:D,J14) -> 1 | Q14: =SUMIF($J:$J,N14,$N:$N) -> 0 | X14: =SUMIF($E:$E,W14,$F:$F) -> 0 | Z14: AVC | AA14: =SUMIF($C:$C,Z14,$F:$F) -> 0.48824786 | AB14: =VLOOKUP(Z14,$AD:$AE,2,FALSE) -> Corporate | AD14: GS | AE14: Commercial
B15: 13 | C15: EM | D15: Business Solutions | E15: =VLOOKUP($C15,$AD:$AE,2,FALSE) -> Operations | F15: =H15*SUMIFS($H:$H,$J:$J,D15,$K:$K,E15)/G15 -> 0.33333333 | G15: =SUMIFS($H$2:$H$1000,$E$2:$E$1000,E15,$D$2:$D$1000,D15) -> 3 | H15: 1 | J15: Business Solutions | K15: Commercial | L15: =N15/O15*100 -> 30.30303 | M15: =SUMIF($J:$J,J15,$L:$L) -> 100 | N15: =COUNTIFS(E:E,K15,D:D,J15) -> 10 | O15: =SUMIF($J:$J,J15,$N:$N) -> 33 | P15: =SUMIFS(F:F,E:E,K15,D:D,J15) -> 1 | Q15: =SUMIF($J:$J,N15,$N:$N) -> 0 | Z15: EM | AA15: =SUMIF($C:$C,Z15,$F:$F) -> 1.9166667 | AB15: =VLOOKUP(Z15,$AD:$AE,2,FALSE) -> Operations | AD15: IDC | AE15: Commercial
B16: 14 | C16: SI-PRD | D16: Business Solutions | E16: =VLOOKUP($C16,$AD:$AE,2,FALSE) -> Technology | F16: =H16*SUMIFS($H:$H,$J:$J,D16,$K:$K,E16)/G16 -> 0.2 | G16: =SUMIFS($H$2:$H$1000,$E$2:$E$1000,E16,$D$2:$D$1000,D16) -> 5 | H16: 1 | J16: Business Solutions | K16: Operations | L16: =N16/O16*100 -> 9.0909091 | M16: =SUMIF($J:$J,J16,$L:$L) -> 100 | N16: =COUNTIFS(E:E,K16,D:D,J16) -> 3 | O16: =SUMIF($J:$J,J16,$N:$N) -> 33 | P16: =SUMIFS(F:F,E:E,K16,D:D,J16) -> 1 | Q16: =SUMIF($J:$J,N16,$N:$N) -> 0 | Z16: SI-PRD | AA16: =SUMIF($C:$C,Z16,$F:$F) -> 1.1666667 | AB16: =VLOOKUP(Z16,$AD:$AE,2,FALSE) -> Technology | AD16: ACR | AE16: Corporate
B17: 15 | C17: CSI | D17: Business Solutions | E17: =VLOOKUP($C17,$AD:$AE,2,FALSE) -> Commercial | F17: =H17*SUMIFS($H:$H,$J:$J,D17,$K:$K,E17)/G17 -> 0.1 | G17: =SUMIFS($H$2:$H$1000,$E$2:$E$1000,E17,$D$2:$D$1000,D17) -> 10 | H17: 1 | J17: Business Solutions | K17: Corporate | L17: =N17/O17*100 -> 39.393939 | M17: =SUMIF($J:$J,J17,$L:$L) -> 100 | N17: =COUNTIFS(E:E,K17,D:D,J17) -> 13 | O17: =SUMIF($J:$J,J17,$N:$N) -> 33 | P17: =SUMIFS(F:F,E:E,K17,D:D,J17) -> 1 | Q17: =SUMIF($J:$J,N17,$N:$N) -> 0 | Z17: CSI | AA17: =SUMIF($C:$C,Z17,$F:$F) -> 0.64166667 | AB17: =VLOOKUP(Z17,$AD:$AE,2,FALSE) -> Commercial | AD17: ATC | AE17: Corporate
B18: 16 | C18: GT | D18: Business Solutions | E18: =VLOOKUP($C18,$AD:$AE,2,FALSE) -> Corporate | F18: =H18*SUMIFS($H:$H,$J:$J,D18,$K:$K,E18)/G18 -> 0.076923077 | G18: =SUMIFS($H$2:$H$1000,$E$2:$E$1000,E18,$D$2:$D$1000,D18) -> 13 | H18: 1 | J18: Business Solutions | K18: Technology | L18: =N18/O18*100 -> 15.151515 | M18: =SUMIF($J:$J,J18,$L:$L) -> 100 | N18: =COUNTIFS(E:E,K18,D:D,J18) -> 5 | O18: =SUMIF($J:$J,J18,$N:$N) -> 33 | P18: =SUMIFS(F:F,E:E,K18,D:D,J18) -> 1 | Q18: =SUMIF($J:$J,N18,$N:$N) -> 0 | Z18: GT | AA18: =SUMIF($C:$C,Z18,$F:$F) -> 0.48824786 | AB18: =VLOOKUP(Z18,$AD:$AE,2,FALSE) -> Corporate | AD18: AVC | AE18: Corporate
B19: 17 | C19: BCTT | D19: Business Solutions | E19: =VLOOKUP($C19,$AD:$AE,2,FALSE) -> Technology | F19: =H19*SUMIFS($H:$H,$J:$J,D19,$K:$K,E19)/G19 -> 0.2 | G19: =SUMIFS($H$2:$H$1000,$E$2:$E$1000,E19,$D$2:$D$1000,D19) -> 5 | H19: 1 | J19: Business Solutions | K19: Data & AI | L19: =N19/O19*100 -> 3.030303 | M19: =SUMIF($J:$J,J19,$L:$L) -> 100 | N19: =COUNTIFS(E:E,K19,D:D,J19) -> 1 | O19: =SUMIF($J:$J,J19,$N:$N) -> 33 | P19: =SUMIFS(F:F,E:E,K19,D:D,J19) -> 1 | Q19: =SUMIF($J:$J,N19,$N:$N) -> 0 | Z19: BCTT | AA19: =SUMIF($C:$C,Z19,$F:$F) -> 1.1666667 | AB19: =VLOOKUP(Z19,$AD:$AE,2,FALSE) -> Technology | AD19: CF | AE19: Corporate
B20: 18 | C20: GP B2C | D20: Business Solutions | E20: =VLOOKUP($C20,$AD:$AE,2,FALSE) -> Commercial | F20: =H20*SUMIFS($H:$H,$J:$J,D20,$K:$K,E20)/G20 -> 0.1 | G20: =SUMIFS($H$2:$H$1000,$E$2:$E$1000,E20,$D$2:$D$1000,D20) -> 10 | H20: 1 | J20: Business Solutions | K20: CISO | L20: =N20/O20*100 -> 3.030303 | M20: =SUMIF($J:$J,J20,$L:$L) -> 100 | N20: =COUNTIFS(E:E,K20,D:D,J20) -> 1 | O20: =SUMIF($J:$J,J20,$N:$N) -> 33 | P20: =SUMIFS(F:F,E:E,K20,D:D,J20) -> 1 | Q20: =SUMIF($J:$J,N20,$N:$N) -> 0 | Z20: GP B2C | AA20: =SUMIF($C:$C,Z20,$F:$F) -> 0.64166667 | AB20: =VLOOKUP(Z20,$AD:$AE,2,FALSE) -> Commercial | AD20: CFO | AE20: Corporate
B21: 19 | C21: GRH | D21: Business Solutions | E21: =VLOOKUP($C21,$AD:$AE,2,FALSE) -> Corporate | F21: =H21*SUMIFS($H:$H,$J:$J,D21,$K:$K,E21)/G21 -> 0.076923077 | G21: =SUMIFS($H$2:$H$1000,$E$2:$E$1000,E21,$D$2:$D$1000,D21) -> 13 | H21: 1 | J21: Retail & Financial Services | K21: Commercial | L21: =N21/O21*100 -> 25 | M21: =SUMIF($J:$J,J21,$L:$L) -> 100 | N21: =COUNTIFS(E:E,K21,D:D,J21) -> 8 | O21: =SUMIF($J:$J,J21,$N:$N) -> 32 | P21: =SUMIFS(F:F,E:E,K21,D:D,J21) -> 1 | Q21: =SUMIF($J:$J,N21,$N:$N) -> 0 | Z21: GRH | AA21: =SUMIF($C:$C,Z21,$F:$F) -> 0.48824786 | AB21: =VLOOKUP(Z21,$AD:$AE,2,FALSE) -> Corporate | AD21: CHR | AE21: Corporate
B22: 20 | C22: SI-CRP | D22: Business Solutions | E22: =VLOOKUP($C22,$AD:$AE,2,FALSE) -> Technology | F22: =H22*SUMIFS($H:$H,$J:$J,D22,$K:$K,E22)/G22 -> 0.2 | G22: =SUMIFS($H$2:$H$1000,$E$2:$E$1000,E22,$D$2:$D$1000,D22) -> 5 | H22: 1 | J22: Retail & Financial Services | K22: Operations | L22: =N22/O22*100 -> 9.375 | M22: =SUMIF($J:$J,J22,$L:$L) -> 100 | N22: =COUNTIFS(E:E,K22,D:D,J22) -> 3 | O22: =SUMIF($J:$J,J22,$N:$N) -> 32 | P22: =SUMIFS(F:F,E:E,K22,D:D,J22) -> 1 | Q22: =SUMIF($J:$J,N22,$N:$N) -> 0 | Z22: SI-CRP | AA22: =SUMIF($C:$C,Z22,$F:$F) -> 1.1666667 | AB22: =VLOOKUP(Z22,$AD:$AE,2,FALSE) -> Technology | AD22: CL | AE22: Corporate
B23: 21 | C23: GP ECL | D23: Business Solutions | E23: =VLOOKUP($C23,$AD:$AE,2,FALSE) -> Commercial | F23: =H23*SUMIFS($H:$H,$J:$J,D23,$K:$K,E23)/G23 -> 0.1 | G23: =SUMIFS($H$2:$H$1000,$E$2:$E$1000,E23,$D$2:$D$1000,D23) -> 10 | H23: 1 | J23: Retail & Financial Services | K23: Corporate | L23: =N23/O23*100 -> 25 | M23: =SUMIF($J:$J,J23,$L:$L) -> 100 | N23: =COUNTIFS(E:E,K23,D:D,J23) -> 8 | O23: =SUMIF($J:$J,J23,$N:$N) -> 32 | P23: =SUMIFS(F:F,E:E,K23,D:D,J23) -> 1 | Q23: =SUMIF($J:$J,N23,$N:$N) -> 0 | Z23: GP ECL | AA23: =SUMIF($C:$C,Z23,$F:$F) -> 0.64166667 | AB23: =VLOOKUP(Z23,$AD:$AE,2,FALSE) -> Commercial | AD23: CMP | AE23: Corporate
B24: 22 | C24: PC | D24: Business Solutions | E24: =VLOOKUP($C24,$AD:$AE,2,FALSE) -> Corporate | F24: =H24*SUMIFS($H:$H,$J:$J,D24,$K:$K,E24)/G24 -> 0.076923077 | G24: =SUMIFS($H$2:$H$1000,$E$2:$E$1000,E24,$D$2:$D$1000,D24) -> 13 | H24: 1 | J24: Retail & Financial Services | K24: Technology | L24: =N24/O24*100 -> 15.625 | M24: =SUMIF($J:$J,J24,$L:$L) -> 100 | N24: =COUNTIFS(E:E,K24,D:D,J24) -> 5 | O24: =SUMIF($J:$J,J24,$N:$N) -> 32 | P24: =SUMIFS(F:F,E:E,K24,D:D,J24) -> 1 | Q24: =SUMIF($J:$J,N24,$N:$N) -> 0 | Z24: PC | AA24: =SUMIF($C:$C,Z24,$F:$F) -> 0.48824786 | AB24: =VLOOKUP(Z24,$AD:$AE,2,FALSE) -> Corporate | AD24: COM | AE24: Corporate
B25: 23 | C25: GPG | D25: Business Solutions | E25: =VLOOKUP($C25,$AD:$AE,2,FALSE) -> Commercial | F25: =H25*SUMIFS($H:$H,$J:$J,D25,$K:$K,E25)/G25 -> 0.1 | G25: =SUMIFS($H$2:$H$1000,$E$2:$E$1000,E25,$D$2:$D$1000,D25) -> 10 | H25: 1 | J25: Retail & Financial Services | K25: Data & AI | L25: =N25/O25*100 -> 21.875 | M25: =SUMIF($J:$J,J25,$L:$L) -> 100 | N25: =COUNTIFS(E:E,K25,D:D,J25) -> 7 | O25: =SUMIF($J:$J,J25,$N:$N) -> 32 | P25: =SUMIFS(F:F,E:E,K25,D:D,J25) -> 1 | Q25: =SUMIF($J:$J,N25,$N:$N) -> 0 | Z25: GPG | AA25: =SUMIF($C:$C,Z25,$F:$F) -> 0.64166667 | AB25: =VLOOKUP(Z25,$AD:$AE,2,FALSE) -> Commercial | AD25: DPO | AE25: Corporate
B26: 24 | C26: RS | D26: Business Solutions | E26: =VLOOKUP($C26,$AD:$AE,2,FALSE) -> Corporate | F26: =H26*SUMIFS($H:$H,$J:$J,D26,$K:$K,E26)/G26 -> 0.076923077 | G26: =SUMIFS($H$2:$H$1000,$E$2:$E$1000,E26,$D$2:$D$1000,D26) -> 13 | H26: 1 | J26: Retail & Financial Services | K26: CISO | L26: =N26/O26*100 -> 3.125 | M26: =SUMIF($J:$J,J26,$L:$L) -> 100 | N26: =COUNTIFS(E:E,K26,D:D,J26) -> 1 | O26: =SUMIF($J:$J,J26,$N:$N) -> 32 | P26: =SUMIFS(F:F,E:E,K26,D:D,J26) -> 1 | Q26: =SUMIF($J:$J,N26,$N:$N) -> 0 | Z26: RS | AA26: =SUMIF($C:$C,Z26,$F:$F) -> 0.48824786 | AB26: =VLOOKUP(Z26,$AD:$AE,2,FALSE) -> Corporate | AD26: FL | AE26: Corporate
... B38: 3 | C38: ATC | D38: eCommerce | E38: =VLOOKUP($C38,$AD:$AE,2,FALSE) -> Corporate | F38: =H38*SUMIFS($H:$H,$J:$J,D38,$K:$K,E38)/G38 -> 0.055555556 | G38: =SUMIFS($H$2:$H$1000,$E$2:$E$1000,E38,$D$2:$D$1000,D38) -> 18 | H38: 1 | J38: Fulfilment | K38: CISO | L38: =N38/O38*100 -> 3.125 | M38: =SUMIF($J:$J,J38,$L:$L) -> 100 | N38: =COUNTIFS(E:E,K38,D:D,J38) -> 1 | O38: =SUMIF($J:$J,J38,$N:$N) -> 32 | P38: =SUMIFS(F:F,E:E,K38,D:D,J38) -> 1 | Q38: =SUMIF($J:$J,N38,$N:$N) -> 0 | Z38: ATC | AA38: =SUMIF($C:$C,Z38,$F:$F) -> 0.055555556 | AB38: =VLOOKUP(Z38,$AD:$AE,2,FALSE) -> Corporate | AD38: SEO | AE38: Operations
B39: 4 | C39: CCO | D39: eCommerce | E39: =VLOOKUP($C39,$AD:$AE,2,FALSE) -> Commercial | F39: =H39*SUMIFS($H:$H,$J:$J,D39,$K:$K,E39)/G39 -> 0.083333333 | G39: =SUMIFS($H$2:$H$1000,$E$2:$E$1000,E39,$D$2:$D$1000,D39) -> 12 | H39: 1 | J39: Mail & Services | K39: Commercial | L39: 38 | Z39: CCO | AA39: =SUMIF($C:$C,Z39,$F:$F) -> 0.083333333 | AB39: =VLOOKUP(Z39,$AD:$AE,2,FALSE) -> Commercial | AD39: BCTT | AE39: Technology
B40: 5 | C40: IDC | D40: eCommerce | E40: =VLOOKUP($C40,$AD:$AE,2,FALSE) -> Commercial | F40: =H40*SUMIFS($H:$H,$J:$J,D40,$K:$K,E40)/G40 -> 0.083333333 | G40: =SUMIFS($H$2:$H$1000,$E$2:$E$1000,E40,$D$2:$D$1000,D40) -> 12 | H40: 1 | J40: Mail & Services | K40: Operations | L40: 19 | Z40: IDC | AA40: =SUMIF($C:$C,Z40,$F:$F) -> 0.083333333 | AB40: =VLOOKUP(Z40,$AD:$AE,2,FALSE) -> Commercial | AD40: CIO | AE40: Technology
B41: 6 | C41: CFO | D41: eCommerce | E41: =VLOOKUP($C41,$AD:$AE,2,FALSE) -> Corporate | F41: =H41*SUMIFS($H:$H,$J:$J,D41,$K:$K,E41)/G41 -> 0.055555556 | G41: =SUMIFS($H$2:$H$1000,$E$2:$E$1000,E41,$D$2:$D$1000,D41) -> 18 | H41: 1 | J41: Mail & Services | K41: Corporate | L41: 19 | Z41: CFO | AA41: =SUMIF($C:$C,Z41,$F:$F) -> 0.055555556 | AB41: =VLOOKUP(Z41,$AD:$AE,2,FALSE) -> Corporate | AD41: SI | AE41: Technology
B42: 7 | C42: CIO | D42: eCommerce | E42: =VLOOKUP($C42,$AD:$AE,2,FALSE) -> Technology | F42: =H42*SUMIFS($H:$H,$J:$J,D42,$K:$K,E42)/G42 -> 0.16666667 | G42: =SUMIFS($H$2:$H$1000,$E$2:$E$1000,E42,$D$2:$D$1000,D42) -> 6 | H42: 1 | J42: Mail & Services | K42: Technology | L42: 17 | Z42: CIO | AA42: =SUMIF($C:$C,Z42,$F:$F) -> 0.16666667 | AB42: =VLOOKUP(Z42,$AD:$AE,2,FALSE) -> Technology | AD42: SI-CRP | AE42: Technology
B43: 8 | C43: PRO | D43: eCommerce | E43: =VLOOKUP($C43,$AD:$AE,2,FALSE) -> Corporate | F43: =H43*SUMIFS($H:$H,$J:$J,D43,$K:$K,E43)/G43 -> 0.055555556 | G43: =SUMIFS($H$2:$H$1000,$E$2:$E$1000,E43,$D$2:$D$1000,D43) -> 18 | H43: 1 | J43: Mail & Services | K43: Data & AI | L43: 5 | Z43: PRO | AA43: =SUMIF($C:$C,Z43,$F:$F) -> 0.055555556 | AB43: =VLOOKUP(Z43,$AD:$AE,2,FALSE) -> Corporate | AD43: SI-OPS | AE43: Technology
B44: 9 | C44: CHR | D44: eCommerce | E44: =VLOOKUP($C44,$AD:$AE,2,FALSE) -> Corporate | F44: =H44*SUMIFS($H:$H,$J:$J,D44,$K:$K,E44)/G44 -> 0.055555556 | G44: =SUMIFS($H$2:$H$1000,$E$2:$E$1000,E44,$D$2:$D$1000,D44) -> 18 | H44: 1 | J44: Mail & Services | K44: CISO | L44: 2 | Z44: CHR | AA44: =SUMIF($C:$C,Z44,$F:$F) -> 0.055555556 | AB44: =VLOOKUP(Z44,$AD:$AE,2,FALSE) -> Corporate | AD44: SI-PRD | AE44: Technology
B45: 11 | C45: GP ECL | D45: eCommerce | E45: =VLOOKUP($C45,$AD:$AE,2,FALSE) -> Commercial | F45: =H45*SUMIFS($H:$H,$J:$J,D45,$K:$K,E45)/G45 -> 0.083333333 | G45: =SUMIFS($H$2:$H$1000,$E$2:$E$1000,E45,$D$2:$D$1000,D45) -> 12 | H45: 1 | Z45: COM | AD45: IAD | AE45: Data & AI
B46: 12 | C46: CISO | D46: eCommerce | E46: =VLOOKUP($C46,$AD:$AE,2,FALSE) -> CISO | F46: =H46*SUMIFS($H:$H,$J:$J,D46,$K:$K,E46)/G46 -> 1 | G46: =SUMIFS($H$2:$H$1000,$E$2:$E$1000,E46,$D$2:$D$1000,D46) -> 1 | H46: 1 | Z46: 0 | AD46: NSP | AE46: Commercial
B47: 13 | C47: IAD | D47: eCommerce | E47: =VLOOKUP($C47,$AD:$AE,2,FALSE) -> Data & AI | F47: =H47*SUMIFS($H:$H,$J:$J,D47,$K:$K,E47)/G47 -> 1 | G47: =SUMIFS($H$2:$H$1000,$E$2:$E$1000,E47,$D$2:$D$1000,D47) -> 1 | H47: 1
B48: 14 | C48: GS | D48: eCommerce | E48: =VLOOKUP($C48,$AD:$AE,2,FALSE) -> Commercial | F48: =H48*SUMIFS($H:$H,$J:$J,D48,$K:$K,E48)/G48 -> 0.083333333 | G48: =SUMIFS($H$2:$H$1000,$E$2:$E$1000,E48,$D$2:$D$1000,D48) -> 12 | H48: 1
B49: 15 | C49: EDO | D49: eCommerce | E49: =VLOOKUP($C49,$AD:$AE,2,FALSE) -> Operations | F49: =H49*SUMIFS($H:$H,$J:$J,D49,$K:$K,E49)/G49 -> 0.25 | G49: =SUMIFS($H$2:$H$1000,$E$2:$E$1000,E49,$D$2:$D$1000,D49) -> 4 | H49: 1
B50: 16 | C50: ACR | D50: eCommerce | E50: =VLOOKUP($C50,$AD:$AE,2,FALSE) -> Corporate | F50: =H50*SUMIFS($H:$H,$J:$J,D50,$K:$K,E50)/G50 -> 0.055555556 | G50: =SUMIFS($H$2:$H$1000,$E$2:$E$1000,E50,$D$2:$D$1000,D50) -> 18 | H50: 1
B51: 17 | C51: SI | D51: eCommerce | E51: =VLOOKUP($C51,$AD:$AE,2,FALSE) -> Technology | F51: =H51*SUMIFS($H:$H,$J:$J,D51,$K:$K,E51)/G51 -> 0.16666667 | G51: =SUMIFS($H$2:$H$1000,$E$2:$E$1000,E51,$D$2:$D$1000,D51) -> 6 | H51: 1
...

Sheet tom_demand_setup - ATUAL
B1: EXPORT CSV | C1: WEIGHTS_RS | D1: =SUM(C3:C18) -> 100 | F1: EXPORT CSV | G1: WEIGHTS_RS_BG | K1: order | L1: EXPORT CSV | M1: WEIGHTS_RA | O1: =SUBTOTAL(9,O2:O1000) -> #REF! | Y1: REF DATA | AC1: REF DATA
B2: RevenueStream | C2: Weight | D2: Check | F2: RevenueStream | G2: BudgetGroup | H2: Weight | I2: Check | K2: # | L2: RequestingArea | M2: RevenueStream | N2: BudgetGroup | O2: Weight | P2: Weight-Base | R2: {=_xlfn.UNIQUE(N2:N1003)} -> BudgetGroup | S2: Check | U2: {=_xlfn.UNIQUE(L2:L1003)} -> RequestingArea | V2: Check | W2: hasBG? | Y2: RequestingArea | Z2: BudgetGroup | AA2: BusinessGroup | AC2: MicroPhase bmap | AD2: MicroPhase Macro | AE2: MicroPhase Demand
B3: eCommerce | C3: 50 | F3: eCommerce | G3: Operations | H3: 25 | I3: =SUMIF($F:$F,F3,$H:$H) -> 100 | K3: 1 | L3: GP B2B | M3: Business Solutions | N3: =VLOOKUP($L3,$Y:$Z,2,FALSE) -> Commercial | O3: =P3*SUMIFS($P:$P,$F:$F,M3,$G:$G,N3)/#REF! -> #REF! | P3: 1 | R3: Commercial | S3: =SUMIF($N:$N,R3,$O:$O) -> #REF! | U3: GP B2B | V3: =SUMIF($L:$L,U3,$O:$O) -> #REF! | W3: =VLOOKUP(U3,$Y:$Z,2,FALSE) -> Commercial | Y3: CISO | Z3: CISO | AC3: IDEA > Backlog | AD3: {=_xlfn.TEXTSPLIT(AC3,">",)} -> IDEA | AE3: Backlog
B4: Mail & Services | C4: 50 | F4: eCommerce | G4: Commercial | H4: 25 | I4: =SUMIF($F:$F,F4,$H:$H) -> 100 | K4: 2 | L4: SEO | M4: Business Solutions | N4: =VLOOKUP($L4,$Y:$Z,2,FALSE) -> Operations | O4: =P4*SUMIFS($P:$P,$F:$F,M4,$G:$G,N4)/#REF! -> #REF! | P4: 1 | R4: Operations | S4: =SUMIF($N:$N,R4,$O:$O) -> #REF! | U4: SEO | V4: =SUMIF($L:$L,U4,$O:$O) -> #REF! | W4: =VLOOKUP(U4,$Y:$Z,2,FALSE) -> Operations | Y4: CCO | Z4: Commercial | AC4: IDEA > Pitch | AD4: {=_xlfn.TEXTSPLIT(AC4,">",)} -> IDEA | AE4: Pitch
F5: eCommerce | G5: Corporate | H5: 20 | I5: =SUMIF($F:$F,F5,$H:$H) -> 100 | K5: 3 | L5: CF | M5: Business Solutions | N5: =VLOOKUP($L5,$Y:$Z,2,FALSE) -> Corporate | O5: =P5*SUMIFS($P:$P,$F:$F,M5,$G:$G,N5)/#REF! -> #REF! | P5: 1 | R5: Corporate | S5: =SUMIF($N:$N,R5,$O:$O) -> #REF! | U5: CF | V5: =SUMIF($L:$L,U5,$O:$O) -> #REF! | W5: =VLOOKUP(U5,$Y:$Z,2,FALSE) -> Corporate | Y5: CMO | Z5: Commercial | AC5: IDEA > In Definition | AD5: {=_xlfn.TEXTSPLIT(AC5,">",)} -> IDEA | AE5: In Definition
F6: eCommerce | G6: Technology | H6: 20 | I6: =SUMIF($F:$F,F6,$H:$H) -> 100 | K6: 4 | L6: SI | M6: Business Solutions | N6: =VLOOKUP($L6,$Y:$Z,2,FALSE) -> Technology | O6: =P6*SUMIFS($P:$P,$F:$F,M6,$G:$G,N6)/#REF! -> #REF! | P6: 1 | R6: Technology | S6: =SUMIF($N:$N,R6,$O:$O) -> #REF! | U6: SI | V6: =SUMIF($L:$L,U6,$O:$O) -> #REF! | W6: =VLOOKUP(U6,$Y:$Z,2,FALSE) -> Technology | Y6: CSI | Z6: Commercial | AC6: SOLUTION > In Approval | AD6: {=_xlfn.TEXTSPLIT(AC6,">",)} -> SOLUTION | AE6: In Approval
F7: eCommerce | G7: Data & AI | H7: 5 | I7: =SUMIF($F:$F,F7,$H:$H) -> 100 | K7: 5 | L7: CISO | M7: Business Solutions | N7: =VLOOKUP($L7,$Y:$Z,2,FALSE) -> CISO | O7: =P7*SUMIFS($P:$P,$F:$F,M7,$G:$G,N7)/#REF! -> #REF! | P7: 1 | R7: CISO | S7: =SUMIF($N:$N,R7,$O:$O) -> #REF! | U7: CISO | V7: =SUMIF($L:$L,U7,$O:$O) -> #REF! | W7: =VLOOKUP(U7,$Y:$Z,2,FALSE) -> CISO | Y7: CTTE | Z7: Commercial | AC7: SOLUTION > Ready for Approval | AD7: {=_xlfn.TEXTSPLIT(AC7,">",)} -> SOLUTION | AE7: Ready for Approval
F8: eCommerce | G8: CISO | H8: 5 | I8: =SUMIF($F:$F,F8,$H:$H) -> 100 | K8: 6 | L8: IAD | M8: Business Solutions | N8: =VLOOKUP($L8,$Y:$Z,2,FALSE) -> Data & AI | O8: =P8*SUMIFS($P:$P,$F:$F,M8,$G:$G,N8)/#REF! -> #REF! | P8: 1 | R8: Data & AI | S8: =SUMIF($N:$N,R8,$O:$O) -> #REF! | U8: IAD | V8: =SUMIF($L:$L,U8,$O:$O) -> #REF! | W8: =VLOOKUP(U8,$Y:$Z,2,FALSE) -> Data & AI | Y8: DNI | Z8: Commercial | AC8: IDEA > Ready for Solution | AD8: {=_xlfn.TEXTSPLIT(AC8,">",)} -> IDEA | AE8: Ready for Solution
F9: Mail | G9: Commercial | H9: 25 | I9: =SUMIF($F:$F,F9,$H:$H) -> 100 | K9: 7 | L9: GS | M9: Business Solutions | N9: =VLOOKUP($L9,$Y:$Z,2,FALSE) -> Commercial | O9: =P9*SUMIFS($P:$P,$F:$F,M9,$G:$G,N9)/#REF! -> #REF! | P9: 1 | R9: 0 | S9: =SUMIF($N:$N,R9,$O:$O) -> 0 | U9: GS | V9: =SUMIF($L:$L,U9,$O:$O) -> #REF! | W9: =VLOOKUP(U9,$Y:$Z,2,FALSE) -> Commercial | Y9: ECM | Z9: Commercial | AC9: SOLUTION > High Level Design | AD9: {=_xlfn.TEXTSPLIT(AC9,">",)} -> SOLUTION | AE9: High Level Design
F10: Mail | G10: Operations | H10: 25 | I10: =SUMIF($F:$F,F10,$H:$H) -> 100 | K10: 8 | L10: ACR | M10: Business Solutions | N10: =VLOOKUP($L10,$Y:$Z,2,FALSE) -> Corporate | O10: =P10*SUMIFS($P:$P,$F:$F,M10,$G:$G,N10)/#REF! -> #REF! | P10: 1 | S10: =SUMIF($N:$N,R10,$O:$O) -> 0 | U10: ACR | V10: =SUMIF($L:$L,U10,$O:$O) -> #REF! | W10: =VLOOKUP(U10,$Y:$Z,2,FALSE) -> Corporate | Y10: GP B2B | Z10: Commercial | AC10: SOLUTION > Ready for Development | AD10: {=_xlfn.TEXTSPLIT(AC10,">",)} -> SOLUTION | AE10: Ready for Development
F11: Mail | G11: Corporate | H11: 20 | I11: =SUMIF($F:$F,F11,$H:$H) -> 100 | K11: 9 | L11: EDO | M11: Business Solutions | N11: =VLOOKUP($L11,$Y:$Z,2,FALSE) -> Operations | O11: =P11*SUMIFS($P:$P,$F:$F,M11,$G:$G,N11)/#REF! -> #REF! | P11: 1 | S11: =SUMIF($N:$N,R11,$O:$O) -> 0 | U11: EDO | V11: =SUMIF($L:$L,U11,$O:$O) -> #REF! | W11: =VLOOKUP(U11,$Y:$Z,2,FALSE) -> Operations | Y11: GP B2C | Z11: Commercial | AC11: SOLUTION > In Definition | AD11: {=_xlfn.TEXTSPLIT(AC11,">",)} -> SOLUTION | AE11: In Definition
F12: Mail | G12: Technology | H12: 20 | I12: =SUMIF($F:$F,F12,$H:$H) -> 100 | K12: 10 | L12: SI-OPS | M12: Business Solutions | N12: =VLOOKUP($L12,$Y:$Z,2,FALSE) -> Technology | O12: =P12*SUMIFS($P:$P,$F:$F,M12,$G:$G,N12)/#REF! -> #REF! | P12: 1 | S12: =SUMIF($N:$N,R12,$O:$O) -> 0 | U12: SI-OPS | V12: =SUMIF($L:$L,U12,$O:$O) -> #REF! | W12: =VLOOKUP(U12,$Y:$Z,2,FALSE) -> Technology | Y12: GP ECL | Z12: Commercial
F13: Mail | G13: Data & AI | H13: 5 | I13: =SUMIF($F:$F,F13,$H:$H) -> 100 | K13: 11 | L13: DNI | M13: Business Solutions | N13: =VLOOKUP($L13,$Y:$Z,2,FALSE) -> Commercial | O13: =P13*SUMIFS($P:$P,$F:$F,M13,$G:$G,N13)/#REF! -> #REF! | P13: 1 | S13: =SUMIF($N:$N,R13,$O:$O) -> 0 | U13: DNI | V13: =SUMIF($L:$L,U13,$O:$O) -> #REF! | W13: =VLOOKUP(U13,$Y:$Z,2,FALSE) -> Commercial | Y13: GPG | Z13: Commercial
F14: Mail | G14: CISO | H14: 5 | I14: =SUMIF($F:$F,F14,$H:$H) -> 100 | K14: 12 | L14: AVC | M14: Business Solutions | N14: =VLOOKUP($L14,$Y:$Z,2,FALSE) -> Corporate | O14: =P14*SUMIFS($P:$P,$F:$F,M14,$G:$G,N14)/#REF! -> #REF! | P14: 1 | S14: =SUMIF($N:$N,R14,$O:$O) -> 0 | U14: AVC | V14: =SUMIF($L:$L,U14,$O:$O) -> #REF! | W14: =VLOOKUP(U14,$Y:$Z,2,FALSE) -> Corporate | Y14: GS | Z14: Commercial
F15: Business Solutions | G15: Commercial | H15: 25 | I15: =SUMIF($F:$F,F15,$H:$H) -> 100 | K15: 13 | L15: EM | M15: Business Solutions | N15: =VLOOKUP($L15,$Y:$Z,2,FALSE) -> Operations | O15: =P15*SUMIFS($P:$P,$F:$F,M15,$G:$G,N15)/#REF! -> #REF! | P15: 1 | U15: EM | V15: =SUMIF($L:$L,U15,$O:$O) -> #REF! | W15: =VLOOKUP(U15,$Y:$Z,2,FALSE) -> Operations | Y15: IDC | Z15: Commercial
F16: Business Solutions | G16: Operations | H16: 25 | I16: =SUMIF($F:$F,F16,$H:$H) -> 100 | K16: 14 | L16: SI-PRD | M16: Business Solutions | N16: =VLOOKUP($L16,$Y:$Z,2,FALSE) -> Technology | O16: =P16*SUMIFS($P:$P,$F:$F,M16,$G:$G,N16)/#REF! -> #REF! | P16: 1 | U16: SI-PRD | V16: =SUMIF($L:$L,U16,$O:$O) -> #REF! | W16: =VLOOKUP(U16,$Y:$Z,2,FALSE) -> Technology | Y16: ACR | Z16: Corporate
F17: Business Solutions | G17: Corporate | H17: 20 | I17: =SUMIF($F:$F,F17,$H:$H) -> 100 | K17: 15 | L17: CSI | M17: Business Solutions | N17: =VLOOKUP($L17,$Y:$Z,2,FALSE) -> Commercial | O17: =P17*SUMIFS($P:$P,$F:$F,M17,$G:$G,N17)/#REF! -> #REF! | P17: 1 | U17: CSI | V17: =SUMIF($L:$L,U17,$O:$O) -> #REF! | W17: =VLOOKUP(U17,$Y:$Z,2,FALSE) -> Commercial | Y17: ATC | Z17: Corporate
F18: Business Solutions | G18: Technology | H18: 20 | I18: =SUMIF($F:$F,F18,$H:$H) -> 100 | K18: 16 | L18: GT | M18: Business Solutions | N18: =VLOOKUP($L18,$Y:$Z,2,FALSE) -> Corporate | O18: =P18*SUMIFS($P:$P,$F:$F,M18,$G:$G,N18)/#REF! -> #REF! | P18: 1 | U18: GT | V18: =SUMIF($L:$L,U18,$O:$O) -> #REF! | W18: =VLOOKUP(U18,$Y:$Z,2,FALSE) -> Corporate | Y18: AVC | Z18: Corporate
F19: Business Solutions | G19: Data & AI | H19: 5 | I19: =SUMIF($F:$F,F19,$H:$H) -> 100 | K19: 17 | L19: BCTT | M19: Business Solutions | N19: =VLOOKUP($L19,$Y:$Z,2,FALSE) -> Technology | O19: =P19*SUMIFS($P:$P,$F:$F,M19,$G:$G,N19)/#REF! -> #REF! | P19: 1 | U19: BCTT | V19: =SUMIF($L:$L,U19,$O:$O) -> #REF! | W19: =VLOOKUP(U19,$Y:$Z,2,FALSE) -> Technology | Y19: CF | Z19: Corporate
F20: Business Solutions | G20: CISO | H20: 5 | I20: =SUMIF($F:$F,F20,$H:$H) -> 100 | K20: 18 | L20: GP B2C | M20: Business Solutions | N20: =VLOOKUP($L20,$Y:$Z,2,FALSE) -> Commercial | O20: =P20*SUMIFS($P:$P,$F:$F,M20,$G:$G,N20)/#REF! -> #REF! | P20: 1 | U20: GP B2C | V20: =SUMIF($L:$L,U20,$O:$O) -> #REF! | W20: =VLOOKUP(U20,$Y:$Z,2,FALSE) -> Commercial | Y20: CFO | Z20: Corporate
F21: Retail & Financial Services | G21: Commercial | H21: 25 | I21: =SUMIF($F:$F,F21,$H:$H) -> 100 | K21: 19 | L21: GRH | M21: Business Solutions | N21: =VLOOKUP($L21,$Y:$Z,2,FALSE) -> Corporate | O21: =P21*SUMIFS($P:$P,$F:$F,M21,$G:$G,N21)/#REF! -> #REF! | P21: 1 | U21: GRH | V21: =SUMIF($L:$L,U21,$O:$O) -> #REF! | W21: =VLOOKUP(U21,$Y:$Z,2,FALSE) -> Corporate | Y21: CHR | Z21: Corporate
F22: Retail & Financial Services | G22: Operations | H22: 25 | I22: =SUMIF($F:$F,F22,$H:$H) -> 100 | K22: 20 | L22: SI-CRP | M22: Business Solutions | N22: =VLOOKUP($L22,$Y:$Z,2,FALSE) -> Technology | O22: =P22*SUMIFS($P:$P,$F:$F,M22,$G:$G,N22)/#REF! -> #REF! | P22: 1 | U22: SI-CRP | V22: =SUMIF($L:$L,U22,$O:$O) -> #REF! | W22: =VLOOKUP(U22,$Y:$Z,2,FALSE) -> Technology | Y22: CL | Z22: Corporate
F23: Retail & Financial Services | G23: Corporate | H23: 20 | I23: =SUMIF($F:$F,F23,$H:$H) -> 100 | K23: 21 | L23: GP ECL | M23: Business Solutions | N23: =VLOOKUP($L23,$Y:$Z,2,FALSE) -> Commercial | O23: =P23*SUMIFS($P:$P,$F:$F,M23,$G:$G,N23)/#REF! -> #REF! | P23: 1 | U23: GP ECL | V23: =SUMIF($L:$L,U23,$O:$O) -> #REF! | W23: =VLOOKUP(U23,$Y:$Z,2,FALSE) -> Commercial | Y23: CMP | Z23: Corporate
F24: Retail & Financial Services | G24: Technology | H24: 20 | I24: =SUMIF($F:$F,F24,$H:$H) -> 100 | K24: 22 | L24: PC | M24: Business Solutions | N24: =VLOOKUP($L24,$Y:$Z,2,FALSE) -> Corporate | O24: =P24*SUMIFS($P:$P,$F:$F,M24,$G:$G,N24)/#REF! -> #REF! | P24: 1 | U24: PC | V24: =SUMIF($L:$L,U24,$O:$O) -> #REF! | W24: =VLOOKUP(U24,$Y:$Z,2,FALSE) -> Corporate | Y24: COM | Z24: Corporate
F25: Retail & Financial Services | G25: Data & AI | H25: 5 | I25: =SUMIF($F:$F,F25,$H:$H) -> 100 | K25: 23 | L25: GPG | M25: Business Solutions | N25: =VLOOKUP($L25,$Y:$Z,2,FALSE) -> Commercial | O25: =P25*SUMIFS($P:$P,$F:$F,M25,$G:$G,N25)/#REF! -> #REF! | P25: 1 | U25: GPG | V25: =SUMIF($L:$L,U25,$O:$O) -> #REF! | W25: =VLOOKUP(U25,$Y:$Z,2,FALSE) -> Commercial | Y25: DPO | Z25: Corporate
F26: Retail & Financial Services | G26: CISO | H26: 5 | I26: =SUMIF($F:$F,F26,$H:$H) -> 100 | K26: 24 | L26: RS | M26: Business Solutions | N26: =VLOOKUP($L26,$Y:$Z,2,FALSE) -> Corporate | O26: =P26*SUMIFS($P:$P,$F:$F,M26,$G:$G,N26)/#REF! -> #REF! | P26: 1 | U26: RS | V26: =SUMIF($L:$L,U26,$O:$O) -> #REF! | W26: =VLOOKUP(U26,$Y:$Z,2,FALSE) -> Corporate | Y26: FL | Z26: Corporate
... F35: Fulfilment | G35: Corporate | H35: 20 | I35: =SUMIF($F:$F,F35,$H:$H) -> 100 | K35: 33 | L35: NSP | M35: Business Solutions | N35: =VLOOKUP($L35,$Y:$Z,2,FALSE) -> Corporate | O35: =P35*SUMIFS($P:$P,$F:$F,M35,$G:$G,N35)/#REF! -> #REF! | P35: 1 | U35: NSP | V35: =SUMIF($L:$L,U35,$O:$O) -> #REF! | W35: =VLOOKUP(U35,$Y:$Z,2,FALSE) -> Corporate | Y35: EDO | Z35: Operations
F36: Fulfilment | G36: Technology | H36: 20 | I36: =SUMIF($F:$F,F36,$H:$H) -> 100 | K36: 1 | L36: COO | M36: eCommerce | N36: =VLOOKUP($L36,$Y:$Z,2,FALSE) -> Operations | O36: 50 | P36: 1 | U36: COO | V36: =SUMIF($L:$L,U36,$O:$O) -> 50.000001 | W36: =VLOOKUP(U36,$Y:$Z,2,FALSE) -> Operations | Y36: EM | Z36: Operations
F37: Fulfilment | G37: Data & AI | H37: 5 | I37: =SUMIF($F:$F,F37,$H:$H) -> 100 | K37: 2 | L37: CMO | M37: eCommerce | N37: =VLOOKUP($L37,$Y:$Z,2,FALSE) -> Commercial | O37: 33.4 | P37: 1 | U37: CMO | V37: =SUMIF($L:$L,U37,$O:$O) -> 33.400001 | W37: =VLOOKUP(U37,$Y:$Z,2,FALSE) -> Commercial | Y37: EM | Z37: Operations
F38: Fulfilment | G38: CISO | H38: 5 | I38: =SUMIF($F:$F,F38,$H:$H) -> 100 | K38: 3 | L38: ATC | M38: eCommerce | N38: =VLOOKUP($L38,$Y:$Z,2,FALSE) -> Corporate | O38: 40 | P38: 1 | U38: ATC | V38: =SUMIF($L:$L,U38,$O:$O) -> 40.000001 | W38: =VLOOKUP(U38,$Y:$Z,2,FALSE) -> Corporate | Y38: SEO | Z38: Operations
F39: Mail & Services | G39: Commercial | H39: 25 | I39: =SUMIF($F:$F,F39,$H:$H) -> 100 | K39: 4 | L39: CCO | M39: eCommerce | N39: =VLOOKUP($L39,$Y:$Z,2,FALSE) -> Commercial | O39: 33.3 | P39: 1 | U39: CCO | V39: =SUMIF($L:$L,U39,$O:$O) -> 33.300001 | W39: =VLOOKUP(U39,$Y:$Z,2,FALSE) -> Commercial | Y39: BCTT | Z39: Technology
F40: Mail & Services | G40: Operations | H40: 25 | I40: =SUMIF($F:$F,F40,$H:$H) -> 100 | K40: 5 | L40: IDC | M40: eCommerce | N40: =VLOOKUP($L40,$Y:$Z,2,FALSE) -> Commercial | O40: 33.3 | P40: 1 | U40: IDC | V40: =SUMIF($L:$L,U40,$O:$O) -> 33.300001 | W40: =VLOOKUP(U40,$Y:$Z,2,FALSE) -> Commercial | Y40: CIO | Z40: Technology
F41: Mail & Services | G41: Corporate | H41: 20 | I41: =SUMIF($F:$F,F41,$H:$H) -> 100 | K41: 6 | L41: CFO | M41: eCommerce | N41: =VLOOKUP($L41,$Y:$Z,2,FALSE) -> Corporate | O41: 40 | P41: 1 | U41: CFO | V41: =SUMIF($L:$L,U41,$O:$O) -> 40.000001 | W41: =VLOOKUP(U41,$Y:$Z,2,FALSE) -> Corporate | Y41: SI | Z41: Technology
F42: Mail & Services | G42: Technology | H42: 20 | I42: =SUMIF($F:$F,F42,$H:$H) -> 100 | K42: 7 | L42: CIO | M42: eCommerce | N42: =VLOOKUP($L42,$Y:$Z,2,FALSE) -> Technology | O42: 100 | P42: 1 | U42: CIO | V42: =SUMIF($L:$L,U42,$O:$O) -> 100 | W42: =VLOOKUP(U42,$Y:$Z,2,FALSE) -> Technology | Y42: SI-CRP | Z42: Technology
F43: Mail & Services | G43: Data & AI | H43: 5 | I43: =SUMIF($F:$F,F43,$H:$H) -> 100 | K43: 8 | L43: PRO | M43: eCommerce | N43: =VLOOKUP($L43,$Y:$Z,2,FALSE) -> Corporate | O43: 10 | P43: 1 | U43: PRO | V43: =SUMIF($L:$L,U43,$O:$O) -> 10.000001 | W43: =VLOOKUP(U43,$Y:$Z,2,FALSE) -> Corporate | Y43: SI-OPS | Z43: Technology
F44: Mail & Services | G44: CISO | H44: 5 | I44: =SUMIF($F:$F,F44,$H:$H) -> 100 | K44: 9 | L44: CHR | M44: eCommerce | N44: =VLOOKUP($L44,$Y:$Z,2,FALSE) -> Corporate | O44: 5 | P44: 1 | U44: CHR | V44: =SUMIF($L:$L,U44,$O:$O) -> 5.000001 | W44: =VLOOKUP(U44,$Y:$Z,2,FALSE) -> Corporate | Y44: SI-PRD | Z44: Technology
K45: 11 | L45: COM | M45: eCommerce | N45: =VLOOKUP($L45,$Y:$Z,2,FALSE) -> Corporate | O45: 5 | P45: 1 | U45: COM | V45: =SUMIF($L:$L,U45,$O:$O) -> 5.000001 | W45: =VLOOKUP(U45,$Y:$Z,2,FALSE) -> Corporate | Y45: IAD | Z45: Data & AI
K46: 12 | L46: GP ECL | M46: eCommerce | N46: =VLOOKUP($L46,$Y:$Z,2,FALSE) -> Commercial | O46: 1e-10 | P46: 1 | U46: SSJ | V46: =SUMIF($L:$L,U46,$O:$O) -> 4.4444444 | W46: =VLOOKUP(U46,$Y:$Z,2,FALSE) -> Corporate | Y46: NSP | Z46: Corporate
K47: 13 | L47: CISO | M47: eCommerce | N47: =VLOOKUP($L47,$Y:$Z,2,FALSE) -> CISO | O47: =P47*SUMIFS($P:$P,$F:$F,M47,$G:$G,N47)/#REF! -> #REF! | P47: 1 | U47: RC | W47: =VLOOKUP(U47,$Y:$Z,2,FALSE) -> Corporate | Y47: SSJ | Z47: Corporate
K48: 14 | L48: IAD | M48: eCommerce | N48: =VLOOKUP($L48,$Y:$Z,2,FALSE) -> Data & AI | O48: 100 | P48: 1 | U48: 0 | Y48: RC | Z48: Corporate
...

Sheet support >>
A1: backup

Sheet tom_demand_setup - ATUAL (2)
B1: order | C1: EXPORT CSV | D1: WEIGHTS_RA | F1: =SUBTOTAL(9,F2:F1000) -> 1131 | J1: EXPORT CSV | K1: Peso BG por RS | U1: EXPORT CSV | V1: WEIGHTS_RS | AF1: REF DATA | AJ1: REF DATA
B2: # | C2: RequestingArea | D2: RevenueStream | E2: BudgetGroup | F2: Weight | G2: Weight-RS+BG | H2: Weight-Base | J2: RevenueStream | K2: BudgetGroup | L2: Weight | M2: Check | N2: weight | O2: Check | P2: Count | Q2: Check | R2: Weight | S2: Check | U2: RevenueStream | V2: Weight | W2: Check | Y2: {=_xlfn.UNIQUE(E2:E1003)} -> BudgetGroup | Z2: Check | AB2: {=_xlfn.UNIQUE(C2:C1003)} -> RequestingArea | AC2: Check | AD2: hasBG? | AF2: RequestingArea | AG2: BudgetGroup | AH2: BusinessGroup | AJ2: MicroPhase bmap | AK2: MicroPhase Macro | AL2: MicroPhase Demand
B3: 1 | C3: GP B2B | D3: Business Solutions | E3: =VLOOKUP($C3,$AF:$AG,2,FALSE) -> Commercial | F3: =H3*SUMIFS($H:$H,$J:$J,D3,$K:$K,E3)/G3 -> 0.11111111 | G3: =SUMIFS($H$2:$H$1003,$E$2:$E$1003,E3,$D$2:$D$1003,D3) -> 9 | H3: 1 | J3: eCommerce | K3: Operations | L3: 25 | M3: =SUMIF($J:$J,J3,$L:$L) -> 100 | N3: =P3/Q3*100 -> 9.5238095 | O3: =SUMIF($J:$J,J3,$N:$N) -> 100 | P3: =COUNTIFS(E:E,K3,D:D,J3) -> 4 | Q3: =SUMIF($J:$J,J3,$P:$P) -> 42 | R3: =SUMIFS(F:F,E:E,K3,D:D,J3) -> 100 | S3: =SUMIF($J:$J,P3,$P:$P) -> 0 | U3: eCommerce | V3: 50 | W3: =SUM(V3:V18) -> 100 | Y3: Commercial | Z3: =SUMIF($E:$E,Y3,$F:$F) -> 205.00001 | AB3: GP B2B | AC3: =SUMIF($C:$C,AB3,$F:$F) -> 16.569445 | AD3: =VLOOKUP(AB3,$AF:$AG,2,FALSE) -> Commercial | AF3: CISO | AG3: CISO | AJ3: IDEA > Backlog | AK3: {=_xlfn.TEXTSPLIT(AJ3,">",)} -> IDEA | AL3: Backlog
B4: 2 | C4: SEO | D4: Business Solutions | E4: =VLOOKUP($C4,$AF:$AG,2,FALSE) -> Operations | F4: =H4*SUMIFS($H:$H,$J:$J,D4,$K:$K,E4)/G4 -> 0.33333333 | G4: =SUMIFS($H$2:$H$1003,$E$2:$E$1003,E4,$D$2:$D$1003,D4) -> 3 | H4: 1 | J4: eCommerce | K4: Commercial | L4: 25 | M4: =SUMIF($J:$J,J4,$L:$L) -> 100 | N4: =P4/Q4*100 -> 28.571429 | O4: =SUMIF($J:$J,J4,$N:$N) -> 100 | P4: =COUNTIFS(E:E,K4,D:D,J4) -> 12 | Q4: =SUMIF($J:$J,J4,$P:$P) -> 42 | R4: =SUMIFS(F:F,E:E,K4,D:D,J4) -> 100 | S4: =SUMIF($J:$J,P4,$P:$P) -> 0 | U4: Mail & Services | V4: 50 | Y4: Operations | Z4: =SUMIF($E:$E,Y4,$F:$F) -> 205 | AB4: SEO | AC4: =SUMIF($C:$C,AB4,$F:$F) -> 36.666668 | AD4: =VLOOKUP(AB4,$AF:$AG,2,FALSE) -> Operations | AF4: CCO | AG4: Commercial | AJ4: IDEA > Pitch | AK4: {=_xlfn.TEXTSPLIT(AJ4,">",)} -> IDEA | AL4: Pitch
B5: 3 | C5: CF | D5: Business Solutions | E5: =VLOOKUP($C5,$AF:$AG,2,FALSE) -> Corporate | F5: =H5*SUMIFS($H:$H,$J:$J,D5,$K:$K,E5)/G5 -> 0.071428571 | G5: =SUMIFS($H$2:$H$1003,$E$2:$E$1003,E5,$D$2:$D$1003,D5) -> 14 | H5: 1 | J5: eCommerce | K5: Corporate | L5: 20 | M5: =SUMIF($J:$J,J5,$L:$L) -> 100 | N5: =P5/Q5*100 -> 42.857143 | O5: =SUMIF($J:$J,J5,$N:$N) -> 100 | P5: =COUNTIFS(E:E,K5,D:D,J5) -> 18 | Q5: =SUMIF($J:$J,J5,$P:$P) -> 42 | R5: =SUMIFS(F:F,E:E,K5,D:D,J5) -> 100 | S5: =SUMIF($J:$J,P5,$P:$P) -> 0 | Y5: Corporate | Z5: =SUMIF($E:$E,Y5,$F:$F) -> 205.00002 | AB5: CF | AC5: =SUMIF($C:$C,AB5,$F:$F) -> 7.0938655 | AD5: =VLOOKUP(AB5,$AF:$AG,2,FALSE) -> Corporate | AF5: CMO | AG5: Commercial | AJ5: IDEA > In Definition | AK5: {=_xlfn.TEXTSPLIT(AJ5,">",)} -> IDEA | AL5: In Definition
B6: 4 | C6: SI | D6: Business Solutions | E6: =VLOOKUP($C6,$AF:$AG,2,FALSE) -> Technology | F6: =H6*SUMIFS($H:$H,$J:$J,D6,$K:$K,E6)/G6 -> 0.2 | G6: =SUMIFS($H$2:$H$1003,$E$2:$E$1003,E6,$D$2:$D$1003,D6) -> 5 | H6: 1 | J6: eCommerce | K6: Technology | L6: 20 | M6: =SUMIF($J:$J,J6,$L:$L) -> 100 | N6: =P6/Q6*100 -> 14.285714 | O6: =SUMIF($J:$J,J6,$N:$N) -> 100 | P6: =COUNTIFS(E:E,K6,D:D,J6) -> 6 | Q6: =SUMIF($J:$J,J6,$P:$P) -> 42 | R6: =SUMIFS(F:F,E:E,K6,D:D,J6) -> 100 | S6: =SUMIF($J:$J,P6,$P:$P) -> 0 | Y6: Technology | Z6: =SUMIF($E:$E,Y6,$F:$F) -> 205.00001 | AB6: SI | AC6: =SUMIF($C:$C,AB6,$F:$F) -> 41.000001 | AD6: =VLOOKUP(AB6,$AF:$AG,2,FALSE) -> Technology | AF6: CSI | AG6: Commercial | AJ6: SOLUTION > In Approval | AK6: {=_xlfn.TEXTSPLIT(AJ6,">",)} -> SOLUTION | AL6: In Approval
B7: 5 | C7: CISO | D7: Business Solutions | E7: =VLOOKUP($C7,$AF:$AG,2,FALSE) -> CISO | F7: =H7*SUMIFS($H:$H,$J:$J,D7,$K:$K,E7)/G7 -> 1 | G7: =SUMIFS($H$2:$H$1003,$E$2:$E$1003,E7,$D$2:$D$1003,D7) -> 1 | H7: 1 | J7: eCommerce | K7: Data & AI | L7: 5 | M7: =SUMIF($J:$J,J7,$L:$L) -> 100 | N7: =P7/Q7*100 -> 2.3809524 | O7: =SUMIF($J:$J,J7,$N:$N) -> 100 | P7: =COUNTIFS(E:E,K7,D:D,J7) -> 1 | Q7: =SUMIF($J:$J,J7,$P:$P) -> 42 | R7: =SUMIFS(F:F,E:E,K7,D:D,J7) -> 100 | S7: =SUMIF($J:$J,P7,$P:$P) -> 0 | Y7: CISO | Z7: =SUMIF($E:$E,Y7,$F:$F) -> 106 | AB7: CISO | AC7: =SUMIF($C:$C,AB7,$F:$F) -> 106 | AD7: =VLOOKUP(AB7,$AF:$AG,2,FALSE) -> CISO | AF7: CTTE | AG7: Commercial | AJ7: SOLUTION > Ready for Approval | AK7: {=_xlfn.TEXTSPLIT(AJ7,">",)} -> SOLUTION | AL7: Ready for Approval
B8: 6 | C8: IAD | D8: Business Solutions | E8: =VLOOKUP($C8,$AF:$AG,2,FALSE) -> Data & AI | F8: =H8*SUMIFS($H:$H,$J:$J,D8,$K:$K,E8)/G8 -> 1 | G8: =SUMIFS($H$2:$H$1003,$E$2:$E$1003,E8,$D$2:$D$1003,D8) -> 1 | H8: 1 | J8: eCommerce | K8: CISO | L8: 5 | M8: =SUMIF($J:$J,J8,$L:$L) -> 100 | N8: =P8/Q8*100 -> 2.3809524 | O8: =SUMIF($J:$J,J8,$N:$N) -> 100 | P8: =COUNTIFS(E:E,K8,D:D,J8) -> 1 | Q8: =SUMIF($J:$J,J8,$P:$P) -> 42 | R8: =SUMIFS(F:F,E:E,K8,D:D,J8) -> 1 | S8: =SUMIF($J:$J,P8,$P:$P) -> 0 | Y8: Data & AI | Z8: =SUMIF($E:$E,Y8,$F:$F) -> 205 | AB8: IAD | AC8: =SUMIF($C:$C,AB8,$F:$F) -> 204.14286 | AD8: =VLOOKUP(AB8,$AF:$AG,2,FALSE) -> Data & AI | AF8: DNI | AG8: Commercial | AJ8: IDEA > Ready for Solution | AK8: {=_xlfn.TEXTSPLIT(AJ8,">",)} -> IDEA | AL8: Ready for Solution
B9: 7 | C9: GS | D9: Business Solutions | E9: =VLOOKUP($C9,$AF:$AG,2,FALSE) -> Commercial | F9: =H9*SUMIFS($H:$H,$J:$J,D9,$K:$K,E9)/G9 -> 0.11111111 | G9: =SUMIFS($H$2:$H$1003,$E$2:$E$1003,E9,$D$2:$D$1003,D9) -> 9 | H9: 1 | J9: Mail | K9: Commercial | L9: 25 | M9: =SUMIF($J:$J,J9,$L:$L) -> 100 | N9: =P9/Q9*100 -> 28.125 | O9: =SUMIF($J:$J,J9,$N:$N) -> 100 | P9: =COUNTIFS(E:E,K9,D:D,J9) -> 9 | Q9: =SUMIF($J:$J,J9,$P:$P) -> 32 | R9: =SUMIFS(F:F,E:E,K9,D:D,J9) -> 1 | S9: =SUMIF($J:$J,P9,$P:$P) -> 0 | Y9: 0 | Z9: =SUMIF($E:$E,Y9,$F:$F) -> 0 | AB9: GS | AC9: =SUMIF($C:$C,AB9,$F:$F) -> 12.569445 | AD9: =VLOOKUP(AB9,$AF:$AG,2,FALSE) -> Commercial | AF9: ECM | AG9: Commercial | AJ9: SOLUTION > High Level Design | AK9: {=_xlfn.TEXTSPLIT(AJ9,">",)} -> SOLUTION | AL9: High Level Design
B10: 8 | C10: ACR | D10: Business Solutions | E10: =VLOOKUP($C10,$AF:$AG,2,FALSE) -> Corporate | F10: =H10*SUMIFS($H:$H,$J:$J,D10,$K:$K,E10)/G10 -> 0.071428571 | G10: =SUMIFS($H$2:$H$1003,$E$2:$E$1003,E10,$D$2:$D$1003,D10) -> 14 | H10: 1 | J10: Mail | K10: Operations | L10: 25 | M10: =SUMIF($J:$J,J10,$L:$L) -> 100 | N10: =P10/Q10*100 -> 9.375 | O10: =SUMIF($J:$J,J10,$N:$N) -> 100 | P10: =COUNTIFS(E:E,K10,D:D,J10) -> 3 | Q10: =SUMIF($J:$J,J10,$P:$P) -> 32 | R10: =SUMIFS(F:F,E:E,K10,D:D,J10) -> 1 | S10: =SUMIF($J:$J,P10,$P:$P) -> 0 | Z10: =SUMIF($E:$E,Y10,$F:$F) -> 0 | AB10: ACR | AC10: =SUMIF($C:$C,AB10,$F:$F) -> 7.0938655 | AD10: =VLOOKUP(AB10,$AF:$AG,2,FALSE) -> Corporate | AF10: GP B2B | AG10: Commercial | AJ10: SOLUTION > Ready for Development | AK10: {=_xlfn.TEXTSPLIT(AJ10,">",)} -> SOLUTION | AL10: Ready for Development
B11: 9 | C11: EDO | D11: Business Solutions | E11: =VLOOKUP($C11,$AF:$AG,2,FALSE) -> Operations | F11: =H11*SUMIFS($H:$H,$J:$J,D11,$K:$K,E11)/G11 -> 0.33333333 | G11: =SUMIFS($H$2:$H$1003,$E$2:$E$1003,E11,$D$2:$D$1003,D11) -> 3 | H11: 1 | J11: Mail | K11: Corporate | L11: 20 | M11: =SUMIF($J:$J,J11,$L:$L) -> 100 | N11: =P11/Q11*100 -> 40.625 | O11: =SUMIF($J:$J,J11,$N:$N) -> 100 | P11: =COUNTIFS(E:E,K11,D:D,J11) -> 13 | Q11: =SUMIF($J:$J,J11,$P:$P) -> 32 | R11: =SUMIFS(F:F,E:E,K11,D:D,J11) -> 1 | S11: =SUMIF($J:$J,P11,$P:$P) -> 0 | Z11: =SUMIF($E:$E,Y11,$F:$F) -> 0 | AB11: EDO | AC11: =SUMIF($C:$C,AB11,$F:$F) -> 85.666668 | AD11: =VLOOKUP(AB11,$AF:$AG,2,FALSE) -> Operations | AF11: GP B2C | AG11: Commercial | AJ11: SOLUTION > In Definition | AK11: {=_xlfn.TEXTSPLIT(AJ11,">",)} -> SOLUTION | AL11: In Definition
B12: 10 | C12: SI-OPS | D12: Business Solutions | E12: =VLOOKUP($C12,$AF:$AG,2,FALSE) -> Technology | F12: =H12*SUMIFS($H:$H,$J:$J,D12,$K:$K,E12)/G12 -> 0.2 | G12: =SUMIFS($H$2:$H$1003,$E$2:$E$1003,E12,$D$2:$D$1003,D12) -> 5 | H12: 1 | J12: Mail | K12: Technology | L12: 20 | M12: =SUMIF($J:$J,J12,$L:$L) -> 100 | N12: =P12/Q12*100 -> 15.625 | O12: =SUMIF($J:$J,J12,$N:$N) -> 100 | P12: =COUNTIFS(E:E,K12,D:D,J12) -> 5 | Q12: =SUMIF($J:$J,J12,$P:$P) -> 32 | R12: =SUMIFS(F:F,E:E,K12,D:D,J12) -> 1 | S12: =SUMIF($J:$J,P12,$P:$P) -> 0 | Z12: =SUMIF($E:$E,Y12,$F:$F) -> 0 | AB12: SI-OPS | AC12: =SUMIF($C:$C,AB12,$F:$F) -> 16.000001 | AD12: =VLOOKUP(AB12,$AF:$AG,2,FALSE) -> Technology | AF12: GP ECL | AG12: Commercial
B13: 11 | C13: DNI | D13: Business Solutions | E13: =VLOOKUP($C13,$AF:$AG,2,FALSE) -> Commercial | F13: =H13*SUMIFS($H:$H,$J:$J,D13,$K:$K,E13)/G13 -> 0.11111111 | G13: =SUMIFS($H$2:$H$1003,$E$2:$E$1003,E13,$D$2:$D$1003,D13) -> 9 | H13: 1 | J13: Mail | K13: Data & AI | L13: 5 | M13: =SUMIF($J:$J,J13,$L:$L) -> 100 | N13: =P13/Q13*100 -> 3.125 | O13: =SUMIF($J:$J,J13,$N:$N) -> 100 | P13: =COUNTIFS(E:E,K13,D:D,J13) -> 1 | Q13: =SUMIF($J:$J,J13,$P:$P) -> 32 | R13: =SUMIFS(F:F,E:E,K13,D:D,J13) -> 1 | S13: =SUMIF($J:$J,P13,$P:$P) -> 0 | Z13: =SUMIF($E:$E,Y13,$F:$F) -> 0 | AB13: DNI | AC13: =SUMIF($C:$C,AB13,$F:$F) -> 16.569445 | AD13: =VLOOKUP(AB13,$AF:$AG,2,FALSE) -> Commercial | AF13: GPG | AG13: Commercial
B14: 12 | C14: AVC | D14: Business Solutions | E14: =VLOOKUP($C14,$AF:$AG,2,FALSE) -> Corporate | F14: =H14*SUMIFS($H:$H,$J:$J,D14,$K:$K,E14)/G14 -> 0.071428571 | G14: =SUMIFS($H$2:$H$1003,$E$2:$E$1003,E14,$D$2:$D$1003,D14) -> 14 | H14: 1 | J14: Mail | K14: CISO | L14: 5 | M14: =SUMIF($J:$J,J14,$L:$L) -> 100 | N14: =P14/Q14*100 -> 3.125 | O14: =SUMIF($J:$J,J14,$N:$N) -> 100 | P14: =COUNTIFS(E:E,K14,D:D,J14) -> 1 | Q14: =SUMIF($J:$J,J14,$P:$P) -> 32 | R14: =SUMIFS(F:F,E:E,K14,D:D,J14) -> 1 | S14: =SUMIF($J:$J,P14,$P:$P) -> 0 | Z14: =SUMIF($E:$E,Y14,$F:$F) -> 0 | AB14: AVC | AC14: =SUMIF($C:$C,AB14,$F:$F) -> 7.0938655 | AD14: =VLOOKUP(AB14,$AF:$AG,2,FALSE) -> Corporate | AF14: GS | AG14: Commercial
B15: 13 | C15: EM | D15: Business Solutions | E15: =VLOOKUP($C15,$AF:$AG,2,FALSE) -> Operations | F15: =H15*SUMIFS($H:$H,$J:$J,D15,$K:$K,E15)/G15 -> 0.33333333 | G15: =SUMIFS($H$2:$H$1003,$E$2:$E$1003,E15,$D$2:$D$1003,D15) -> 3 | H15: 1 | J15: Business Solutions | K15: Commercial | L15: 25 | M15: =SUMIF($J:$J,J15,$L:$L) -> 100 | N15: =P15/Q15*100 -> 27.272727 | O15: =SUMIF($J:$J,J15,$N:$N) -> 100 | P15: =COUNTIFS(E:E,K15,D:D,J15) -> 9 | Q15: =SUMIF($J:$J,J15,$P:$P) -> 33 | R15: =SUMIFS(F:F,E:E,K15,D:D,J15) -> 1 | S15: =SUMIF($J:$J,P15,$P:$P) -> 0 | AB15: EM | AC15: =SUMIF($C:$C,AB15,$F:$F) -> 32.666668 | AD15: =VLOOKUP(AB15,$AF:$AG,2,FALSE) -> Operations | AF15: IDC | AG15: Commercial
B16: 14 | C16: SI-PRD | D16: Business Solutions | E16: =VLOOKUP($C16,$AF:$AG,2,FALSE) -> Technology | F16: =H16*SUMIFS($H:$H,$J:$J,D16,$K:$K,E16)/G16 -> 0.2 | G16: =SUMIFS($H$2:$H$1003,$E$2:$E$1003,E16,$D$2:$D$1003,D16) -> 5 | H16: 1 | J16: Business Solutions | K16: Operations | L16: 25 | M16: =SUMIF($J:$J,J16,$L:$L) -> 100 | N16: =P16/Q16*100 -> 9.0909091 | O16: =SUMIF($J:$J,J16,$N:$N) -> 100 | P16: =COUNTIFS(E:E,K16,D:D,J16) -> 3 | Q16: =SUMIF($J:$J,J16,$P:$P) -> 33 | R16: =SUMIFS(F:F,E:E,K16,D:D,J16) -> 1 | S16: =SUMIF($J:$J,P16,$P:$P) -> 0 | AB16: SI-PRD | AC16: =SUMIF($C:$C,AB16,$F:$F) -> 16.000001 | AD16: =VLOOKUP(AB16,$AF:$AG,2,FALSE) -> Technology | AF16: ACR | AG16: Corporate
B17: 15 | C17: CSI | D17: Business Solutions | E17: =VLOOKUP($C17,$AF:$AG,2,FALSE) -> Commercial | F17: =H17*SUMIFS($H:$H,$J:$J,D17,$K:$K,E17)/G17 -> 0.11111111 | G17: =SUMIFS($H$2:$H$1003,$E$2:$E$1003,E17,$D$2:$D$1003,D17) -> 9 | H17: 1 | J17: Business Solutions | K17: Corporate | L17: 20 | M17: =SUMIF($J:$J,J17,$L:$L) -> 100 | N17: =P17/Q17*100 -> 42.424242 | O17: =SUMIF($J:$J,J17,$N:$N) -> 100 | P17: =COUNTIFS(E:E,K17,D:D,J17) -> 14 | Q17: =SUMIF($J:$J,J17,$P:$P) -> 33 | R17: =SUMIFS(F:F,E:E,K17,D:D,J17) -> 1 | S17: =SUMIF($J:$J,P17,$P:$P) -> 0 | AB17: CSI | AC17: =SUMIF($C:$C,AB17,$F:$F) -> 10.569445 | AD17: =VLOOKUP(AB17,$AF:$AG,2,FALSE) -> Commercial | AF17: ATC | AG17: Corporate
B18: 16 | C18: GT | D18: Business Solutions | E18: =VLOOKUP($C18,$AF:$AG,2,FALSE) -> Corporate | F18: =H18*SUMIFS($H:$H,$J:$J,D18,$K:$K,E18)/G18 -> 0.071428571 | G18: =SUMIFS($H$2:$H$1003,$E$2:$E$1003,E18,$D$2:$D$1003,D18) -> 14 | H18: 1 | J18: Business Solutions | K18: Technology | L18: 20 | M18: =SUMIF($J:$J,J18,$L:$L) -> 100 | N18: =P18/Q18*100 -> 15.151515 | O18: =SUMIF($J:$J,J18,$N:$N) -> 100 | P18: =COUNTIFS(E:E,K18,D:D,J18) -> 5 | Q18: =SUMIF($J:$J,J18,$P:$P) -> 33 | R18: =SUMIFS(F:F,E:E,K18,D:D,J18) -> 1 | S18: =SUMIF($J:$J,P18,$P:$P) -> 0 | AB18: GT | AC18: =SUMIF($C:$C,AB18,$F:$F) -> 7.0938655 | AD18: =VLOOKUP(AB18,$AF:$AG,2,FALSE) -> Corporate | AF18: AVC | AG18: Corporate
B19: 17 | C19: BCTT | D19: Business Solutions | E19: =VLOOKUP($C19,$AF:$AG,2,FALSE) -> Technology | F19: =H19*SUMIFS($H:$H,$J:$J,D19,$K:$K,E19)/G19 -> 0.2 | G19: =SUMIFS($H$2:$H$1003,$E$2:$E$1003,E19,$D$2:$D$1003,D19) -> 5 | H19: 1 | J19: Business Solutions | K19: Data & AI | L19: 5 | M19: =SUMIF($J:$J,J19,$L:$L) -> 100 | N19: =P19/Q19*100 -> 3.030303 | O19: =SUMIF($J:$J,J19,$N:$N) -> 100 | P19: =COUNTIFS(E:E,K19,D:D,J19) -> 1 | Q19: =SUMIF($J:$J,J19,$P:$P) -> 33 | R19: =SUMIFS(F:F,E:E,K19,D:D,J19) -> 1 | S19: =SUMIF($J:$J,P19,$P:$P) -> 0 | AB19: BCTT | AC19: =SUMIF($C:$C,AB19,$F:$F) -> 16.000001 | AD19: =VLOOKUP(AB19,$AF:$AG,2,FALSE) -> Technology | AF19: CF | AG19: Corporate
B20: 18 | C20: GP B2C | D20: Business Solutions | E20: =VLOOKUP($C20,$AF:$AG,2,FALSE) -> Commercial | F20: =H20*SUMIFS($H:$H,$J:$J,D20,$K:$K,E20)/G20 -> 0.11111111 | G20: =SUMIFS($H$2:$H$1003,$E$2:$E$1003,E20,$D$2:$D$1003,D20) -> 9 | H20: 1 | J20: Business Solutions | K20: CISO | L20: 5 | M20: =SUMIF($J:$J,J20,$L:$L) -> 100 | N20: =P20/Q20*100 -> 3.030303 | O20: =SUMIF($J:$J,J20,$N:$N) -> 100 | P20: =COUNTIFS(E:E,K20,D:D,J20) -> 1 | Q20: =SUMIF($J:$J,J20,$P:$P) -> 33 | R20: =SUMIFS(F:F,E:E,K20,D:D,J20) -> 1 | S20: =SUMIF($J:$J,P20,$P:$P) -> 0 | AB20: GP B2C | AC20: =SUMIF($C:$C,AB20,$F:$F) -> 9.5694454 | AD20: =VLOOKUP(AB20,$AF:$AG,2,FALSE) -> Commercial | AF20: CFO | AG20: Corporate
B21: 19 | C21: GRH | D21: Business Solutions | E21: =VLOOKUP($C21,$AF:$AG,2,FALSE) -> Corporate | F21: =H21*SUMIFS($H:$H,$J:$J,D21,$K:$K,E21)/G21 -> 0.071428571 | G21: =SUMIFS($H$2:$H$1003,$E$2:$E$1003,E21,$D$2:$D$1003,D21) -> 14 | H21: 1 | J21: Retail & Financial Services | K21: Commercial | L21: 25 | M21: =SUMIF($J:$J,J21,$L:$L) -> 100 | N21: =P21/Q21*100 -> 25 | O21: =SUMIF($J:$J,J21,$N:$N) -> 100 | P21: =COUNTIFS(E:E,K21,D:D,J21) -> 8 | Q21: =SUMIF($J:$J,J21,$P:$P) -> 32 | R21: =SUMIFS(F:F,E:E,K21,D:D,J21) -> 1 | S21: =SUMIF($J:$J,P21,$P:$P) -> 0 | AB21: GRH | AC21: =SUMIF($C:$C,AB21,$F:$F) -> 7.0938655 | AD21: =VLOOKUP(AB21,$AF:$AG,2,FALSE) -> Corporate | AF21: CHR | AG21: Corporate
B22: 20 | C22: SI-CRP | D22: Business Solutions | E22: =VLOOKUP($C22,$AF:$AG,2,FALSE) -> Technology | F22: =H22*SUMIFS($H:$H,$J:$J,D22,$K:$K,E22)/G22 -> 0.2 | G22: =SUMIFS($H$2:$H$1003,$E$2:$E$1003,E22,$D$2:$D$1003,D22) -> 5 | H22: 1 | J22: Retail & Financial Services | K22: Operations | L22: 25 | M22: =SUMIF($J:$J,J22,$L:$L) -> 100 | N22: =P22/Q22*100 -> 9.375 | O22: =SUMIF($J:$J,J22,$N:$N) -> 100 | P22: =COUNTIFS(E:E,K22,D:D,J22) -> 3 | Q22: =SUMIF($J:$J,J22,$P:$P) -> 32 | R22: =SUMIFS(F:F,E:E,K22,D:D,J22) -> 1 | S22: =SUMIF($J:$J,P22,$P:$P) -> 0 | AB22: SI-CRP | AC22: =SUMIF($C:$C,AB22,$F:$F) -> 16.000001 | AD22: =VLOOKUP(AB22,$AF:$AG,2,FALSE) -> Technology | AF22: CL | AG22: Corporate
B23: 21 | C23: GP ECL | D23: Business Solutions | E23: =VLOOKUP($C23,$AF:$AG,2,FALSE) -> Commercial | F23: =H23*SUMIFS($H:$H,$J:$J,D23,$K:$K,E23)/G23 -> 0.11111111 | G23: =SUMIFS($H$2:$H$1003,$E$2:$E$1003,E23,$D$2:$D$1003,D23) -> 9 | H23: 1 | J23: Retail & Financial Services | K23: Corporate | L23: 20 | M23: =SUMIF($J:$J,J23,$L:$L) -> 100 | N23: =P23/Q23*100 -> 25 | O23: =SUMIF($J:$J,J23,$N:$N) -> 100 | P23: =COUNTIFS(E:E,K23,D:D,J23) -> 8 | Q23: =SUMIF($J:$J,J23,$P:$P) -> 32 | R23: =SUMIFS(F:F,E:E,K23,D:D,J23) -> 1 | S23: =SUMIF($J:$J,P23,$P:$P) -> 0 | AB23: GP ECL | AC23: =SUMIF($C:$C,AB23,$F:$F) -> 16.569445 | AD23: =VLOOKUP(AB23,$AF:$AG,2,FALSE) -> Commercial | AF23: CMP | AG23: Corporate
B24: 22 | C24: PC | D24: Business Solutions | E24: =VLOOKUP($C24,$AF:$AG,2,FALSE) -> Corporate | F24: =H24*SUMIFS($H:$H,$J:$J,D24,$K:$K,E24)/G24 -> 0.071428571 | G24: =SUMIFS($H$2:$H$1003,$E$2:$E$1003,E24,$D$2:$D$1003,D24) -> 14 | H24: 1 | J24: Retail & Financial Services | K24: Technology | L24: 20 | M24: =SUMIF($J:$J,J24,$L:$L) -> 100 | N24: =P24/Q24*100 -> 15.625 | O24: =SUMIF($J:$J,J24,$N:$N) -> 100 | P24: =COUNTIFS(E:E,K24,D:D,J24) -> 5 | Q24: =SUMIF($J:$J,J24,$P:$P) -> 32 | R24: =SUMIFS(F:F,E:E,K24,D:D,J24) -> 1 | S24: =SUMIF($J:$J,P24,$P:$P) -> 0 | AB24: PC | AC24: =SUMIF($C:$C,AB24,$F:$F) -> 7.0938655 | AD24: =VLOOKUP(AB24,$AF:$AG,2,FALSE) -> Corporate | AF24: COM | AG24: Corporate
B25: 23 | C25: GPG | D25: Business Solutions | E25: =VLOOKUP($C25,$AF:$AG,2,FALSE) -> Commercial | F25: =H25*SUMIFS($H:$H,$J:$J,D25,$K:$K,E25)/G25 -> 0.11111111 | G25: =SUMIFS($H$2:$H$1003,$E$2:$E$1003,E25,$D$2:$D$1003,D25) -> 9 | H25: 1 | J25: Retail & Financial Services | K25: Data & AI | L25: 5 | M25: =SUMIF($J:$J,J25,$L:$L) -> 100 | N25: =P25/Q25*100 -> 21.875 | O25: =SUMIF($J:$J,J25,$N:$N) -> 100 | P25: =COUNTIFS(E:E,K25,D:D,J25) -> 7 | Q25: =SUMIF($J:$J,J25,$P:$P) -> 32 | R25: =SUMIFS(F:F,E:E,K25,D:D,J25) -> 1 | S25: =SUMIF($J:$J,P25,$P:$P) -> 0 | AB25: GPG | AC25: =SUMIF($C:$C,AB25,$F:$F) -> 9.5694454 | AD25: =VLOOKUP(AB25,$AF:$AG,2,FALSE) -> Commercial | AF25: DPO | AG25: Corporate
B26: 24 | C26: RS | D26: Business Solutions | E26: =VLOOKUP($C26,$AF:$AG,2,FALSE) -> Corporate | F26: =H26*SUMIFS($H:$H,$J:$J,D26,$K:$K,E26)/G26 -> 0.071428571 | G26: =SUMIFS($H$2:$H$1003,$E$2:$E$1003,E26,$D$2:$D$1003,D26) -> 14 | H26: 1 | J26: Retail & Financial Services | K26: CISO | L26: 5 | M26: =SUMIF($J:$J,J26,$L:$L) -> 100 | N26: =P26/Q26*100 -> 3.125 | O26: =SUMIF($J:$J,J26,$N:$N) -> 100 | P26: =COUNTIFS(E:E,K26,D:D,J26) -> 1 | Q26: =SUMIF($J:$J,J26,$P:$P) -> 32 | R26: =SUMIFS(F:F,E:E,K26,D:D,J26) -> 1 | S26: =SUMIF($J:$J,P26,$P:$P) -> 0 | AB26: RS | AC26: =SUMIF($C:$C,AB26,$F:$F) -> 7.0938655 | AD26: =VLOOKUP(AB26,$AF:$AG,2,FALSE) -> Corporate | AF26: FL | AG26: Corporate
... B35: 33 | C35: NSP | D35: Business Solutions | E35: =VLOOKUP($C35,$AF:$AG,2,FALSE) -> Corporate | F35: =H35*SUMIFS($H:$H,$J:$J,D35,$K:$K,E35)/G35 -> 0.071428571 | G35: =SUMIFS($H$2:$H$1003,$E$2:$E$1003,E35,$D$2:$D$1003,D35) -> 14 | H35: 1 | J35: Fulfilment | K35: Corporate | L35: 20 | M35: =SUMIF($J:$J,J35,$L:$L) -> 100 | N35: =P35/Q35*100 -> 40.625 | O35: =SUMIF($J:$J,J35,$N:$N) -> 100 | P35: =COUNTIFS(E:E,K35,D:D,J35) -> 13 | Q35: =SUMIF($J:$J,J35,$P:$P) -> 32 | R35: =SUMIFS(F:F,E:E,K35,D:D,J35) -> 1 | S35: =SUMIF($J:$J,P35,$P:$P) -> 0 | AB35: NSP | AC35: =SUMIF($C:$C,AB35,$F:$F) -> 6.7380952 | AD35: =VLOOKUP(AB35,$AF:$AG,2,FALSE) -> Corporate | AF35: EDO | AG35: Operations
B36: 1 | C36: COO | D36: eCommerce | E36: =VLOOKUP($C36,$AF:$AG,2,FALSE) -> Operations | F36: 50 | G36: =SUMIFS($H$2:$H$1003,$E$2:$E$1003,E36,$D$2:$D$1003,D36) -> 4 | H36: 1 | J36: Fulfilment | K36: Technology | L36: 20 | M36: =SUMIF($J:$J,J36,$L:$L) -> 100 | N36: =P36/Q36*100 -> 15.625 | O36: =SUMIF($J:$J,J36,$N:$N) -> 100 | P36: =COUNTIFS(E:E,K36,D:D,J36) -> 5 | Q36: =SUMIF($J:$J,J36,$P:$P) -> 32 | R36: =SUMIFS(F:F,E:E,K36,D:D,J36) -> 1 | S36: =SUMIF($J:$J,P36,$P:$P) -> 0 | AB36: COO | AC36: =SUMIF($C:$C,AB36,$F:$F) -> 50.000001 | AD36: =VLOOKUP(AB36,$AF:$AG,2,FALSE) -> Operations | AF36: EM | AG36: Operations
B37: 2 | C37: CMO | D37: eCommerce | E37: =VLOOKUP($C37,$AF:$AG,2,FALSE) -> Commercial | F37: 33.4 | G37: =SUMIFS($H$2:$H$1003,$E$2:$E$1003,E37,$D$2:$D$1003,D37) -> 12 | H37: 1 | J37: Fulfilment | K37: Data & AI | L37: 5 | M37: =SUMIF($J:$J,J37,$L:$L) -> 100 | N37: =P37/Q37*100 -> 3.125 | O37: =SUMIF($J:$J,J37,$N:$N) -> 100 | P37: =COUNTIFS(E:E,K37,D:D,J37) -> 1 | Q37: =SUMIF($J:$J,J37,$P:$P) -> 32 | R37: =SUMIFS(F:F,E:E,K37,D:D,J37) -> 1 | S37: =SUMIF($J:$J,P37,$P:$P) -> 0 | AB37: CMO | AC37: =SUMIF($C:$C,AB37,$F:$F) -> 33.400001 | AD37: =VLOOKUP(AB37,$AF:$AG,2,FALSE) -> Commercial | AF37: EM | AG37: Operations
B38: 3 | C38: ATC | D38: eCommerce | E38: =VLOOKUP($C38,$AF:$AG,2,FALSE) -> Corporate | F38: 40 | G38: =SUMIFS($H$2:$H$1003,$E$2:$E$1003,E38,$D$2:$D$1003,D38) -> 18 | H38: 1 | J38: Fulfilment | K38: CISO | L38: 5 | M38: =SUMIF($J:$J,J38,$L:$L) -> 100 | N38: =P38/Q38*100 -> 3.125 | O38: =SUMIF($J:$J,J38,$N:$N) -> 100 | P38: =COUNTIFS(E:E,K38,D:D,J38) -> 1 | Q38: =SUMIF($J:$J,J38,$P:$P) -> 32 | R38: =SUMIFS(F:F,E:E,K38,D:D,J38) -> 1 | S38: =SUMIF($J:$J,P38,$P:$P) -> 0 | AB38: ATC | AC38: =SUMIF($C:$C,AB38,$F:$F) -> 40.000001 | AD38: =VLOOKUP(AB38,$AF:$AG,2,FALSE) -> Corporate | AF38: SEO | AG38: Operations
B39: 4 | C39: CCO | D39: eCommerce | E39: =VLOOKUP($C39,$AF:$AG,2,FALSE) -> Commercial | F39: 33.3 | G39: =SUMIFS($H$2:$H$1003,$E$2:$E$1003,E39,$D$2:$D$1003,D39) -> 12 | H39: 1 | J39: Mail & Services | K39: Commercial | L39: 25 | M39: =SUMIF($J:$J,J39,$L:$L) -> 100 | N39: 38 | O39: =SUMIF($J:$J,J39,$N:$N) -> 100 | P39: =COUNTIFS(E:E,K39,D:D,J39) -> 9 | Q39: =SUMIF($J:$J,J39,$P:$P) -> 35 | R39: =SUMIFS(F:F,E:E,K39,D:D,J39) -> 100 | S39: =SUMIF($J:$J,P39,$P:$P) -> 0 | AB39: CCO | AC39: =SUMIF($C:$C,AB39,$F:$F) -> 33.300001 | AD39: =VLOOKUP(AB39,$AF:$AG,2,FALSE) -> Commercial | AF39: BCTT | AG39: Technology
B40: 5 | C40: IDC | D40: eCommerce | E40: =VLOOKUP($C40,$AF:$AG,2,FALSE) -> Commercial | F40: 33.3 | G40: =SUMIFS($H$2:$H$1003,$E$2:$E$1003,E40,$D$2:$D$1003,D40) -> 12 | H40: 1 | J40: Mail & Services | K40: Operations | L40: 25 | M40: =SUMIF($J:$J,J40,$L:$L) -> 100 | N40: 19 | O40: =SUMIF($J:$J,J40,$N:$N) -> 100 | P40: =COUNTIFS(E:E,K40,D:D,J40) -> 3 | Q40: =SUMIF($J:$J,J40,$P:$P) -> 35 | R40: =SUMIFS(F:F,E:E,K40,D:D,J40) -> 100 | S40: =SUMIF($J:$J,P40,$P:$P) -> 0 | AB40: IDC | AC40: =SUMIF($C:$C,AB40,$F:$F) -> 33.300001 | AD40: =VLOOKUP(AB40,$AF:$AG,2,FALSE) -> Commercial | AF40: CIO | AG40: Technology
